Watching for file changes with StatReloader
D:\Fanshawe\capstone\recover_smart\recoversmart\settings.py changed, reloading.
Watching for file changes with StatReloader
Bad Request: /api/patients/
"POST //api/patients/ HTTP/1.1" 400 58
"POST //api/patients/ HTTP/1.1" 201 155
D:\Fanshawe\capstone\recover_smart\users\views.py changed, reloading.
Watching for file changes with StatReloader
Bad Request: /api/patients/
"POST //api/patients/ HTTP/1.1" 400 58
"POST //api/patients/ HTTP/1.1" 201 155
D:\Fanshawe\capstone\recover_smart\users\views.py changed, reloading.
Watching for file changes with StatReloader
D:\Fanshawe\capstone\recover_smart\users\views.py changed, reloading.
Watching for file changes with StatReloader
Bad Request: /api/patients/
"POST //api/patients/ HTTP/1.1" 400 58
"POST //api/users HTTP/1.1" 201 121
D:\Fanshawe\capstone\recover_smart\users\views.py changed, reloading.
Watching for file changes with StatReloader
D:\Fanshawe\capstone\recover_smart\users\views.py changed, reloading.
Watching for file changes with StatReloader
D:\Fanshawe\capstone\recover_smart\users\views.py changed, reloading.
Watching for file changes with StatReloader
Bad Request: /api/users
"POST //api/users HTTP/1.1" 400 58
D:\Fanshawe\capstone\recover_smart\users\views.py changed, reloading.
Watching for file changes with StatReloader
Internal Server Error: /api/users
Traceback (most recent call last):
  File "D:\Fanshawe\capstone\recover_smart\venv\Lib\site-packages\django\core\handlers\exception.py", line 55, in inner
    response = get_response(request)
  File "D:\Fanshawe\capstone\recover_smart\venv\Lib\site-packages\django\core\handlers\base.py", line 197, in _get_response
    response = wrapped_callback(request, *callback_args, **callback_kwargs)
  File "D:\Fanshawe\capstone\recover_smart\venv\Lib\site-packages\django\views\decorators\csrf.py", line 65, in _view_wrapper
    return view_func(request, *args, **kwargs)
  File "D:\Fanshawe\capstone\recover_smart\venv\Lib\site-packages\django\views\generic\base.py", line 104, in view
    return self.dispatch(request, *args, **kwargs)
           ~~~~~~~~~~~~~^^^^^^^^^^^^^^^^^^^^^^^^^^
  File "D:\Fanshawe\capstone\recover_smart\venv\Lib\site-packages\rest_framework\views.py", line 509, in dispatch
    response = self.handle_exception(exc)
  File "D:\Fanshawe\capstone\recover_smart\venv\Lib\site-packages\rest_framework\views.py", line 469, in handle_exception
    self.raise_uncaught_exception(exc)
    ~~~~~~~~~~~~~~~~~~~~~~~~~~~~~^^^^^
  File "D:\Fanshawe\capstone\recover_smart\venv\Lib\site-packages\rest_framework\views.py", line 480, in raise_uncaught_exception
    raise exc
  File "D:\Fanshawe\capstone\recover_smart\venv\Lib\site-packages\rest_framework\views.py", line 506, in dispatch
    response = handler(request, *args, **kwargs)
  File "D:\Fanshawe\capstone\recover_smart\users\views.py", line 78, in post
    create_user_and_send_email(context = {
    ~~~~~~~~~~~~~~~~~~~~~~~~~~^^^^^^^^^^^^
        "first_name": user.first_name,
        ^^^^^^^^^^^^^^^^^^^^^^^^^^^^^^
        "username": user.username,
        ^^^^^^^^^^^^^^^^^^^^^^^^^^
        "password": password
        ^^^^^^^^^^^^^^^^^^^^
    })
    ^^
TypeError: create_user_and_send_email() got an unexpected keyword argument 'context'
"POST //api/users HTTP/1.1" 500 108450
D:\Fanshawe\capstone\recover_smart\users\services.py changed, reloading.
Watching for file changes with StatReloader
D:\Fanshawe\capstone\recover_smart\users\services.py changed, reloading.
Watching for file changes with StatReloader
D:\Fanshawe\capstone\recover_smart\users\services.py changed, reloading.
Watching for file changes with StatReloader
D:\Fanshawe\capstone\recover_smart\users\services.py changed, reloading.
Watching for file changes with StatReloader
D:\Fanshawe\capstone\recover_smart\users\views.py changed, reloading.
Watching for file changes with StatReloader
D:\Fanshawe\capstone\recover_smart\users\views.py changed, reloading.
Watching for file changes with StatReloader
Bad Request: /api/users
"POST //api/users HTTP/1.1" 400 58
"POST //api/users HTTP/1.1" 201 123
D:\Fanshawe\capstone\recover_smart\users\services.py changed, reloading.
Watching for file changes with StatReloader
D:\Fanshawe\capstone\recover_smart\patients\views.py changed, reloading.
Watching for file changes with StatReloader
D:\Fanshawe\capstone\recover_smart\patients\views.py changed, reloading.
Watching for file changes with StatReloader
D:\Fanshawe\capstone\recover_smart\patients\views.py changed, reloading.
Watching for file changes with StatReloader
D:\Fanshawe\capstone\recover_smart\users\views.py changed, reloading.
Watching for file changes with StatReloader
D:\Fanshawe\capstone\recover_smart\users\views.py changed, reloading.
Watching for file changes with StatReloader
D:\Fanshawe\capstone\recover_smart\patients\views.py changed, reloading.
Watching for file changes with StatReloader
Internal Server Error: /api/patients/
Traceback (most recent call last):
  File "D:\Fanshawe\capstone\recover_smart\users\services.py", line 13, in create_user_and_send_email
    user.set_password(password)  # Securely set the password
    ^^^^^^^^^^^^^^^^^
AttributeError: 'UserSerializer' object has no attribute 'set_password'

During handling of the above exception, another exception occurred:

Traceback (most recent call last):
  File "D:\Fanshawe\capstone\recover_smart\venv\Lib\site-packages\django\core\handlers\exception.py", line 55, in inner
    response = get_response(request)
  File "D:\Fanshawe\capstone\recover_smart\venv\Lib\site-packages\django\core\handlers\base.py", line 197, in _get_response
    response = wrapped_callback(request, *callback_args, **callback_kwargs)
  File "D:\Fanshawe\capstone\recover_smart\venv\Lib\site-packages\django\views\decorators\csrf.py", line 65, in _view_wrapper
    return view_func(request, *args, **kwargs)
  File "D:\Fanshawe\capstone\recover_smart\venv\Lib\site-packages\django\views\generic\base.py", line 104, in view
    return self.dispatch(request, *args, **kwargs)
           ~~~~~~~~~~~~~^^^^^^^^^^^^^^^^^^^^^^^^^^
  File "D:\Fanshawe\capstone\recover_smart\venv\Lib\site-packages\rest_framework\views.py", line 509, in dispatch
    response = self.handle_exception(exc)
  File "D:\Fanshawe\capstone\recover_smart\venv\Lib\site-packages\rest_framework\views.py", line 469, in handle_exception
    self.raise_uncaught_exception(exc)
    ~~~~~~~~~~~~~~~~~~~~~~~~~~~~~^^^^^
  File "D:\Fanshawe\capstone\recover_smart\venv\Lib\site-packages\rest_framework\views.py", line 480, in raise_uncaught_exception
    raise exc
  File "D:\Fanshawe\capstone\recover_smart\venv\Lib\site-packages\rest_framework\views.py", line 506, in dispatch
    response = handler(request, *args, **kwargs)
  File "D:\Fanshawe\capstone\recover_smart\patients\views.py", line 93, in post
    create_user_and_send_email(user=user)
    ~~~~~~~~~~~~~~~~~~~~~~~~~~^^^^^^^^^^^
  File "D:\Fanshawe\capstone\recover_smart\users\services.py", line 29, in create_user_and_send_email
    raise ValueError(f"Error creating user: {str(e)}")
ValueError: Error creating user: 'UserSerializer' object has no attribute 'set_password'
"POST //api/patients/ HTTP/1.1" 500 119717
D:\Fanshawe\capstone\recover_smart\patients\views.py changed, reloading.
Watching for file changes with StatReloader
Bad Request: /api/patients/
"POST //api/patients/ HTTP/1.1" 400 58
Internal Server Error: /api/patients/
Traceback (most recent call last):
  File "D:\Fanshawe\capstone\recover_smart\users\services.py", line 13, in create_user_and_send_email
    user.set_password(password)  # Securely set the password
    ^^^^^^^^^^^^^^^^^
AttributeError: 'ReturnDict' object has no attribute 'set_password'

During handling of the above exception, another exception occurred:

Traceback (most recent call last):
  File "D:\Fanshawe\capstone\recover_smart\venv\Lib\site-packages\django\core\handlers\exception.py", line 55, in inner
    response = get_response(request)
  File "D:\Fanshawe\capstone\recover_smart\venv\Lib\site-packages\django\core\handlers\base.py", line 197, in _get_response
    response = wrapped_callback(request, *callback_args, **callback_kwargs)
  File "D:\Fanshawe\capstone\recover_smart\venv\Lib\site-packages\django\views\decorators\csrf.py", line 65, in _view_wrapper
    return view_func(request, *args, **kwargs)
  File "D:\Fanshawe\capstone\recover_smart\venv\Lib\site-packages\django\views\generic\base.py", line 104, in view
    return self.dispatch(request, *args, **kwargs)
           ~~~~~~~~~~~~~^^^^^^^^^^^^^^^^^^^^^^^^^^
  File "D:\Fanshawe\capstone\recover_smart\venv\Lib\site-packages\rest_framework\views.py", line 509, in dispatch
    response = self.handle_exception(exc)
  File "D:\Fanshawe\capstone\recover_smart\venv\Lib\site-packages\rest_framework\views.py", line 469, in handle_exception
    self.raise_uncaught_exception(exc)
    ~~~~~~~~~~~~~~~~~~~~~~~~~~~~~^^^^^
  File "D:\Fanshawe\capstone\recover_smart\venv\Lib\site-packages\rest_framework\views.py", line 480, in raise_uncaught_exception
    raise exc
  File "D:\Fanshawe\capstone\recover_smart\venv\Lib\site-packages\rest_framework\views.py", line 506, in dispatch
    response = handler(request, *args, **kwargs)
  File "D:\Fanshawe\capstone\recover_smart\patients\views.py", line 93, in post
    create_user_and_send_email(user=user.data)
    ~~~~~~~~~~~~~~~~~~~~~~~~~~^^^^^^^^^^^^^^^^
  File "D:\Fanshawe\capstone\recover_smart\users\services.py", line 29, in create_user_and_send_email
    raise ValueError(f"Error creating user: {str(e)}")
ValueError: Error creating user: 'ReturnDict' object has no attribute 'set_password'
"POST //api/patients/ HTTP/1.1" 500 118411
D:\Fanshawe\capstone\recover_smart\patients\views.py changed, reloading.
Watching for file changes with StatReloader
Bad Request: /api/patients/
"POST //api/patients/ HTTP/1.1" 400 58
Internal Server Error: /api/patients/
Traceback (most recent call last):
  File "D:\Fanshawe\capstone\recover_smart\users\services.py", line 13, in create_user_and_send_email
    user.set_password(password)  # Securely set the password
    ^^^^^^^^^^^^^^^^^
AttributeError: 'UserSerializer' object has no attribute 'set_password'

During handling of the above exception, another exception occurred:

Traceback (most recent call last):
  File "D:\Fanshawe\capstone\recover_smart\venv\Lib\site-packages\django\core\handlers\exception.py", line 55, in inner
    response = get_response(request)
  File "D:\Fanshawe\capstone\recover_smart\venv\Lib\site-packages\django\core\handlers\base.py", line 197, in _get_response
    response = wrapped_callback(request, *callback_args, **callback_kwargs)
  File "D:\Fanshawe\capstone\recover_smart\venv\Lib\site-packages\django\views\decorators\csrf.py", line 65, in _view_wrapper
    return view_func(request, *args, **kwargs)
  File "D:\Fanshawe\capstone\recover_smart\venv\Lib\site-packages\django\views\generic\base.py", line 104, in view
    return self.dispatch(request, *args, **kwargs)
           ~~~~~~~~~~~~~^^^^^^^^^^^^^^^^^^^^^^^^^^
  File "D:\Fanshawe\capstone\recover_smart\venv\Lib\site-packages\rest_framework\views.py", line 509, in dispatch
    response = self.handle_exception(exc)
  File "D:\Fanshawe\capstone\recover_smart\venv\Lib\site-packages\rest_framework\views.py", line 469, in handle_exception
    self.raise_uncaught_exception(exc)
    ~~~~~~~~~~~~~~~~~~~~~~~~~~~~~^^^^^
  File "D:\Fanshawe\capstone\recover_smart\venv\Lib\site-packages\rest_framework\views.py", line 480, in raise_uncaught_exception
    raise exc
  File "D:\Fanshawe\capstone\recover_smart\venv\Lib\site-packages\rest_framework\views.py", line 506, in dispatch
    response = handler(request, *args, **kwargs)
  File "D:\Fanshawe\capstone\recover_smart\patients\views.py", line 93, in post
    create_user_and_send_email(user=user)
    ~~~~~~~~~~~~~~~~~~~~~~~~~~^^^^^^^^^^^
  File "D:\Fanshawe\capstone\recover_smart\users\services.py", line 29, in create_user_and_send_email
    raise ValueError(f"Error creating user: {str(e)}")
ValueError: Error creating user: 'UserSerializer' object has no attribute 'set_password'
"POST //api/patients/ HTTP/1.1" 500 119741
D:\Fanshawe\capstone\recover_smart\patients\views.py changed, reloading.
Watching for file changes with StatReloader
D:\Fanshawe\capstone\recover_smart\patients\views.py changed, reloading.
Watching for file changes with StatReloader
D:\Fanshawe\capstone\recover_smart\patients\views.py changed, reloading.
Watching for file changes with StatReloader
"POST //api/patients/ HTTP/1.1" 201 158
D:\Fanshawe\capstone\recover_smart\users\services.py changed, reloading.
Watching for file changes with StatReloader
D:\Fanshawe\capstone\recover_smart\users\services.py changed, reloading.
Watching for file changes with StatReloader
"POST //api/patients/ HTTP/1.1" 201 159
D:\Fanshawe\capstone\recover_smart\users\services.py changed, reloading.
Watching for file changes with StatReloader
Internal Server Error: /api/patients/
Traceback (most recent call last):
  File "D:\Fanshawe\capstone\recover_smart\venv\Lib\site-packages\django\core\handlers\exception.py", line 55, in inner
    response = get_response(request)
  File "D:\Fanshawe\capstone\recover_smart\venv\Lib\site-packages\django\core\handlers\base.py", line 197, in _get_response
    response = wrapped_callback(request, *callback_args, **callback_kwargs)
  File "D:\Fanshawe\capstone\recover_smart\venv\Lib\site-packages\django\views\decorators\csrf.py", line 65, in _view_wrapper
    return view_func(request, *args, **kwargs)
  File "D:\Fanshawe\capstone\recover_smart\venv\Lib\site-packages\django\views\generic\base.py", line 104, in view
    return self.dispatch(request, *args, **kwargs)
           ~~~~~~~~~~~~~^^^^^^^^^^^^^^^^^^^^^^^^^^
  File "D:\Fanshawe\capstone\recover_smart\venv\Lib\site-packages\rest_framework\views.py", line 509, in dispatch
    response = self.handle_exception(exc)
  File "D:\Fanshawe\capstone\recover_smart\venv\Lib\site-packages\rest_framework\views.py", line 469, in handle_exception
    self.raise_uncaught_exception(exc)
    ~~~~~~~~~~~~~~~~~~~~~~~~~~~~~^^^^^
  File "D:\Fanshawe\capstone\recover_smart\venv\Lib\site-packages\rest_framework\views.py", line 480, in raise_uncaught_exception
    raise exc
  File "D:\Fanshawe\capstone\recover_smart\venv\Lib\site-packages\rest_framework\views.py", line 506, in dispatch
    response = handler(request, *args, **kwargs)
  File "D:\Fanshawe\capstone\recover_smart\patients\views.py", line 87, in post
    return Response(user.errors, status=400)
                    ^^^^
UnboundLocalError: cannot access local variable 'user' where it is not associated with a value
"POST //api/patients/ HTTP/1.1" 500 108937
"POST //api/patients/ HTTP/1.1" 201 160
"POST //api/patients/ HTTP/1.1" 201 158
"POST //api/patients/ HTTP/1.1" 201 164
Watching for file changes with StatReloader
D:\Fanshawe\capstone\recover_smart\patients\urls.py changed, reloading.
Watching for file changes with StatReloader
D:\Fanshawe\capstone\recover_smart\patients\views.py changed, reloading.
Watching for file changes with StatReloader
D:\Fanshawe\capstone\recover_smart\patients\views.py changed, reloading.
Watching for file changes with StatReloader
D:\Fanshawe\capstone\recover_smart\patients\urls.py changed, reloading.
Watching for file changes with StatReloader
Internal Server Error: /api/auth/user/patient
Traceback (most recent call last):
  File "D:\Fanshawe\capstone\recover_smart\venv\Lib\site-packages\django\core\handlers\exception.py", line 55, in inner
    response = get_response(request)
  File "D:\Fanshawe\capstone\recover_smart\venv\Lib\site-packages\django\core\handlers\base.py", line 220, in _get_response
    response = response.render()
  File "D:\Fanshawe\capstone\recover_smart\venv\Lib\site-packages\django\template\response.py", line 114, in render
    self.content = self.rendered_content
                   ^^^^^^^^^^^^^^^^^^^^^
  File "D:\Fanshawe\capstone\recover_smart\venv\Lib\site-packages\rest_framework\response.py", line 59, in rendered_content
    assert renderer, ".accepted_renderer not set on Response"
           ^^^^^^^^
AssertionError: .accepted_renderer not set on Response
"GET /api/auth/user/patient HTTP/1.1" 500 83845
D:\Fanshawe\capstone\recover_smart\patients\views.py changed, reloading.
Watching for file changes with StatReloader
Internal Server Error: /api/auth/user/patient
Traceback (most recent call last):
  File "D:\Fanshawe\capstone\recover_smart\venv\Lib\site-packages\django\core\handlers\exception.py", line 55, in inner
    response = get_response(request)
  File "D:\Fanshawe\capstone\recover_smart\venv\Lib\site-packages\django\core\handlers\base.py", line 220, in _get_response
    response = response.render()
  File "D:\Fanshawe\capstone\recover_smart\venv\Lib\site-packages\django\template\response.py", line 114, in render
    self.content = self.rendered_content
                   ^^^^^^^^^^^^^^^^^^^^^
  File "D:\Fanshawe\capstone\recover_smart\venv\Lib\site-packages\rest_framework\response.py", line 59, in rendered_content
    assert renderer, ".accepted_renderer not set on Response"
           ^^^^^^^^
AssertionError: .accepted_renderer not set on Response
"GET /api/auth/user/patient HTTP/1.1" 500 83845
Internal Server Error: /api/auth/user/patient
Traceback (most recent call last):
  File "D:\Fanshawe\capstone\recover_smart\venv\Lib\site-packages\django\core\handlers\exception.py", line 55, in inner
    response = get_response(request)
  File "D:\Fanshawe\capstone\recover_smart\venv\Lib\site-packages\django\core\handlers\base.py", line 220, in _get_response
    response = response.render()
  File "D:\Fanshawe\capstone\recover_smart\venv\Lib\site-packages\django\template\response.py", line 114, in render
    self.content = self.rendered_content
                   ^^^^^^^^^^^^^^^^^^^^^
  File "D:\Fanshawe\capstone\recover_smart\venv\Lib\site-packages\rest_framework\response.py", line 59, in rendered_content
    assert renderer, ".accepted_renderer not set on Response"
           ^^^^^^^^
AssertionError: .accepted_renderer not set on Response
"GET /api/auth/user/patient HTTP/1.1" 500 83845
D:\Fanshawe\capstone\recover_smart\patients\views.py changed, reloading.
Watching for file changes with StatReloader
D:\Fanshawe\capstone\recover_smart\patients\views.py changed, reloading.
Watching for file changes with StatReloader
Internal Server Error: /api/auth/user/patient
Traceback (most recent call last):
  File "D:\Fanshawe\capstone\recover_smart\venv\Lib\site-packages\django\core\handlers\exception.py", line 55, in inner
    response = get_response(request)
  File "D:\Fanshawe\capstone\recover_smart\venv\Lib\site-packages\django\core\handlers\base.py", line 220, in _get_response
    response = response.render()
  File "D:\Fanshawe\capstone\recover_smart\venv\Lib\site-packages\django\template\response.py", line 114, in render
    self.content = self.rendered_content
                   ^^^^^^^^^^^^^^^^^^^^^
  File "D:\Fanshawe\capstone\recover_smart\venv\Lib\site-packages\rest_framework\response.py", line 59, in rendered_content
    assert renderer, ".accepted_renderer not set on Response"
           ^^^^^^^^
AssertionError: .accepted_renderer not set on Response
"GET /api/auth/user/patient HTTP/1.1" 500 83845
D:\Fanshawe\capstone\recover_smart\patients\views.py changed, reloading.
Watching for file changes with StatReloader
Internal Server Error: /api/auth/user/patient
Traceback (most recent call last):
  File "D:\Fanshawe\capstone\recover_smart\venv\Lib\site-packages\django\db\models\fields\__init__.py", line 2123, in get_prep_value
    return int(value)
TypeError: int() argument must be a string, a bytes-like object or a real number, not 'SimpleLazyObject'

The above exception was the direct cause of the following exception:

Traceback (most recent call last):
  File "D:\Fanshawe\capstone\recover_smart\venv\Lib\site-packages\django\core\handlers\exception.py", line 55, in inner
    response = get_response(request)
  File "D:\Fanshawe\capstone\recover_smart\venv\Lib\site-packages\django\core\handlers\base.py", line 197, in _get_response
    response = wrapped_callback(request, *callback_args, **callback_kwargs)
  File "D:\Fanshawe\capstone\recover_smart\patients\views.py", line 119, in userPatient
    patient = Patient.objects.prefetch_related("medical_records").get(user=user)
  File "D:\Fanshawe\capstone\recover_smart\venv\Lib\site-packages\django\db\models\query.py", line 635, in get
    clone = self._chain() if self.query.combinator else self.filter(*args, **kwargs)
                                                        ~~~~~~~~~~~^^^^^^^^^^^^^^^^^
  File "D:\Fanshawe\capstone\recover_smart\venv\Lib\site-packages\django\db\models\query.py", line 1476, in filter
    return self._filter_or_exclude(False, args, kwargs)
           ~~~~~~~~~~~~~~~~~~~~~~~^^^^^^^^^^^^^^^^^^^^^
  File "D:\Fanshawe\capstone\recover_smart\venv\Lib\site-packages\django\db\models\query.py", line 1494, in _filter_or_exclude
    clone._filter_or_exclude_inplace(negate, args, kwargs)
    ~~~~~~~~~~~~~~~~~~~~~~~~~~~~~~~~^^^^^^^^^^^^^^^^^^^^^^
  File "D:\Fanshawe\capstone\recover_smart\venv\Lib\site-packages\django\db\models\query.py", line 1501, in _filter_or_exclude_inplace
    self._query.add_q(Q(*args, **kwargs))
    ~~~~~~~~~~~~~~~~~^^^^^^^^^^^^^^^^^^^^
  File "D:\Fanshawe\capstone\recover_smart\venv\Lib\site-packages\django\db\models\sql\query.py", line 1609, in add_q
    clause, _ = self._add_q(q_object, self.used_aliases)
                ~~~~~~~~~~~^^^^^^^^^^^^^^^^^^^^^^^^^^^^^
  File "D:\Fanshawe\capstone\recover_smart\venv\Lib\site-packages\django\db\models\sql\query.py", line 1641, in _add_q
    child_clause, needed_inner = self.build_filter(
                                 ~~~~~~~~~~~~~~~~~^
        child,
        ^^^^^^
    ...<7 lines>...
        update_join_types=update_join_types,
        ^^^^^^^^^^^^^^^^^^^^^^^^^^^^^^^^^^^^
    )
    ^
  File "D:\Fanshawe\capstone\recover_smart\venv\Lib\site-packages\django\db\models\sql\query.py", line 1555, in build_filter
    condition = self.build_lookup(lookups, col, value)
  File "D:\Fanshawe\capstone\recover_smart\venv\Lib\site-packages\django\db\models\sql\query.py", line 1385, in build_lookup
    lookup = lookup_class(lhs, rhs)
  File "D:\Fanshawe\capstone\recover_smart\venv\Lib\site-packages\django\db\models\lookups.py", line 30, in __init__
    self.rhs = self.get_prep_lookup()
               ~~~~~~~~~~~~~~~~~~~~^^
  File "D:\Fanshawe\capstone\recover_smart\venv\Lib\site-packages\django\db\models\fields\related_lookups.py", line 156, in get_prep_lookup
    self.rhs = target_field.get_prep_value(self.rhs)
               ~~~~~~~~~~~~~~~~~~~~~~~~~~~^^^^^^^^^^
  File "D:\Fanshawe\capstone\recover_smart\venv\Lib\site-packages\django\db\models\fields\__init__.py", line 2125, in get_prep_value
    raise e.__class__(
        "Field '%s' expected a number but got %r." % (self.name, value),
    ) from e
TypeError: Field 'id' expected a number but got <SimpleLazyObject: <django.contrib.auth.models.AnonymousUser object at 0x0000012BDA86DD30>>.
"GET /api/auth/user/patient HTTP/1.1" 500 140244
D:\Fanshawe\capstone\recover_smart\patients\views.py changed, reloading.
Watching for file changes with StatReloader
D:\Fanshawe\capstone\recover_smart\patients\views.py changed, reloading.
Watching for file changes with StatReloader
Internal Server Error: /api/auth/user/patient
Traceback (most recent call last):
  File "D:\Fanshawe\capstone\recover_smart\venv\Lib\site-packages\django\core\handlers\exception.py", line 55, in inner
    response = get_response(request)
  File "D:\Fanshawe\capstone\recover_smart\venv\Lib\site-packages\django\core\handlers\base.py", line 220, in _get_response
    response = response.render()
  File "D:\Fanshawe\capstone\recover_smart\venv\Lib\site-packages\django\template\response.py", line 114, in render
    self.content = self.rendered_content
                   ^^^^^^^^^^^^^^^^^^^^^
  File "D:\Fanshawe\capstone\recover_smart\venv\Lib\site-packages\rest_framework\response.py", line 59, in rendered_content
    assert renderer, ".accepted_renderer not set on Response"
           ^^^^^^^^
AssertionError: .accepted_renderer not set on Response
"GET /api/auth/user/patient HTTP/1.1" 500 83845
D:\Fanshawe\capstone\recover_smart\patients\views.py changed, reloading.
Watching for file changes with StatReloader
D:\Fanshawe\capstone\recover_smart\patients\views.py changed, reloading.
Watching for file changes with StatReloader
Internal Server Error: /api/auth/user/patient
Traceback (most recent call last):
  File "D:\Fanshawe\capstone\recover_smart\venv\Lib\site-packages\django\core\handlers\exception.py", line 55, in inner
    response = get_response(request)
  File "D:\Fanshawe\capstone\recover_smart\venv\Lib\site-packages\django\core\handlers\base.py", line 220, in _get_response
    response = response.render()
  File "D:\Fanshawe\capstone\recover_smart\venv\Lib\site-packages\django\template\response.py", line 114, in render
    self.content = self.rendered_content
                   ^^^^^^^^^^^^^^^^^^^^^
  File "D:\Fanshawe\capstone\recover_smart\venv\Lib\site-packages\rest_framework\response.py", line 59, in rendered_content
    assert renderer, ".accepted_renderer not set on Response"
           ^^^^^^^^
AssertionError: .accepted_renderer not set on Response
"GET /api/auth/user/patient HTTP/1.1" 500 83845
D:\Fanshawe\capstone\recover_smart\patients\views.py changed, reloading.
Watching for file changes with StatReloader
Internal Server Error: /api/auth/user/patient
Traceback (most recent call last):
  File "D:\Fanshawe\capstone\recover_smart\venv\Lib\site-packages\django\core\handlers\exception.py", line 55, in inner
    response = get_response(request)
  File "D:\Fanshawe\capstone\recover_smart\venv\Lib\site-packages\django\core\handlers\base.py", line 220, in _get_response
    response = response.render()
  File "D:\Fanshawe\capstone\recover_smart\venv\Lib\site-packages\django\template\response.py", line 114, in render
    self.content = self.rendered_content
                   ^^^^^^^^^^^^^^^^^^^^^
  File "D:\Fanshawe\capstone\recover_smart\venv\Lib\site-packages\rest_framework\response.py", line 59, in rendered_content
    assert renderer, ".accepted_renderer not set on Response"
           ^^^^^^^^
AssertionError: .accepted_renderer not set on Response
"GET /api/auth/user/patient HTTP/1.1" 500 83845
D:\Fanshawe\capstone\recover_smart\patients\views.py changed, reloading.
Watching for file changes with StatReloader
D:\Fanshawe\capstone\recover_smart\patients\views.py changed, reloading.
Watching for file changes with StatReloader
D:\Fanshawe\capstone\recover_smart\patients\views.py changed, reloading.
Watching for file changes with StatReloader
D:\Fanshawe\capstone\recover_smart\patients\views.py changed, reloading.
Watching for file changes with StatReloader
D:\Fanshawe\capstone\recover_smart\patients\views.py changed, reloading.
Watching for file changes with StatReloader
Internal Server Error: /api/auth/user/patient
Traceback (most recent call last):
  File "D:\Fanshawe\capstone\recover_smart\venv\Lib\site-packages\django\core\handlers\exception.py", line 55, in inner
    response = get_response(request)
  File "D:\Fanshawe\capstone\recover_smart\venv\Lib\site-packages\django\core\handlers\base.py", line 220, in _get_response
    response = response.render()
  File "D:\Fanshawe\capstone\recover_smart\venv\Lib\site-packages\django\template\response.py", line 114, in render
    self.content = self.rendered_content
                   ^^^^^^^^^^^^^^^^^^^^^
  File "D:\Fanshawe\capstone\recover_smart\venv\Lib\site-packages\rest_framework\response.py", line 59, in rendered_content
    assert renderer, ".accepted_renderer not set on Response"
           ^^^^^^^^
AssertionError: .accepted_renderer not set on Response
"GET /api/auth/user/patient HTTP/1.1" 500 83845
Watching for file changes with StatReloader
"POST /api/auth/ HTTP/1.1" 200 483
"GET //api/patients/ HTTP/1.1" 200 283
"GET //api/checklists/ HTTP/1.1" 200 2
"GET //api/medical_record/2 HTTP/1.1" 200 2
Not Found: /api/home/
"POST /api/home/ HTTP/1.1" 404 6594
Internal Server Error: /api/users
Traceback (most recent call last):
  File "C:\Users\moham\AppData\Local\Programs\Python\Python313\Lib\smtplib.py", line 398, in getreply
    line = self.file.readline(_MAXLINE + 1)
  File "C:\Users\moham\AppData\Local\Programs\Python\Python313\Lib\socket.py", line 719, in readinto
    return self._sock.recv_into(b)
           ~~~~~~~~~~~~~~~~~~~~^^^
ConnectionAbortedError: [WinError 10053] An established connection was aborted by the software in your host machine

During handling of the above exception, another exception occurred:

Traceback (most recent call last):
  File "D:\Fanshawe\capstone\recover_smart\users\services.py", line 29, in create_user_and_send_email
    email.send()  # Send the email
    ~~~~~~~~~~^^
  File "D:\Fanshawe\capstone\recover_smart\venv\Lib\site-packages\django\core\mail\message.py", line 301, in send
    return self.get_connection(fail_silently).send_messages([self])
           ~~~~~~~~~~~~~~~~~~~~~~~~~~~~~~~~~~~~~~~~~~~~~~~~^^^^^^^^
  File "D:\Fanshawe\capstone\recover_smart\venv\Lib\site-packages\django\core\mail\backends\smtp.py", line 128, in send_messages
    new_conn_created = self.open()
  File "D:\Fanshawe\capstone\recover_smart\venv\Lib\site-packages\django\core\mail\backends\smtp.py", line 86, in open
    self.connection = self.connection_class(
                      ~~~~~~~~~~~~~~~~~~~~~^
        self.host, self.port, **connection_params
        ^^^^^^^^^^^^^^^^^^^^^^^^^^^^^^^^^^^^^^^^^
    )
    ^
  File "C:\Users\moham\AppData\Local\Programs\Python\Python313\Lib\smtplib.py", line 255, in __init__
    (code, msg) = self.connect(host, port)
                  ~~~~~~~~~~~~^^^^^^^^^^^^
  File "C:\Users\moham\AppData\Local\Programs\Python\Python313\Lib\smtplib.py", line 343, in connect
    (code, msg) = self.getreply()
                  ~~~~~~~~~~~~~^^
  File "C:\Users\moham\AppData\Local\Programs\Python\Python313\Lib\smtplib.py", line 401, in getreply
    raise SMTPServerDisconnected("Connection unexpectedly closed: "
                                 + str(e))
smtplib.SMTPServerDisconnected: Connection unexpectedly closed: [WinError 10053] An established connection was aborted by the software in your host machine

During handling of the above exception, another exception occurred:

Traceback (most recent call last):
  File "D:\Fanshawe\capstone\recover_smart\venv\Lib\site-packages\django\core\handlers\exception.py", line 55, in inner
    response = get_response(request)
  File "D:\Fanshawe\capstone\recover_smart\venv\Lib\site-packages\django\core\handlers\base.py", line 197, in _get_response
    response = wrapped_callback(request, *callback_args, **callback_kwargs)
  File "D:\Fanshawe\capstone\recover_smart\venv\Lib\site-packages\django\views\decorators\csrf.py", line 65, in _view_wrapper
    return view_func(request, *args, **kwargs)
  File "D:\Fanshawe\capstone\recover_smart\venv\Lib\site-packages\django\views\generic\base.py", line 104, in view
    return self.dispatch(request, *args, **kwargs)
           ~~~~~~~~~~~~~^^^^^^^^^^^^^^^^^^^^^^^^^^
  File "D:\Fanshawe\capstone\recover_smart\venv\Lib\site-packages\rest_framework\views.py", line 509, in dispatch
    response = self.handle_exception(exc)
  File "D:\Fanshawe\capstone\recover_smart\venv\Lib\site-packages\rest_framework\views.py", line 469, in handle_exception
    self.raise_uncaught_exception(exc)
    ~~~~~~~~~~~~~~~~~~~~~~~~~~~~~^^^^^
  File "D:\Fanshawe\capstone\recover_smart\venv\Lib\site-packages\rest_framework\views.py", line 480, in raise_uncaught_exception
    raise exc
  File "D:\Fanshawe\capstone\recover_smart\venv\Lib\site-packages\rest_framework\views.py", line 506, in dispatch
    response = handler(request, *args, **kwargs)
  File "D:\Fanshawe\capstone\recover_smart\users\views.py", line 87, in post
    create_user_and_send_email(user=user)
    ~~~~~~~~~~~~~~~~~~~~~~~~~~^^^^^^^^^^^
  File "D:\Fanshawe\capstone\recover_smart\users\services.py", line 33, in create_user_and_send_email
    raise ValueError(f"Error creating user: {str(e)}")
ValueError: Error creating user: Connection unexpectedly closed: [WinError 10053] An established connection was aborted by the software in your host machine
- Broken pipe from ('127.0.0.1', 52940)
Internal Server Error: /api/auth/user/patient
Traceback (most recent call last):
  File "D:\Fanshawe\capstone\recover_smart\venv\Lib\site-packages\django\core\handlers\exception.py", line 55, in inner
    response = get_response(request)
  File "D:\Fanshawe\capstone\recover_smart\venv\Lib\site-packages\django\core\handlers\base.py", line 220, in _get_response
    response = response.render()
  File "D:\Fanshawe\capstone\recover_smart\venv\Lib\site-packages\django\template\response.py", line 114, in render
    self.content = self.rendered_content
                   ^^^^^^^^^^^^^^^^^^^^^
  File "D:\Fanshawe\capstone\recover_smart\venv\Lib\site-packages\rest_framework\response.py", line 59, in rendered_content
    assert renderer, ".accepted_renderer not set on Response"
           ^^^^^^^^
AssertionError: .accepted_renderer not set on Response
"GET /api/auth/user/patient HTTP/1.1" 500 83845
D:\Fanshawe\capstone\recover_smart\patients\views.py changed, reloading.
Watching for file changes with StatReloader
D:\Fanshawe\capstone\recover_smart\patients\views.py changed, reloading.
Watching for file changes with StatReloader
Unauthorized: /api/auth/user/patient
"GET /api/auth/user/patient HTTP/1.1" 401 58
"POST /api/auth/ HTTP/1.1" 200 483
Unauthorized: /api/auth/user/patient
"GET /api/auth/user/patient HTTP/1.1" 401 58
Not Found: /api/auth/user/patient
"GET /api/auth/user/patient HTTP/1.1" 404 29
Watching for file changes with StatReloader
Watching for file changes with StatReloader
Watching for file changes with StatReloader
Watching for file changes with StatReloader
Watching for file changes with StatReloader
Watching for file changes with StatReloader
"GET / HTTP/1.1" 200 13
Not Found: /favicon.ico
"GET /favicon.ico HTTP/1.1" 404 6599
Unauthorized: /api/auth/
"POST /api/auth/ HTTP/1.1" 401 63
"POST /api/auth/ HTTP/1.1" 200 483
Unauthorized: /api/patients/
"POST /api/patients/ HTTP/1.1" 401 176
Internal Server Error: /api/patients/
Traceback (most recent call last):
  File "D:\Fanshawe\capstone\recover_smart\venv\Lib\site-packages\django\core\handlers\exception.py", line 55, in inner
    response = get_response(request)
  File "D:\Fanshawe\capstone\recover_smart\venv\Lib\site-packages\django\core\handlers\base.py", line 197, in _get_response
    response = wrapped_callback(request, *callback_args, **callback_kwargs)
  File "D:\Fanshawe\capstone\recover_smart\venv\Lib\site-packages\django\views\decorators\csrf.py", line 65, in _view_wrapper
    return view_func(request, *args, **kwargs)
  File "D:\Fanshawe\capstone\recover_smart\venv\Lib\site-packages\django\views\generic\base.py", line 104, in view
    return self.dispatch(request, *args, **kwargs)
           ~~~~~~~~~~~~~^^^^^^^^^^^^^^^^^^^^^^^^^^
  File "D:\Fanshawe\capstone\recover_smart\venv\Lib\site-packages\rest_framework\views.py", line 509, in dispatch
    response = self.handle_exception(exc)
  File "D:\Fanshawe\capstone\recover_smart\venv\Lib\site-packages\rest_framework\views.py", line 469, in handle_exception
    self.raise_uncaught_exception(exc)
    ~~~~~~~~~~~~~~~~~~~~~~~~~~~~~^^^^^
  File "D:\Fanshawe\capstone\recover_smart\venv\Lib\site-packages\rest_framework\views.py", line 480, in raise_uncaught_exception
    raise exc
  File "D:\Fanshawe\capstone\recover_smart\venv\Lib\site-packages\rest_framework\views.py", line 506, in dispatch
    response = handler(request, *args, **kwargs)
  File "D:\Fanshawe\capstone\recover_smart\patients\views.py", line 88, in post
    return Response(user.errors, status=400)
                    ^^^^
UnboundLocalError: cannot access local variable 'user' where it is not associated with a value
"POST /api/patients/ HTTP/1.1" 500 110502
Internal Server Error: /api/patients/
Traceback (most recent call last):
  File "D:\Fanshawe\capstone\recover_smart\venv\Lib\site-packages\django\core\handlers\exception.py", line 55, in inner
    response = get_response(request)
  File "D:\Fanshawe\capstone\recover_smart\venv\Lib\site-packages\django\core\handlers\base.py", line 197, in _get_response
    response = wrapped_callback(request, *callback_args, **callback_kwargs)
  File "D:\Fanshawe\capstone\recover_smart\venv\Lib\site-packages\django\views\decorators\csrf.py", line 65, in _view_wrapper
    return view_func(request, *args, **kwargs)
  File "D:\Fanshawe\capstone\recover_smart\venv\Lib\site-packages\django\views\generic\base.py", line 104, in view
    return self.dispatch(request, *args, **kwargs)
           ~~~~~~~~~~~~~^^^^^^^^^^^^^^^^^^^^^^^^^^
  File "D:\Fanshawe\capstone\recover_smart\venv\Lib\site-packages\rest_framework\views.py", line 509, in dispatch
    response = self.handle_exception(exc)
  File "D:\Fanshawe\capstone\recover_smart\venv\Lib\site-packages\rest_framework\views.py", line 469, in handle_exception
    self.raise_uncaught_exception(exc)
    ~~~~~~~~~~~~~~~~~~~~~~~~~~~~~^^^^^
  File "D:\Fanshawe\capstone\recover_smart\venv\Lib\site-packages\rest_framework\views.py", line 480, in raise_uncaught_exception
    raise exc
  File "D:\Fanshawe\capstone\recover_smart\venv\Lib\site-packages\rest_framework\views.py", line 506, in dispatch
    response = handler(request, *args, **kwargs)
  File "D:\Fanshawe\capstone\recover_smart\patients\views.py", line 88, in post
    return Response(user.errors, status=400)
                    ^^^^
UnboundLocalError: cannot access local variable 'user' where it is not associated with a value
"POST /api/patients/ HTTP/1.1" 500 110502
"GET /api/patients/ HTTP/1.1" 200 427
Internal Server Error: /api/patients/
Traceback (most recent call last):
  File "D:\Fanshawe\capstone\recover_smart\venv\Lib\site-packages\django\core\handlers\exception.py", line 55, in inner
    response = get_response(request)
  File "D:\Fanshawe\capstone\recover_smart\venv\Lib\site-packages\django\core\handlers\base.py", line 197, in _get_response
    response = wrapped_callback(request, *callback_args, **callback_kwargs)
  File "D:\Fanshawe\capstone\recover_smart\venv\Lib\site-packages\django\views\decorators\csrf.py", line 65, in _view_wrapper
    return view_func(request, *args, **kwargs)
  File "D:\Fanshawe\capstone\recover_smart\venv\Lib\site-packages\django\views\generic\base.py", line 104, in view
    return self.dispatch(request, *args, **kwargs)
           ~~~~~~~~~~~~~^^^^^^^^^^^^^^^^^^^^^^^^^^
  File "D:\Fanshawe\capstone\recover_smart\venv\Lib\site-packages\rest_framework\views.py", line 509, in dispatch
    response = self.handle_exception(exc)
  File "D:\Fanshawe\capstone\recover_smart\venv\Lib\site-packages\rest_framework\views.py", line 469, in handle_exception
    self.raise_uncaught_exception(exc)
    ~~~~~~~~~~~~~~~~~~~~~~~~~~~~~^^^^^
  File "D:\Fanshawe\capstone\recover_smart\venv\Lib\site-packages\rest_framework\views.py", line 480, in raise_uncaught_exception
    raise exc
  File "D:\Fanshawe\capstone\recover_smart\venv\Lib\site-packages\rest_framework\views.py", line 506, in dispatch
    response = handler(request, *args, **kwargs)
  File "D:\Fanshawe\capstone\recover_smart\patients\views.py", line 88, in post
    return Response(user.errors, status=400)
                    ^^^^
UnboundLocalError: cannot access local variable 'user' where it is not associated with a value
"POST /api/patients/ HTTP/1.1" 500 110502
D:\Fanshawe\capstone\recover_smart\recoversmart\settings.py changed, reloading.
Watching for file changes with StatReloader
D:\Fanshawe\capstone\recover_smart\recoversmart\settings.py changed, reloading.
Watching for file changes with StatReloader
D:\Fanshawe\capstone\recover_smart\recoversmart\settings.py changed, reloading.
Watching for file changes with StatReloader
D:\Fanshawe\capstone\recover_smart\patients\views.py changed, reloading.
Watching for file changes with StatReloader
D:\Fanshawe\capstone\recover_smart\patients\views.py changed, reloading.
Watching for file changes with StatReloader
Internal Server Error: /api/patients/
Traceback (most recent call last):
  File "D:\Fanshawe\capstone\recover_smart\venv\Lib\site-packages\django\core\handlers\exception.py", line 55, in inner
    response = get_response(request)
  File "D:\Fanshawe\capstone\recover_smart\venv\Lib\site-packages\django\core\handlers\base.py", line 197, in _get_response
    response = wrapped_callback(request, *callback_args, **callback_kwargs)
  File "D:\Fanshawe\capstone\recover_smart\venv\Lib\site-packages\django\views\decorators\csrf.py", line 65, in _view_wrapper
    return view_func(request, *args, **kwargs)
  File "D:\Fanshawe\capstone\recover_smart\venv\Lib\site-packages\django\views\generic\base.py", line 104, in view
    return self.dispatch(request, *args, **kwargs)
           ~~~~~~~~~~~~~^^^^^^^^^^^^^^^^^^^^^^^^^^
  File "D:\Fanshawe\capstone\recover_smart\venv\Lib\site-packages\rest_framework\views.py", line 509, in dispatch
    response = self.handle_exception(exc)
  File "D:\Fanshawe\capstone\recover_smart\venv\Lib\site-packages\rest_framework\views.py", line 469, in handle_exception
    self.raise_uncaught_exception(exc)
    ~~~~~~~~~~~~~~~~~~~~~~~~~~~~~^^^^^
  File "D:\Fanshawe\capstone\recover_smart\venv\Lib\site-packages\rest_framework\views.py", line 480, in raise_uncaught_exception
    raise exc
  File "D:\Fanshawe\capstone\recover_smart\venv\Lib\site-packages\rest_framework\views.py", line 506, in dispatch
    response = handler(request, *args, **kwargs)
  File "D:\Fanshawe\capstone\recover_smart\patients\views.py", line 88, in post
    return Response(user.errors, status=400)
                    ^^^^
UnboundLocalError: cannot access local variable 'user' where it is not associated with a value
"POST /api/patients/ HTTP/1.1" 500 110365
"POST /api/patients/ HTTP/1.1" 201 164
D:\Fanshawe\capstone\recover_smart\patients\views.py changed, reloading.
Watching for file changes with StatReloader
D:\Fanshawe\capstone\recover_smart\patients\views.py changed, reloading.
Watching for file changes with StatReloader
D:\Fanshawe\capstone\recover_smart\users\services.py changed, reloading.
Watching for file changes with StatReloader
D:\Fanshawe\capstone\recover_smart\users\services.py changed, reloading.
Watching for file changes with StatReloader
D:\Fanshawe\capstone\recover_smart\users\services.py changed, reloading.
Watching for file changes with StatReloader
D:\Fanshawe\capstone\recover_smart\users\services.py changed, reloading.
Watching for file changes with StatReloader
D:\Fanshawe\capstone\recover_smart\users\services.py changed, reloading.
Watching for file changes with StatReloader
D:\Fanshawe\capstone\recover_smart\users\services.py changed, reloading.
Watching for file changes with StatReloader
D:\Fanshawe\capstone\recover_smart\users\services.py changed, reloading.
Watching for file changes with StatReloader
D:\Fanshawe\capstone\recover_smart\users\services.py changed, reloading.
Watching for file changes with StatReloader
"POST /api/patients/ HTTP/1.1" 201 164
"POST /api/auth/ HTTP/1.1" 200 486
Forbidden: /api/patients/
"GET /api/patients/ HTTP/1.1" 403 66
Forbidden: /api/medical_record/2
"GET /api/medical_record/2 HTTP/1.1" 403 66
D:\Fanshawe\capstone\recover_smart\medical_records\views.py changed, reloading.
Watching for file changes with StatReloader
"GET /api/medical_record/2 HTTP/1.1" 200 2
Forbidden: /api/medical_record
"POST /api/medical_record HTTP/1.1" 403 62
"POST /api/auth/ HTTP/1.1" 200 483
Bad Request: /api/medical_record
"POST /api/medical_record HTTP/1.1" 400 313
Bad Request: /api/medical_record
"POST /api/medical_record HTTP/1.1" 400 171
Bad Request: /api/medical_record
"POST /api/medical_record HTTP/1.1" 400 102
Bad Request: /api/medical_record
"POST /api/medical_record HTTP/1.1" 400 102
D:\Fanshawe\capstone\recover_smart\medical_records\serializers.py changed, reloading.
Watching for file changes with StatReloader
D:\Fanshawe\capstone\recover_smart\medical_records\views.py changed, reloading.
Watching for file changes with StatReloader
D:\Fanshawe\capstone\recover_smart\medical_records\views.py changed, reloading.
Watching for file changes with StatReloader
D:\Fanshawe\capstone\recover_smart\medical_records\views.py changed, reloading.
Watching for file changes with StatReloader
Bad Request: /api/medical_record
"POST /api/medical_record HTTP/1.1" 400 43
Internal Server Error: /api/medical_record
Traceback (most recent call last):
  File "D:\Fanshawe\capstone\recover_smart\venv\Lib\site-packages\django\db\backends\utils.py", line 105, in _execute
    return self.cursor.execute(sql, params)
           ~~~~~~~~~~~~~~~~~~~^^^^^^^^^^^^^
  File "D:\Fanshawe\capstone\recover_smart\venv\Lib\site-packages\django\db\backends\mysql\base.py", line 76, in execute
    return self.cursor.execute(query, args)
           ~~~~~~~~~~~~~~~~~~~^^^^^^^^^^^^^
  File "D:\Fanshawe\capstone\recover_smart\venv\Lib\site-packages\pymysql\cursors.py", line 153, in execute
    result = self._query(query)
  File "D:\Fanshawe\capstone\recover_smart\venv\Lib\site-packages\pymysql\cursors.py", line 322, in _query
    conn.query(q)
    ~~~~~~~~~~^^^
  File "D:\Fanshawe\capstone\recover_smart\venv\Lib\site-packages\pymysql\connections.py", line 563, in query
    self._affected_rows = self._read_query_result(unbuffered=unbuffered)
                          ~~~~~~~~~~~~~~~~~~~~~~~^^^^^^^^^^^^^^^^^^^^^^^
  File "D:\Fanshawe\capstone\recover_smart\venv\Lib\site-packages\pymysql\connections.py", line 825, in _read_query_result
    result.read()
    ~~~~~~~~~~~^^
  File "D:\Fanshawe\capstone\recover_smart\venv\Lib\site-packages\pymysql\connections.py", line 1199, in read
    first_packet = self.connection._read_packet()
  File "D:\Fanshawe\capstone\recover_smart\venv\Lib\site-packages\pymysql\connections.py", line 775, in _read_packet
    packet.raise_for_error()
    ~~~~~~~~~~~~~~~~~~~~~~^^
  File "D:\Fanshawe\capstone\recover_smart\venv\Lib\site-packages\pymysql\protocol.py", line 219, in raise_for_error
    err.raise_mysql_exception(self._data)
    ~~~~~~~~~~~~~~~~~~~~~~~~~^^^^^^^^^^^^
  File "D:\Fanshawe\capstone\recover_smart\venv\Lib\site-packages\pymysql\err.py", line 150, in raise_mysql_exception
    raise errorclass(errno, errval)
pymysql.err.IntegrityError: (1048, "Column 'created_by_id' cannot be null")

The above exception was the direct cause of the following exception:

Traceback (most recent call last):
  File "D:\Fanshawe\capstone\recover_smart\venv\Lib\site-packages\django\core\handlers\exception.py", line 55, in inner
    response = get_response(request)
  File "D:\Fanshawe\capstone\recover_smart\venv\Lib\site-packages\django\core\handlers\base.py", line 197, in _get_response
    response = wrapped_callback(request, *callback_args, **callback_kwargs)
  File "D:\Fanshawe\capstone\recover_smart\venv\Lib\site-packages\django\views\decorators\csrf.py", line 65, in _view_wrapper
    return view_func(request, *args, **kwargs)
  File "D:\Fanshawe\capstone\recover_smart\venv\Lib\site-packages\django\views\generic\base.py", line 104, in view
    return self.dispatch(request, *args, **kwargs)
           ~~~~~~~~~~~~~^^^^^^^^^^^^^^^^^^^^^^^^^^
  File "D:\Fanshawe\capstone\recover_smart\venv\Lib\site-packages\rest_framework\views.py", line 509, in dispatch
    response = self.handle_exception(exc)
  File "D:\Fanshawe\capstone\recover_smart\venv\Lib\site-packages\rest_framework\views.py", line 469, in handle_exception
    self.raise_uncaught_exception(exc)
    ~~~~~~~~~~~~~~~~~~~~~~~~~~~~~^^^^^
  File "D:\Fanshawe\capstone\recover_smart\venv\Lib\site-packages\rest_framework\views.py", line 480, in raise_uncaught_exception
    raise exc
  File "D:\Fanshawe\capstone\recover_smart\venv\Lib\site-packages\rest_framework\views.py", line 506, in dispatch
    response = handler(request, *args, **kwargs)
  File "D:\Fanshawe\capstone\recover_smart\medical_records\views.py", line 40, in post
    serializer.save()
    ~~~~~~~~~~~~~~~^^
  File "D:\Fanshawe\capstone\recover_smart\venv\Lib\site-packages\rest_framework\serializers.py", line 208, in save
    self.instance = self.create(validated_data)
                    ~~~~~~~~~~~^^^^^^^^^^^^^^^^
  File "D:\Fanshawe\capstone\recover_smart\venv\Lib\site-packages\rest_framework\serializers.py", line 989, in create
    instance = ModelClass._default_manager.create(**validated_data)
  File "D:\Fanshawe\capstone\recover_smart\venv\Lib\site-packages\django\db\models\manager.py", line 87, in manager_method
    return getattr(self.get_queryset(), name)(*args, **kwargs)
           ~~~~~~~~~~~~~~~~~~~~~~~~~~~~~~~~~~^^^^^^^^^^^^^^^^^
  File "D:\Fanshawe\capstone\recover_smart\venv\Lib\site-packages\django\db\models\query.py", line 679, in create
    obj.save(force_insert=True, using=self.db)
    ~~~~~~~~^^^^^^^^^^^^^^^^^^^^^^^^^^^^^^^^^^
  File "D:\Fanshawe\capstone\recover_smart\venv\Lib\site-packages\django\db\models\base.py", line 892, in save
    self.save_base(
    ~~~~~~~~~~~~~~^
        using=using,
        ^^^^^^^^^^^^
    ...<2 lines>...
        update_fields=update_fields,
        ^^^^^^^^^^^^^^^^^^^^^^^^^^^^
    )
    ^
  File "D:\Fanshawe\capstone\recover_smart\venv\Lib\site-packages\django\db\models\base.py", line 998, in save_base
    updated = self._save_table(
        raw,
    ...<4 lines>...
        update_fields,
    )
  File "D:\Fanshawe\capstone\recover_smart\venv\Lib\site-packages\django\db\models\base.py", line 1161, in _save_table
    results = self._do_insert(
        cls._base_manager, using, fields, returning_fields, raw
    )
  File "D:\Fanshawe\capstone\recover_smart\venv\Lib\site-packages\django\db\models\base.py", line 1202, in _do_insert
    return manager._insert(
           ~~~~~~~~~~~~~~~^
        [self],
        ^^^^^^^
    ...<3 lines>...
        raw=raw,
        ^^^^^^^^
    )
    ^
  File "D:\Fanshawe\capstone\recover_smart\venv\Lib\site-packages\django\db\models\manager.py", line 87, in manager_method
    return getattr(self.get_queryset(), name)(*args, **kwargs)
           ~~~~~~~~~~~~~~~~~~~~~~~~~~~~~~~~~~^^^^^^^^^^^^^^^^^
  File "D:\Fanshawe\capstone\recover_smart\venv\Lib\site-packages\django\db\models\query.py", line 1847, in _insert
    return query.get_compiler(using=using).execute_sql(returning_fields)
           ~~~~~~~~~~~~~~~~~~~~~~~~~~~~~~~~~~~~~~~~~~~^^^^^^^^^^^^^^^^^^
  File "D:\Fanshawe\capstone\recover_smart\venv\Lib\site-packages\django\db\models\sql\compiler.py", line 1836, in execute_sql
    cursor.execute(sql, params)
    ~~~~~~~~~~~~~~^^^^^^^^^^^^^
  File "D:\Fanshawe\capstone\recover_smart\venv\Lib\site-packages\django\db\backends\utils.py", line 122, in execute
    return super().execute(sql, params)
           ~~~~~~~~~~~~~~~^^^^^^^^^^^^^
  File "D:\Fanshawe\capstone\recover_smart\venv\Lib\site-packages\django\db\backends\utils.py", line 79, in execute
    return self._execute_with_wrappers(
           ~~~~~~~~~~~~~~~~~~~~~~~~~~~^
        sql, params, many=False, executor=self._execute
        ^^^^^^^^^^^^^^^^^^^^^^^^^^^^^^^^^^^^^^^^^^^^^^^
    )
    ^
  File "D:\Fanshawe\capstone\recover_smart\venv\Lib\site-packages\django\db\backends\utils.py", line 92, in _execute_with_wrappers
    return executor(sql, params, many, context)
  File "D:\Fanshawe\capstone\recover_smart\venv\Lib\site-packages\django\db\backends\utils.py", line 100, in _execute
    with self.db.wrap_database_errors:
         ^^^^^^^^^^^^^^^^^^^^^^^^^^^^
  File "D:\Fanshawe\capstone\recover_smart\venv\Lib\site-packages\django\db\utils.py", line 91, in __exit__
    raise dj_exc_value.with_traceback(traceback) from exc_value
  File "D:\Fanshawe\capstone\recover_smart\venv\Lib\site-packages\django\db\backends\utils.py", line 105, in _execute
    return self.cursor.execute(sql, params)
           ~~~~~~~~~~~~~~~~~~~^^^^^^^^^^^^^
  File "D:\Fanshawe\capstone\recover_smart\venv\Lib\site-packages\django\db\backends\mysql\base.py", line 76, in execute
    return self.cursor.execute(query, args)
           ~~~~~~~~~~~~~~~~~~~^^^^^^^^^^^^^
  File "D:\Fanshawe\capstone\recover_smart\venv\Lib\site-packages\pymysql\cursors.py", line 153, in execute
    result = self._query(query)
  File "D:\Fanshawe\capstone\recover_smart\venv\Lib\site-packages\pymysql\cursors.py", line 322, in _query
    conn.query(q)
    ~~~~~~~~~~^^^
  File "D:\Fanshawe\capstone\recover_smart\venv\Lib\site-packages\pymysql\connections.py", line 563, in query
    self._affected_rows = self._read_query_result(unbuffered=unbuffered)
                          ~~~~~~~~~~~~~~~~~~~~~~~^^^^^^^^^^^^^^^^^^^^^^^
  File "D:\Fanshawe\capstone\recover_smart\venv\Lib\site-packages\pymysql\connections.py", line 825, in _read_query_result
    result.read()
    ~~~~~~~~~~~^^
  File "D:\Fanshawe\capstone\recover_smart\venv\Lib\site-packages\pymysql\connections.py", line 1199, in read
    first_packet = self.connection._read_packet()
  File "D:\Fanshawe\capstone\recover_smart\venv\Lib\site-packages\pymysql\connections.py", line 775, in _read_packet
    packet.raise_for_error()
    ~~~~~~~~~~~~~~~~~~~~~~^^
  File "D:\Fanshawe\capstone\recover_smart\venv\Lib\site-packages\pymysql\protocol.py", line 219, in raise_for_error
    err.raise_mysql_exception(self._data)
    ~~~~~~~~~~~~~~~~~~~~~~~~~^^^^^^^^^^^^
  File "D:\Fanshawe\capstone\recover_smart\venv\Lib\site-packages\pymysql\err.py", line 150, in raise_mysql_exception
    raise errorclass(errno, errval)
django.db.utils.IntegrityError: (1048, "Column 'created_by_id' cannot be null")
"POST /api/medical_record HTTP/1.1" 500 285684
D:\Fanshawe\capstone\recover_smart\medical_records\views.py changed, reloading.
Watching for file changes with StatReloader
Internal Server Error: /api/medical_record
Traceback (most recent call last):
  File "D:\Fanshawe\capstone\recover_smart\venv\Lib\site-packages\django\db\backends\utils.py", line 105, in _execute
    return self.cursor.execute(sql, params)
           ~~~~~~~~~~~~~~~~~~~^^^^^^^^^^^^^
  File "D:\Fanshawe\capstone\recover_smart\venv\Lib\site-packages\django\db\backends\mysql\base.py", line 76, in execute
    return self.cursor.execute(query, args)
           ~~~~~~~~~~~~~~~~~~~^^^^^^^^^^^^^
  File "D:\Fanshawe\capstone\recover_smart\venv\Lib\site-packages\pymysql\cursors.py", line 153, in execute
    result = self._query(query)
  File "D:\Fanshawe\capstone\recover_smart\venv\Lib\site-packages\pymysql\cursors.py", line 322, in _query
    conn.query(q)
    ~~~~~~~~~~^^^
  File "D:\Fanshawe\capstone\recover_smart\venv\Lib\site-packages\pymysql\connections.py", line 563, in query
    self._affected_rows = self._read_query_result(unbuffered=unbuffered)
                          ~~~~~~~~~~~~~~~~~~~~~~~^^^^^^^^^^^^^^^^^^^^^^^
  File "D:\Fanshawe\capstone\recover_smart\venv\Lib\site-packages\pymysql\connections.py", line 825, in _read_query_result
    result.read()
    ~~~~~~~~~~~^^
  File "D:\Fanshawe\capstone\recover_smart\venv\Lib\site-packages\pymysql\connections.py", line 1199, in read
    first_packet = self.connection._read_packet()
  File "D:\Fanshawe\capstone\recover_smart\venv\Lib\site-packages\pymysql\connections.py", line 775, in _read_packet
    packet.raise_for_error()
    ~~~~~~~~~~~~~~~~~~~~~~^^
  File "D:\Fanshawe\capstone\recover_smart\venv\Lib\site-packages\pymysql\protocol.py", line 219, in raise_for_error
    err.raise_mysql_exception(self._data)
    ~~~~~~~~~~~~~~~~~~~~~~~~~^^^^^^^^^^^^
  File "D:\Fanshawe\capstone\recover_smart\venv\Lib\site-packages\pymysql\err.py", line 150, in raise_mysql_exception
    raise errorclass(errno, errval)
pymysql.err.IntegrityError: (1048, "Column 'created_by_id' cannot be null")

The above exception was the direct cause of the following exception:

Traceback (most recent call last):
  File "D:\Fanshawe\capstone\recover_smart\venv\Lib\site-packages\django\core\handlers\exception.py", line 55, in inner
    response = get_response(request)
  File "D:\Fanshawe\capstone\recover_smart\venv\Lib\site-packages\django\core\handlers\base.py", line 197, in _get_response
    response = wrapped_callback(request, *callback_args, **callback_kwargs)
  File "D:\Fanshawe\capstone\recover_smart\venv\Lib\site-packages\django\views\decorators\csrf.py", line 65, in _view_wrapper
    return view_func(request, *args, **kwargs)
  File "D:\Fanshawe\capstone\recover_smart\venv\Lib\site-packages\django\views\generic\base.py", line 104, in view
    return self.dispatch(request, *args, **kwargs)
           ~~~~~~~~~~~~~^^^^^^^^^^^^^^^^^^^^^^^^^^
  File "D:\Fanshawe\capstone\recover_smart\venv\Lib\site-packages\rest_framework\views.py", line 509, in dispatch
    response = self.handle_exception(exc)
  File "D:\Fanshawe\capstone\recover_smart\venv\Lib\site-packages\rest_framework\views.py", line 469, in handle_exception
    self.raise_uncaught_exception(exc)
    ~~~~~~~~~~~~~~~~~~~~~~~~~~~~~^^^^^
  File "D:\Fanshawe\capstone\recover_smart\venv\Lib\site-packages\rest_framework\views.py", line 480, in raise_uncaught_exception
    raise exc
  File "D:\Fanshawe\capstone\recover_smart\venv\Lib\site-packages\rest_framework\views.py", line 506, in dispatch
    response = handler(request, *args, **kwargs)
  File "D:\Fanshawe\capstone\recover_smart\medical_records\views.py", line 40, in post
    serializer.save()
    ~~~~~~~~~~~~~~~^^
  File "D:\Fanshawe\capstone\recover_smart\venv\Lib\site-packages\rest_framework\serializers.py", line 208, in save
    self.instance = self.create(validated_data)
                    ~~~~~~~~~~~^^^^^^^^^^^^^^^^
  File "D:\Fanshawe\capstone\recover_smart\venv\Lib\site-packages\rest_framework\serializers.py", line 989, in create
    instance = ModelClass._default_manager.create(**validated_data)
  File "D:\Fanshawe\capstone\recover_smart\venv\Lib\site-packages\django\db\models\manager.py", line 87, in manager_method
    return getattr(self.get_queryset(), name)(*args, **kwargs)
           ~~~~~~~~~~~~~~~~~~~~~~~~~~~~~~~~~~^^^^^^^^^^^^^^^^^
  File "D:\Fanshawe\capstone\recover_smart\venv\Lib\site-packages\django\db\models\query.py", line 679, in create
    obj.save(force_insert=True, using=self.db)
    ~~~~~~~~^^^^^^^^^^^^^^^^^^^^^^^^^^^^^^^^^^
  File "D:\Fanshawe\capstone\recover_smart\venv\Lib\site-packages\django\db\models\base.py", line 892, in save
    self.save_base(
    ~~~~~~~~~~~~~~^
        using=using,
        ^^^^^^^^^^^^
    ...<2 lines>...
        update_fields=update_fields,
        ^^^^^^^^^^^^^^^^^^^^^^^^^^^^
    )
    ^
  File "D:\Fanshawe\capstone\recover_smart\venv\Lib\site-packages\django\db\models\base.py", line 998, in save_base
    updated = self._save_table(
        raw,
    ...<4 lines>...
        update_fields,
    )
  File "D:\Fanshawe\capstone\recover_smart\venv\Lib\site-packages\django\db\models\base.py", line 1161, in _save_table
    results = self._do_insert(
        cls._base_manager, using, fields, returning_fields, raw
    )
  File "D:\Fanshawe\capstone\recover_smart\venv\Lib\site-packages\django\db\models\base.py", line 1202, in _do_insert
    return manager._insert(
           ~~~~~~~~~~~~~~~^
        [self],
        ^^^^^^^
    ...<3 lines>...
        raw=raw,
        ^^^^^^^^
    )
    ^
  File "D:\Fanshawe\capstone\recover_smart\venv\Lib\site-packages\django\db\models\manager.py", line 87, in manager_method
    return getattr(self.get_queryset(), name)(*args, **kwargs)
           ~~~~~~~~~~~~~~~~~~~~~~~~~~~~~~~~~~^^^^^^^^^^^^^^^^^
  File "D:\Fanshawe\capstone\recover_smart\venv\Lib\site-packages\django\db\models\query.py", line 1847, in _insert
    return query.get_compiler(using=using).execute_sql(returning_fields)
           ~~~~~~~~~~~~~~~~~~~~~~~~~~~~~~~~~~~~~~~~~~~^^^^^^^^^^^^^^^^^^
  File "D:\Fanshawe\capstone\recover_smart\venv\Lib\site-packages\django\db\models\sql\compiler.py", line 1836, in execute_sql
    cursor.execute(sql, params)
    ~~~~~~~~~~~~~~^^^^^^^^^^^^^
  File "D:\Fanshawe\capstone\recover_smart\venv\Lib\site-packages\django\db\backends\utils.py", line 122, in execute
    return super().execute(sql, params)
           ~~~~~~~~~~~~~~~^^^^^^^^^^^^^
  File "D:\Fanshawe\capstone\recover_smart\venv\Lib\site-packages\django\db\backends\utils.py", line 79, in execute
    return self._execute_with_wrappers(
           ~~~~~~~~~~~~~~~~~~~~~~~~~~~^
        sql, params, many=False, executor=self._execute
        ^^^^^^^^^^^^^^^^^^^^^^^^^^^^^^^^^^^^^^^^^^^^^^^
    )
    ^
  File "D:\Fanshawe\capstone\recover_smart\venv\Lib\site-packages\django\db\backends\utils.py", line 92, in _execute_with_wrappers
    return executor(sql, params, many, context)
  File "D:\Fanshawe\capstone\recover_smart\venv\Lib\site-packages\django\db\backends\utils.py", line 100, in _execute
    with self.db.wrap_database_errors:
         ^^^^^^^^^^^^^^^^^^^^^^^^^^^^
  File "D:\Fanshawe\capstone\recover_smart\venv\Lib\site-packages\django\db\utils.py", line 91, in __exit__
    raise dj_exc_value.with_traceback(traceback) from exc_value
  File "D:\Fanshawe\capstone\recover_smart\venv\Lib\site-packages\django\db\backends\utils.py", line 105, in _execute
    return self.cursor.execute(sql, params)
           ~~~~~~~~~~~~~~~~~~~^^^^^^^^^^^^^
  File "D:\Fanshawe\capstone\recover_smart\venv\Lib\site-packages\django\db\backends\mysql\base.py", line 76, in execute
    return self.cursor.execute(query, args)
           ~~~~~~~~~~~~~~~~~~~^^^^^^^^^^^^^
  File "D:\Fanshawe\capstone\recover_smart\venv\Lib\site-packages\pymysql\cursors.py", line 153, in execute
    result = self._query(query)
  File "D:\Fanshawe\capstone\recover_smart\venv\Lib\site-packages\pymysql\cursors.py", line 322, in _query
    conn.query(q)
    ~~~~~~~~~~^^^
  File "D:\Fanshawe\capstone\recover_smart\venv\Lib\site-packages\pymysql\connections.py", line 563, in query
    self._affected_rows = self._read_query_result(unbuffered=unbuffered)
                          ~~~~~~~~~~~~~~~~~~~~~~~^^^^^^^^^^^^^^^^^^^^^^^
  File "D:\Fanshawe\capstone\recover_smart\venv\Lib\site-packages\pymysql\connections.py", line 825, in _read_query_result
    result.read()
    ~~~~~~~~~~~^^
  File "D:\Fanshawe\capstone\recover_smart\venv\Lib\site-packages\pymysql\connections.py", line 1199, in read
    first_packet = self.connection._read_packet()
  File "D:\Fanshawe\capstone\recover_smart\venv\Lib\site-packages\pymysql\connections.py", line 775, in _read_packet
    packet.raise_for_error()
    ~~~~~~~~~~~~~~~~~~~~~~^^
  File "D:\Fanshawe\capstone\recover_smart\venv\Lib\site-packages\pymysql\protocol.py", line 219, in raise_for_error
    err.raise_mysql_exception(self._data)
    ~~~~~~~~~~~~~~~~~~~~~~~~~^^^^^^^^^^^^
  File "D:\Fanshawe\capstone\recover_smart\venv\Lib\site-packages\pymysql\err.py", line 150, in raise_mysql_exception
    raise errorclass(errno, errval)
django.db.utils.IntegrityError: (1048, "Column 'created_by_id' cannot be null")
"POST /api/medical_record HTTP/1.1" 500 285699
D:\Fanshawe\capstone\recover_smart\medical_records\views.py changed, reloading.
Watching for file changes with StatReloader
D:\Fanshawe\capstone\recover_smart\medical_records\serializers.py changed, reloading.
Watching for file changes with StatReloader
D:\Fanshawe\capstone\recover_smart\medical_records\serializers.py changed, reloading.
Watching for file changes with StatReloader
D:\Fanshawe\capstone\recover_smart\medical_records\serializers.py changed, reloading.
Watching for file changes with StatReloader
D:\Fanshawe\capstone\recover_smart\medical_records\serializers.py changed, reloading.
Watching for file changes with StatReloader
Bad Request: /api/medical_record
"POST /api/medical_record HTTP/1.1" 400 42
D:\Fanshawe\capstone\recover_smart\medical_records\views.py changed, reloading.
Watching for file changes with StatReloader
D:\Fanshawe\capstone\recover_smart\medical_records\views.py changed, reloading.
Watching for file changes with StatReloader
Bad Request: /api/medical_record
"POST /api/medical_record HTTP/1.1" 400 42
D:\Fanshawe\capstone\recover_smart\medical_records\serializers.py changed, reloading.
Watching for file changes with StatReloader
Bad Request: /api/medical_record
"POST /api/medical_record HTTP/1.1" 400 42
D:\Fanshawe\capstone\recover_smart\medical_records\serializers.py changed, reloading.
Watching for file changes with StatReloader
D:\Fanshawe\capstone\recover_smart\medical_records\serializers.py changed, reloading.
Watching for file changes with StatReloader
D:\Fanshawe\capstone\recover_smart\medical_records\views.py changed, reloading.
Watching for file changes with StatReloader
Bad Request: /api/medical_record
"POST /api/medical_record HTTP/1.1" 400 42
"POST /api/medical_record HTTP/1.1" 201 227
"POST /api/medical_record HTTP/1.1" 201 227
"GET /api/medical_record/2 HTTP/1.1" 200 2
"GET /api/patients/ HTTP/1.1" 200 145
"GET /api/medical_record/6 HTTP/1.1" 200 2
"GET /api/medical_record/6 HTTP/1.1" 200 2
D:\Fanshawe\capstone\recover_smart\medical_records\views.py changed, reloading.
Watching for file changes with StatReloader
D:\Fanshawe\capstone\recover_smart\medical_records\views.py changed, reloading.
Watching for file changes with StatReloader
D:\Fanshawe\capstone\recover_smart\medical_records\views.py changed, reloading.
Watching for file changes with StatReloader
D:\Fanshawe\capstone\recover_smart\medical_records\views.py changed, reloading.
Watching for file changes with StatReloader
D:\Fanshawe\capstone\recover_smart\medical_records\views.py changed, reloading.
Watching for file changes with StatReloader
D:\Fanshawe\capstone\recover_smart\medical_records\views.py changed, reloading.
Watching for file changes with StatReloader
D:\Fanshawe\capstone\recover_smart\medical_records\views.py changed, reloading.
Watching for file changes with StatReloader
D:\Fanshawe\capstone\recover_smart\medical_records\views.py changed, reloading.
Watching for file changes with StatReloader
D:\Fanshawe\capstone\recover_smart\medical_records\views.py changed, reloading.
Watching for file changes with StatReloader
D:\Fanshawe\capstone\recover_smart\medical_records\views.py changed, reloading.
Watching for file changes with StatReloader
D:\Fanshawe\capstone\recover_smart\medical_records\views.py changed, reloading.
Watching for file changes with StatReloader
D:\Fanshawe\capstone\recover_smart\medical_records\views.py changed, reloading.
Watching for file changes with StatReloader
D:\Fanshawe\capstone\recover_smart\medical_records\views.py changed, reloading.
Watching for file changes with StatReloader
D:\Fanshawe\capstone\recover_smart\medical_records\views.py changed, reloading.
Watching for file changes with StatReloader
Internal Server Error: /api/medical_record/my_records
Traceback (most recent call last):
  File "D:\Fanshawe\capstone\recover_smart\venv\Lib\site-packages\django\core\handlers\exception.py", line 55, in inner
    response = get_response(request)
  File "D:\Fanshawe\capstone\recover_smart\venv\Lib\site-packages\django\core\handlers\base.py", line 197, in _get_response
    response = wrapped_callback(request, *callback_args, **callback_kwargs)
TypeError: MedicalRecordView.getMyRecords() missing 1 required positional argument: 'request'
"GET /api/medical_record/my_records HTTP/1.1" 500 77907
D:\Fanshawe\capstone\recover_smart\medical_records\views.py changed, reloading.
Watching for file changes with StatReloader
Internal Server Error: /api/medical_record/my_records
Traceback (most recent call last):
  File "D:\Fanshawe\capstone\recover_smart\venv\Lib\site-packages\django\core\handlers\exception.py", line 55, in inner
    response = get_response(request)
  File "D:\Fanshawe\capstone\recover_smart\venv\Lib\site-packages\django\core\handlers\base.py", line 197, in _get_response
    response = wrapped_callback(request, *callback_args, **callback_kwargs)
  File "D:\Fanshawe\capstone\recover_smart\medical_records\views.py", line 24, in getMyRecords
    patients = Patient.objects.filter(patient_id=request.user)
  File "D:\Fanshawe\capstone\recover_smart\venv\Lib\site-packages\django\db\models\manager.py", line 87, in manager_method
    return getattr(self.get_queryset(), name)(*args, **kwargs)
           ~~~~~~~~~~~~~~~~~~~~~~~~~~~~~~~~~~^^^^^^^^^^^^^^^^^
  File "D:\Fanshawe\capstone\recover_smart\venv\Lib\site-packages\django\db\models\query.py", line 1476, in filter
    return self._filter_or_exclude(False, args, kwargs)
           ~~~~~~~~~~~~~~~~~~~~~~~^^^^^^^^^^^^^^^^^^^^^
  File "D:\Fanshawe\capstone\recover_smart\venv\Lib\site-packages\django\db\models\query.py", line 1494, in _filter_or_exclude
    clone._filter_or_exclude_inplace(negate, args, kwargs)
    ~~~~~~~~~~~~~~~~~~~~~~~~~~~~~~~~^^^^^^^^^^^^^^^^^^^^^^
  File "D:\Fanshawe\capstone\recover_smart\venv\Lib\site-packages\django\db\models\query.py", line 1501, in _filter_or_exclude_inplace
    self._query.add_q(Q(*args, **kwargs))
    ~~~~~~~~~~~~~~~~~^^^^^^^^^^^^^^^^^^^^
  File "D:\Fanshawe\capstone\recover_smart\venv\Lib\site-packages\django\db\models\sql\query.py", line 1609, in add_q
    clause, _ = self._add_q(q_object, self.used_aliases)
                ~~~~~~~~~~~^^^^^^^^^^^^^^^^^^^^^^^^^^^^^
  File "D:\Fanshawe\capstone\recover_smart\venv\Lib\site-packages\django\db\models\sql\query.py", line 1641, in _add_q
    child_clause, needed_inner = self.build_filter(
                                 ~~~~~~~~~~~~~~~~~^
        child,
        ^^^^^^
    ...<7 lines>...
        update_join_types=update_join_types,
        ^^^^^^^^^^^^^^^^^^^^^^^^^^^^^^^^^^^^
    )
    ^
  File "D:\Fanshawe\capstone\recover_smart\venv\Lib\site-packages\django\db\models\sql\query.py", line 1491, in build_filter
    lookups, parts, reffed_expression = self.solve_lookup_type(arg, summarize)
                                        ~~~~~~~~~~~~~~~~~~~~~~^^^^^^^^^^^^^^^^
  File "D:\Fanshawe\capstone\recover_smart\venv\Lib\site-packages\django\db\models\sql\query.py", line 1303, in solve_lookup_type
    _, field, _, lookup_parts = self.names_to_path(lookup_splitted, self.get_meta())
                                ~~~~~~~~~~~~~~~~~~^^^^^^^^^^^^^^^^^^^^^^^^^^^^^^^^^^
  File "D:\Fanshawe\capstone\recover_smart\venv\Lib\site-packages\django\db\models\sql\query.py", line 1768, in names_to_path
    raise FieldError(
    ...<2 lines>...
    )
django.core.exceptions.FieldError: Cannot resolve keyword 'patient_id' into field. Choices are: email, first_name, id, last_name, medical_records, message, middle_name, mobile, user, user_id
"GET /api/medical_record/my_records HTTP/1.1" 500 127432
D:\Fanshawe\capstone\recover_smart\medical_records\views.py changed, reloading.
Watching for file changes with StatReloader
Internal Server Error: /api/medical_record/my_records
Traceback (most recent call last):
  File "D:\Fanshawe\capstone\recover_smart\venv\Lib\site-packages\django\db\models\fields\__init__.py", line 2123, in get_prep_value
    return int(value)
TypeError: int() argument must be a string, a bytes-like object or a real number, not 'SimpleLazyObject'

The above exception was the direct cause of the following exception:

Traceback (most recent call last):
  File "D:\Fanshawe\capstone\recover_smart\venv\Lib\site-packages\django\core\handlers\exception.py", line 55, in inner
    response = get_response(request)
  File "D:\Fanshawe\capstone\recover_smart\venv\Lib\site-packages\django\core\handlers\base.py", line 197, in _get_response
    response = wrapped_callback(request, *callback_args, **callback_kwargs)
  File "D:\Fanshawe\capstone\recover_smart\medical_records\views.py", line 24, in getMyRecords
    patients = Patient.objects.filter(id=request.user)
  File "D:\Fanshawe\capstone\recover_smart\venv\Lib\site-packages\django\db\models\manager.py", line 87, in manager_method
    return getattr(self.get_queryset(), name)(*args, **kwargs)
           ~~~~~~~~~~~~~~~~~~~~~~~~~~~~~~~~~~^^^^^^^^^^^^^^^^^
  File "D:\Fanshawe\capstone\recover_smart\venv\Lib\site-packages\django\db\models\query.py", line 1476, in filter
    return self._filter_or_exclude(False, args, kwargs)
           ~~~~~~~~~~~~~~~~~~~~~~~^^^^^^^^^^^^^^^^^^^^^
  File "D:\Fanshawe\capstone\recover_smart\venv\Lib\site-packages\django\db\models\query.py", line 1494, in _filter_or_exclude
    clone._filter_or_exclude_inplace(negate, args, kwargs)
    ~~~~~~~~~~~~~~~~~~~~~~~~~~~~~~~~^^^^^^^^^^^^^^^^^^^^^^
  File "D:\Fanshawe\capstone\recover_smart\venv\Lib\site-packages\django\db\models\query.py", line 1501, in _filter_or_exclude_inplace
    self._query.add_q(Q(*args, **kwargs))
    ~~~~~~~~~~~~~~~~~^^^^^^^^^^^^^^^^^^^^
  File "D:\Fanshawe\capstone\recover_smart\venv\Lib\site-packages\django\db\models\sql\query.py", line 1609, in add_q
    clause, _ = self._add_q(q_object, self.used_aliases)
                ~~~~~~~~~~~^^^^^^^^^^^^^^^^^^^^^^^^^^^^^
  File "D:\Fanshawe\capstone\recover_smart\venv\Lib\site-packages\django\db\models\sql\query.py", line 1641, in _add_q
    child_clause, needed_inner = self.build_filter(
                                 ~~~~~~~~~~~~~~~~~^
        child,
        ^^^^^^
    ...<7 lines>...
        update_join_types=update_join_types,
        ^^^^^^^^^^^^^^^^^^^^^^^^^^^^^^^^^^^^
    )
    ^
  File "D:\Fanshawe\capstone\recover_smart\venv\Lib\site-packages\django\db\models\sql\query.py", line 1555, in build_filter
    condition = self.build_lookup(lookups, col, value)
  File "D:\Fanshawe\capstone\recover_smart\venv\Lib\site-packages\django\db\models\sql\query.py", line 1385, in build_lookup
    lookup = lookup_class(lhs, rhs)
  File "D:\Fanshawe\capstone\recover_smart\venv\Lib\site-packages\django\db\models\lookups.py", line 30, in __init__
    self.rhs = self.get_prep_lookup()
               ~~~~~~~~~~~~~~~~~~~~^^
  File "D:\Fanshawe\capstone\recover_smart\venv\Lib\site-packages\django\db\models\lookups.py", line 369, in get_prep_lookup
    return super().get_prep_lookup()
           ~~~~~~~~~~~~~~~~~~~~~~~^^
  File "D:\Fanshawe\capstone\recover_smart\venv\Lib\site-packages\django\db\models\lookups.py", line 88, in get_prep_lookup
    return self.lhs.output_field.get_prep_value(self.rhs)
           ~~~~~~~~~~~~~~~~~~~~~~~~~~~~~~~~~~~~^^^^^^^^^^
  File "D:\Fanshawe\capstone\recover_smart\venv\Lib\site-packages\django\db\models\fields\__init__.py", line 2125, in get_prep_value
    raise e.__class__(
        "Field '%s' expected a number but got %r." % (self.name, value),
    ) from e
TypeError: Field 'id' expected a number but got <SimpleLazyObject: <django.contrib.auth.models.AnonymousUser object at 0x0000016BC1A8DA90>>.
"GET /api/medical_record/my_records HTTP/1.1" 500 145349
D:\Fanshawe\capstone\recover_smart\medical_records\views.py changed, reloading.
Watching for file changes with StatReloader
Internal Server Error: /api/medical_record/my_records
Traceback (most recent call last):
  File "D:\Fanshawe\capstone\recover_smart\venv\Lib\site-packages\django\db\models\fields\__init__.py", line 2123, in get_prep_value
    return int(value)
TypeError: int() argument must be a string, a bytes-like object or a real number, not 'SimpleLazyObject'

The above exception was the direct cause of the following exception:

Traceback (most recent call last):
  File "D:\Fanshawe\capstone\recover_smart\venv\Lib\site-packages\django\core\handlers\exception.py", line 55, in inner
    response = get_response(request)
  File "D:\Fanshawe\capstone\recover_smart\venv\Lib\site-packages\django\core\handlers\base.py", line 197, in _get_response
    response = wrapped_callback(request, *callback_args, **callback_kwargs)
  File "D:\Fanshawe\capstone\recover_smart\medical_records\views.py", line 24, in getMyRecords
    patients = Patient.objects.filter(pk=request.user)
  File "D:\Fanshawe\capstone\recover_smart\venv\Lib\site-packages\django\db\models\manager.py", line 87, in manager_method
    return getattr(self.get_queryset(), name)(*args, **kwargs)
           ~~~~~~~~~~~~~~~~~~~~~~~~~~~~~~~~~~^^^^^^^^^^^^^^^^^
  File "D:\Fanshawe\capstone\recover_smart\venv\Lib\site-packages\django\db\models\query.py", line 1476, in filter
    return self._filter_or_exclude(False, args, kwargs)
           ~~~~~~~~~~~~~~~~~~~~~~~^^^^^^^^^^^^^^^^^^^^^
  File "D:\Fanshawe\capstone\recover_smart\venv\Lib\site-packages\django\db\models\query.py", line 1494, in _filter_or_exclude
    clone._filter_or_exclude_inplace(negate, args, kwargs)
    ~~~~~~~~~~~~~~~~~~~~~~~~~~~~~~~~^^^^^^^^^^^^^^^^^^^^^^
  File "D:\Fanshawe\capstone\recover_smart\venv\Lib\site-packages\django\db\models\query.py", line 1501, in _filter_or_exclude_inplace
    self._query.add_q(Q(*args, **kwargs))
    ~~~~~~~~~~~~~~~~~^^^^^^^^^^^^^^^^^^^^
  File "D:\Fanshawe\capstone\recover_smart\venv\Lib\site-packages\django\db\models\sql\query.py", line 1609, in add_q
    clause, _ = self._add_q(q_object, self.used_aliases)
                ~~~~~~~~~~~^^^^^^^^^^^^^^^^^^^^^^^^^^^^^
  File "D:\Fanshawe\capstone\recover_smart\venv\Lib\site-packages\django\db\models\sql\query.py", line 1641, in _add_q
    child_clause, needed_inner = self.build_filter(
                                 ~~~~~~~~~~~~~~~~~^
        child,
        ^^^^^^
    ...<7 lines>...
        update_join_types=update_join_types,
        ^^^^^^^^^^^^^^^^^^^^^^^^^^^^^^^^^^^^
    )
    ^
  File "D:\Fanshawe\capstone\recover_smart\venv\Lib\site-packages\django\db\models\sql\query.py", line 1555, in build_filter
    condition = self.build_lookup(lookups, col, value)
  File "D:\Fanshawe\capstone\recover_smart\venv\Lib\site-packages\django\db\models\sql\query.py", line 1385, in build_lookup
    lookup = lookup_class(lhs, rhs)
  File "D:\Fanshawe\capstone\recover_smart\venv\Lib\site-packages\django\db\models\lookups.py", line 30, in __init__
    self.rhs = self.get_prep_lookup()
               ~~~~~~~~~~~~~~~~~~~~^^
  File "D:\Fanshawe\capstone\recover_smart\venv\Lib\site-packages\django\db\models\lookups.py", line 369, in get_prep_lookup
    return super().get_prep_lookup()
           ~~~~~~~~~~~~~~~~~~~~~~~^^
  File "D:\Fanshawe\capstone\recover_smart\venv\Lib\site-packages\django\db\models\lookups.py", line 88, in get_prep_lookup
    return self.lhs.output_field.get_prep_value(self.rhs)
           ~~~~~~~~~~~~~~~~~~~~~~~~~~~~~~~~~~~~^^^^^^^^^^
  File "D:\Fanshawe\capstone\recover_smart\venv\Lib\site-packages\django\db\models\fields\__init__.py", line 2125, in get_prep_value
    raise e.__class__(
        "Field '%s' expected a number but got %r." % (self.name, value),
    ) from e
TypeError: Field 'id' expected a number but got <SimpleLazyObject: <django.contrib.auth.models.AnonymousUser object at 0x000001D5D4D31A90>>.
"GET /api/medical_record/my_records HTTP/1.1" 500 145349
D:\Fanshawe\capstone\recover_smart\medical_records\views.py changed, reloading.
Watching for file changes with StatReloader
D:\Fanshawe\capstone\recover_smart\medical_records\views.py changed, reloading.
Watching for file changes with StatReloader
Internal Server Error: /api/medical_record/my_records
Traceback (most recent call last):
  File "D:\Fanshawe\capstone\recover_smart\venv\Lib\site-packages\django\db\models\fields\__init__.py", line 2123, in get_prep_value
    return int(value)
TypeError: int() argument must be a string, a bytes-like object or a real number, not 'SimpleLazyObject'

The above exception was the direct cause of the following exception:

Traceback (most recent call last):
  File "D:\Fanshawe\capstone\recover_smart\venv\Lib\site-packages\django\core\handlers\exception.py", line 55, in inner
    response = get_response(request)
  File "D:\Fanshawe\capstone\recover_smart\venv\Lib\site-packages\django\core\handlers\base.py", line 197, in _get_response
    response = wrapped_callback(request, *callback_args, **callback_kwargs)
  File "D:\Fanshawe\capstone\recover_smart\medical_records\views.py", line 24, in getMyRecords
    patients = Patient.objects.get(pk=request.user)
  File "D:\Fanshawe\capstone\recover_smart\venv\Lib\site-packages\django\db\models\manager.py", line 87, in manager_method
    return getattr(self.get_queryset(), name)(*args, **kwargs)
           ~~~~~~~~~~~~~~~~~~~~~~~~~~~~~~~~~~^^^^^^^^^^^^^^^^^
  File "D:\Fanshawe\capstone\recover_smart\venv\Lib\site-packages\django\db\models\query.py", line 635, in get
    clone = self._chain() if self.query.combinator else self.filter(*args, **kwargs)
                                                        ~~~~~~~~~~~^^^^^^^^^^^^^^^^^
  File "D:\Fanshawe\capstone\recover_smart\venv\Lib\site-packages\django\db\models\query.py", line 1476, in filter
    return self._filter_or_exclude(False, args, kwargs)
           ~~~~~~~~~~~~~~~~~~~~~~~^^^^^^^^^^^^^^^^^^^^^
  File "D:\Fanshawe\capstone\recover_smart\venv\Lib\site-packages\django\db\models\query.py", line 1494, in _filter_or_exclude
    clone._filter_or_exclude_inplace(negate, args, kwargs)
    ~~~~~~~~~~~~~~~~~~~~~~~~~~~~~~~~^^^^^^^^^^^^^^^^^^^^^^
  File "D:\Fanshawe\capstone\recover_smart\venv\Lib\site-packages\django\db\models\query.py", line 1501, in _filter_or_exclude_inplace
    self._query.add_q(Q(*args, **kwargs))
    ~~~~~~~~~~~~~~~~~^^^^^^^^^^^^^^^^^^^^
  File "D:\Fanshawe\capstone\recover_smart\venv\Lib\site-packages\django\db\models\sql\query.py", line 1609, in add_q
    clause, _ = self._add_q(q_object, self.used_aliases)
                ~~~~~~~~~~~^^^^^^^^^^^^^^^^^^^^^^^^^^^^^
  File "D:\Fanshawe\capstone\recover_smart\venv\Lib\site-packages\django\db\models\sql\query.py", line 1641, in _add_q
    child_clause, needed_inner = self.build_filter(
                                 ~~~~~~~~~~~~~~~~~^
        child,
        ^^^^^^
    ...<7 lines>...
        update_join_types=update_join_types,
        ^^^^^^^^^^^^^^^^^^^^^^^^^^^^^^^^^^^^
    )
    ^
  File "D:\Fanshawe\capstone\recover_smart\venv\Lib\site-packages\django\db\models\sql\query.py", line 1555, in build_filter
    condition = self.build_lookup(lookups, col, value)
  File "D:\Fanshawe\capstone\recover_smart\venv\Lib\site-packages\django\db\models\sql\query.py", line 1385, in build_lookup
    lookup = lookup_class(lhs, rhs)
  File "D:\Fanshawe\capstone\recover_smart\venv\Lib\site-packages\django\db\models\lookups.py", line 30, in __init__
    self.rhs = self.get_prep_lookup()
               ~~~~~~~~~~~~~~~~~~~~^^
  File "D:\Fanshawe\capstone\recover_smart\venv\Lib\site-packages\django\db\models\lookups.py", line 369, in get_prep_lookup
    return super().get_prep_lookup()
           ~~~~~~~~~~~~~~~~~~~~~~~^^
  File "D:\Fanshawe\capstone\recover_smart\venv\Lib\site-packages\django\db\models\lookups.py", line 88, in get_prep_lookup
    return self.lhs.output_field.get_prep_value(self.rhs)
           ~~~~~~~~~~~~~~~~~~~~~~~~~~~~~~~~~~~~^^^^^^^^^^
  File "D:\Fanshawe\capstone\recover_smart\venv\Lib\site-packages\django\db\models\fields\__init__.py", line 2125, in get_prep_value
    raise e.__class__(
        "Field '%s' expected a number but got %r." % (self.name, value),
    ) from e
TypeError: Field 'id' expected a number but got <SimpleLazyObject: <django.contrib.auth.models.AnonymousUser object at 0x000001C7CD9C9BE0>>.
"GET /api/medical_record/my_records HTTP/1.1" 500 149762
D:\Fanshawe\capstone\recover_smart\medical_records\views.py changed, reloading.
Watching for file changes with StatReloader
D:\Fanshawe\capstone\recover_smart\medical_records\views.py changed, reloading.
Watching for file changes with StatReloader
Internal Server Error: /api/medical_record/my_records
Traceback (most recent call last):
  File "D:\Fanshawe\capstone\recover_smart\venv\Lib\site-packages\django\db\models\fields\__init__.py", line 2123, in get_prep_value
    return int(value)
TypeError: int() argument must be a string, a bytes-like object or a real number, not 'SimpleLazyObject'

The above exception was the direct cause of the following exception:

Traceback (most recent call last):
  File "D:\Fanshawe\capstone\recover_smart\venv\Lib\site-packages\django\core\handlers\exception.py", line 55, in inner
    response = get_response(request)
  File "D:\Fanshawe\capstone\recover_smart\venv\Lib\site-packages\django\core\handlers\base.py", line 197, in _get_response
    response = wrapped_callback(request, *callback_args, **callback_kwargs)
  File "D:\Fanshawe\capstone\recover_smart\medical_records\views.py", line 25, in getMyRecords
    patients = Patient.objects.get(pk=request.user)
  File "D:\Fanshawe\capstone\recover_smart\venv\Lib\site-packages\django\db\models\manager.py", line 87, in manager_method
    return getattr(self.get_queryset(), name)(*args, **kwargs)
           ~~~~~~~~~~~~~~~~~~~~~~~~~~~~~~~~~~^^^^^^^^^^^^^^^^^
  File "D:\Fanshawe\capstone\recover_smart\venv\Lib\site-packages\django\db\models\query.py", line 635, in get
    clone = self._chain() if self.query.combinator else self.filter(*args, **kwargs)
                                                        ~~~~~~~~~~~^^^^^^^^^^^^^^^^^
  File "D:\Fanshawe\capstone\recover_smart\venv\Lib\site-packages\django\db\models\query.py", line 1476, in filter
    return self._filter_or_exclude(False, args, kwargs)
           ~~~~~~~~~~~~~~~~~~~~~~~^^^^^^^^^^^^^^^^^^^^^
  File "D:\Fanshawe\capstone\recover_smart\venv\Lib\site-packages\django\db\models\query.py", line 1494, in _filter_or_exclude
    clone._filter_or_exclude_inplace(negate, args, kwargs)
    ~~~~~~~~~~~~~~~~~~~~~~~~~~~~~~~~^^^^^^^^^^^^^^^^^^^^^^
  File "D:\Fanshawe\capstone\recover_smart\venv\Lib\site-packages\django\db\models\query.py", line 1501, in _filter_or_exclude_inplace
    self._query.add_q(Q(*args, **kwargs))
    ~~~~~~~~~~~~~~~~~^^^^^^^^^^^^^^^^^^^^
  File "D:\Fanshawe\capstone\recover_smart\venv\Lib\site-packages\django\db\models\sql\query.py", line 1609, in add_q
    clause, _ = self._add_q(q_object, self.used_aliases)
                ~~~~~~~~~~~^^^^^^^^^^^^^^^^^^^^^^^^^^^^^
  File "D:\Fanshawe\capstone\recover_smart\venv\Lib\site-packages\django\db\models\sql\query.py", line 1641, in _add_q
    child_clause, needed_inner = self.build_filter(
                                 ~~~~~~~~~~~~~~~~~^
        child,
        ^^^^^^
    ...<7 lines>...
        update_join_types=update_join_types,
        ^^^^^^^^^^^^^^^^^^^^^^^^^^^^^^^^^^^^
    )
    ^
  File "D:\Fanshawe\capstone\recover_smart\venv\Lib\site-packages\django\db\models\sql\query.py", line 1555, in build_filter
    condition = self.build_lookup(lookups, col, value)
  File "D:\Fanshawe\capstone\recover_smart\venv\Lib\site-packages\django\db\models\sql\query.py", line 1385, in build_lookup
    lookup = lookup_class(lhs, rhs)
  File "D:\Fanshawe\capstone\recover_smart\venv\Lib\site-packages\django\db\models\lookups.py", line 30, in __init__
    self.rhs = self.get_prep_lookup()
               ~~~~~~~~~~~~~~~~~~~~^^
  File "D:\Fanshawe\capstone\recover_smart\venv\Lib\site-packages\django\db\models\lookups.py", line 369, in get_prep_lookup
    return super().get_prep_lookup()
           ~~~~~~~~~~~~~~~~~~~~~~~^^
  File "D:\Fanshawe\capstone\recover_smart\venv\Lib\site-packages\django\db\models\lookups.py", line 88, in get_prep_lookup
    return self.lhs.output_field.get_prep_value(self.rhs)
           ~~~~~~~~~~~~~~~~~~~~~~~~~~~~~~~~~~~~^^^^^^^^^^
  File "D:\Fanshawe\capstone\recover_smart\venv\Lib\site-packages\django\db\models\fields\__init__.py", line 2125, in get_prep_value
    raise e.__class__(
        "Field '%s' expected a number but got %r." % (self.name, value),
    ) from e
TypeError: Field 'id' expected a number but got <SimpleLazyObject: <django.contrib.auth.models.AnonymousUser object at 0x0000020F4B551BE0>>.
"GET /api/medical_record/my_records HTTP/1.1" 500 149777
D:\Fanshawe\capstone\recover_smart\medical_records\views.py changed, reloading.
Watching for file changes with StatReloader
D:\Fanshawe\capstone\recover_smart\medical_records\views.py changed, reloading.
Watching for file changes with StatReloader
D:\Fanshawe\capstone\recover_smart\medical_records\views.py changed, reloading.
Watching for file changes with StatReloader
Internal Server Error: /api/medical_record/my_records
Traceback (most recent call last):
  File "D:\Fanshawe\capstone\recover_smart\venv\Lib\site-packages\django\db\models\fields\__init__.py", line 2123, in get_prep_value
    return int(value)
TypeError: int() argument must be a string, a bytes-like object or a real number, not 'SimpleLazyObject'

The above exception was the direct cause of the following exception:

Traceback (most recent call last):
  File "D:\Fanshawe\capstone\recover_smart\venv\Lib\site-packages\django\core\handlers\exception.py", line 55, in inner
    response = get_response(request)
  File "D:\Fanshawe\capstone\recover_smart\venv\Lib\site-packages\django\core\handlers\base.py", line 197, in _get_response
    response = wrapped_callback(request, *callback_args, **callback_kwargs)
  File "D:\Fanshawe\capstone\recover_smart\medical_records\views.py", line 25, in getMyRecords
    patients = Patient.objects.get(pk=request.user)
  File "D:\Fanshawe\capstone\recover_smart\venv\Lib\site-packages\django\db\models\manager.py", line 87, in manager_method
    return getattr(self.get_queryset(), name)(*args, **kwargs)
           ~~~~~~~~~~~~~~~~~~~~~~~~~~~~~~~~~~^^^^^^^^^^^^^^^^^
  File "D:\Fanshawe\capstone\recover_smart\venv\Lib\site-packages\django\db\models\query.py", line 635, in get
    clone = self._chain() if self.query.combinator else self.filter(*args, **kwargs)
                                                        ~~~~~~~~~~~^^^^^^^^^^^^^^^^^
  File "D:\Fanshawe\capstone\recover_smart\venv\Lib\site-packages\django\db\models\query.py", line 1476, in filter
    return self._filter_or_exclude(False, args, kwargs)
           ~~~~~~~~~~~~~~~~~~~~~~~^^^^^^^^^^^^^^^^^^^^^
  File "D:\Fanshawe\capstone\recover_smart\venv\Lib\site-packages\django\db\models\query.py", line 1494, in _filter_or_exclude
    clone._filter_or_exclude_inplace(negate, args, kwargs)
    ~~~~~~~~~~~~~~~~~~~~~~~~~~~~~~~~^^^^^^^^^^^^^^^^^^^^^^
  File "D:\Fanshawe\capstone\recover_smart\venv\Lib\site-packages\django\db\models\query.py", line 1501, in _filter_or_exclude_inplace
    self._query.add_q(Q(*args, **kwargs))
    ~~~~~~~~~~~~~~~~~^^^^^^^^^^^^^^^^^^^^
  File "D:\Fanshawe\capstone\recover_smart\venv\Lib\site-packages\django\db\models\sql\query.py", line 1609, in add_q
    clause, _ = self._add_q(q_object, self.used_aliases)
                ~~~~~~~~~~~^^^^^^^^^^^^^^^^^^^^^^^^^^^^^
  File "D:\Fanshawe\capstone\recover_smart\venv\Lib\site-packages\django\db\models\sql\query.py", line 1641, in _add_q
    child_clause, needed_inner = self.build_filter(
                                 ~~~~~~~~~~~~~~~~~^
        child,
        ^^^^^^
    ...<7 lines>...
        update_join_types=update_join_types,
        ^^^^^^^^^^^^^^^^^^^^^^^^^^^^^^^^^^^^
    )
    ^
  File "D:\Fanshawe\capstone\recover_smart\venv\Lib\site-packages\django\db\models\sql\query.py", line 1555, in build_filter
    condition = self.build_lookup(lookups, col, value)
  File "D:\Fanshawe\capstone\recover_smart\venv\Lib\site-packages\django\db\models\sql\query.py", line 1385, in build_lookup
    lookup = lookup_class(lhs, rhs)
  File "D:\Fanshawe\capstone\recover_smart\venv\Lib\site-packages\django\db\models\lookups.py", line 30, in __init__
    self.rhs = self.get_prep_lookup()
               ~~~~~~~~~~~~~~~~~~~~^^
  File "D:\Fanshawe\capstone\recover_smart\venv\Lib\site-packages\django\db\models\lookups.py", line 369, in get_prep_lookup
    return super().get_prep_lookup()
           ~~~~~~~~~~~~~~~~~~~~~~~^^
  File "D:\Fanshawe\capstone\recover_smart\venv\Lib\site-packages\django\db\models\lookups.py", line 88, in get_prep_lookup
    return self.lhs.output_field.get_prep_value(self.rhs)
           ~~~~~~~~~~~~~~~~~~~~~~~~~~~~~~~~~~~~^^^^^^^^^^
  File "D:\Fanshawe\capstone\recover_smart\venv\Lib\site-packages\django\db\models\fields\__init__.py", line 2125, in get_prep_value
    raise e.__class__(
        "Field '%s' expected a number but got %r." % (self.name, value),
    ) from e
TypeError: Field 'id' expected a number but got <SimpleLazyObject: <django.contrib.auth.models.AnonymousUser object at 0x0000029812F41BE0>>.
"GET /api/medical_record/my_records HTTP/1.1" 500 149747
D:\Fanshawe\capstone\recover_smart\medical_records\views.py changed, reloading.
Watching for file changes with StatReloader
Internal Server Error: /api/medical_record/my_records
Traceback (most recent call last):
  File "D:\Fanshawe\capstone\recover_smart\venv\Lib\site-packages\django\core\handlers\exception.py", line 55, in inner
    response = get_response(request)
  File "D:\Fanshawe\capstone\recover_smart\venv\Lib\site-packages\django\core\handlers\base.py", line 197, in _get_response
    response = wrapped_callback(request, *callback_args, **callback_kwargs)
  File "D:\Fanshawe\capstone\recover_smart\medical_records\views.py", line 25, in getMyRecords
    patients = Patient.objects.get(pk=request.user.id)
  File "D:\Fanshawe\capstone\recover_smart\venv\Lib\site-packages\django\db\models\manager.py", line 87, in manager_method
    return getattr(self.get_queryset(), name)(*args, **kwargs)
           ~~~~~~~~~~~~~~~~~~~~~~~~~~~~~~~~~~^^^^^^^^^^^^^^^^^
  File "D:\Fanshawe\capstone\recover_smart\venv\Lib\site-packages\django\db\models\query.py", line 649, in get
    raise self.model.DoesNotExist(
        "%s matching query does not exist." % self.model._meta.object_name
    )
patients.models.Patient.DoesNotExist: Patient matching query does not exist.
"GET /api/medical_record/my_records HTTP/1.1" 500 90471
D:\Fanshawe\capstone\recover_smart\medical_records\views.py changed, reloading.
Watching for file changes with StatReloader
D:\Fanshawe\capstone\recover_smart\medical_records\views.py changed, reloading.
Watching for file changes with StatReloader
Internal Server Error: /api/medical_record/my_records
Traceback (most recent call last):
  File "D:\Fanshawe\capstone\recover_smart\venv\Lib\site-packages\django\core\handlers\exception.py", line 55, in inner
    response = get_response(request)
  File "D:\Fanshawe\capstone\recover_smart\venv\Lib\site-packages\django\core\handlers\base.py", line 197, in _get_response
    response = wrapped_callback(request, *callback_args, **callback_kwargs)
  File "D:\Fanshawe\capstone\recover_smart\medical_records\views.py", line 25, in getMyRecords
    patients = Patient.objects.get(user_id=request.user.id)
  File "D:\Fanshawe\capstone\recover_smart\venv\Lib\site-packages\django\db\models\manager.py", line 87, in manager_method
    return getattr(self.get_queryset(), name)(*args, **kwargs)
           ~~~~~~~~~~~~~~~~~~~~~~~~~~~~~~~~~~^^^^^^^^^^^^^^^^^
  File "D:\Fanshawe\capstone\recover_smart\venv\Lib\site-packages\django\db\models\query.py", line 649, in get
    raise self.model.DoesNotExist(
        "%s matching query does not exist." % self.model._meta.object_name
    )
patients.models.Patient.DoesNotExist: Patient matching query does not exist.
"GET /api/medical_record/my_records HTTP/1.1" 500 90501
D:\Fanshawe\capstone\recover_smart\medical_records\views.py changed, reloading.
Watching for file changes with StatReloader
D:\Fanshawe\capstone\recover_smart\medical_records\views.py changed, reloading.
Watching for file changes with StatReloader
D:\Fanshawe\capstone\recover_smart\medical_records\views.py changed, reloading.
Watching for file changes with StatReloader
D:\Fanshawe\capstone\recover_smart\medical_records\views.py changed, reloading.
Watching for file changes with StatReloader
Internal Server Error: /api/medical_record/my_records
Traceback (most recent call last):
  File "D:\Fanshawe\capstone\recover_smart\venv\Lib\site-packages\django\core\handlers\exception.py", line 55, in inner
    response = get_response(request)
  File "D:\Fanshawe\capstone\recover_smart\venv\Lib\site-packages\django\core\handlers\base.py", line 197, in _get_response
    response = wrapped_callback(request, *callback_args, **callback_kwargs)
  File "D:\Fanshawe\capstone\recover_smart\medical_records\views.py", line 28, in getMyRecords
    patients = Patient.objects.get(user_id=request.user.id)
  File "D:\Fanshawe\capstone\recover_smart\venv\Lib\site-packages\django\db\models\manager.py", line 87, in manager_method
    return getattr(self.get_queryset(), name)(*args, **kwargs)
           ~~~~~~~~~~~~~~~~~~~~~~~~~~~~~~~~~~^^^^^^^^^^^^^^^^^
  File "D:\Fanshawe\capstone\recover_smart\venv\Lib\site-packages\django\db\models\query.py", line 649, in get
    raise self.model.DoesNotExist(
        "%s matching query does not exist." % self.model._meta.object_name
    )
patients.models.Patient.DoesNotExist: Patient matching query does not exist.
"GET /api/medical_record/my_records HTTP/1.1" 500 90526
D:\Fanshawe\capstone\recover_smart\medical_records\views.py changed, reloading.
Watching for file changes with StatReloader
Internal Server Error: /api/medical_record/my_records
Traceback (most recent call last):
  File "D:\Fanshawe\capstone\recover_smart\venv\Lib\site-packages\django\core\handlers\exception.py", line 55, in inner
    response = get_response(request)
  File "D:\Fanshawe\capstone\recover_smart\venv\Lib\site-packages\django\core\handlers\base.py", line 197, in _get_response
    response = wrapped_callback(request, *callback_args, **callback_kwargs)
  File "D:\Fanshawe\capstone\recover_smart\medical_records\views.py", line 28, in getMyRecords
    patients = Patient.objects.get(user_id=request.user.id)
  File "D:\Fanshawe\capstone\recover_smart\venv\Lib\site-packages\django\db\models\manager.py", line 87, in manager_method
    return getattr(self.get_queryset(), name)(*args, **kwargs)
           ~~~~~~~~~~~~~~~~~~~~~~~~~~~~~~~~~~^^^^^^^^^^^^^^^^^
  File "D:\Fanshawe\capstone\recover_smart\venv\Lib\site-packages\django\db\models\query.py", line 649, in get
    raise self.model.DoesNotExist(
        "%s matching query does not exist." % self.model._meta.object_name
    )
patients.models.Patient.DoesNotExist: Patient matching query does not exist.
"GET /api/medical_record/my_records HTTP/1.1" 500 90527
D:\Fanshawe\capstone\recover_smart\medical_records\views.py changed, reloading.
Watching for file changes with StatReloader
Internal Server Error: /api/medical_record/my_records
Traceback (most recent call last):
  File "D:\Fanshawe\capstone\recover_smart\venv\Lib\site-packages\django\core\handlers\exception.py", line 55, in inner
    response = get_response(request)
  File "D:\Fanshawe\capstone\recover_smart\venv\Lib\site-packages\django\core\handlers\base.py", line 197, in _get_response
    response = wrapped_callback(request, *callback_args, **callback_kwargs)
  File "D:\Fanshawe\capstone\recover_smart\medical_records\views.py", line 28, in getMyRecords
    patients = Patient.objects.get(user_id=request.user.id)
  File "D:\Fanshawe\capstone\recover_smart\venv\Lib\site-packages\django\db\models\manager.py", line 87, in manager_method
    return getattr(self.get_queryset(), name)(*args, **kwargs)
           ~~~~~~~~~~~~~~~~~~~~~~~~~~~~~~~~~~^^^^^^^^^^^^^^^^^
  File "D:\Fanshawe\capstone\recover_smart\venv\Lib\site-packages\django\db\models\query.py", line 649, in get
    raise self.model.DoesNotExist(
        "%s matching query does not exist." % self.model._meta.object_name
    )
patients.models.Patient.DoesNotExist: Patient matching query does not exist.
"GET /api/medical_record/my_records HTTP/1.1" 500 90524
D:\Fanshawe\capstone\recover_smart\medical_records\views.py changed, reloading.
Watching for file changes with StatReloader
D:\Fanshawe\capstone\recover_smart\medical_records\views.py changed, reloading.
Watching for file changes with StatReloader
"POST /api/auth/ HTTP/1.1" 200 486
Internal Server Error: /api/medical_record/my_records
Traceback (most recent call last):
  File "D:\Fanshawe\capstone\recover_smart\venv\Lib\site-packages\django\core\handlers\exception.py", line 55, in inner
    response = get_response(request)
  File "D:\Fanshawe\capstone\recover_smart\venv\Lib\site-packages\django\core\handlers\base.py", line 197, in _get_response
    response = wrapped_callback(request, *callback_args, **callback_kwargs)
  File "D:\Fanshawe\capstone\recover_smart\medical_records\views.py", line 26, in getMyRecords
    patients = Patient.objects.get(user_id=request.user.id)
  File "D:\Fanshawe\capstone\recover_smart\venv\Lib\site-packages\django\db\models\manager.py", line 87, in manager_method
    return getattr(self.get_queryset(), name)(*args, **kwargs)
           ~~~~~~~~~~~~~~~~~~~~~~~~~~~~~~~~~~^^^^^^^^^^^^^^^^^
  File "D:\Fanshawe\capstone\recover_smart\venv\Lib\site-packages\django\db\models\query.py", line 649, in get
    raise self.model.DoesNotExist(
        "%s matching query does not exist." % self.model._meta.object_name
    )
patients.models.Patient.DoesNotExist: Patient matching query does not exist.
"GET /api/medical_record/my_records HTTP/1.1" 500 90295
Internal Server Error: /api/medical_record/my_records
Traceback (most recent call last):
  File "D:\Fanshawe\capstone\recover_smart\venv\Lib\site-packages\django\core\handlers\exception.py", line 55, in inner
    response = get_response(request)
  File "D:\Fanshawe\capstone\recover_smart\venv\Lib\site-packages\django\core\handlers\base.py", line 197, in _get_response
    response = wrapped_callback(request, *callback_args, **callback_kwargs)
  File "D:\Fanshawe\capstone\recover_smart\medical_records\views.py", line 26, in getMyRecords
    patients = Patient.objects.get(user_id=request.user.id)
  File "D:\Fanshawe\capstone\recover_smart\venv\Lib\site-packages\django\db\models\manager.py", line 87, in manager_method
    return getattr(self.get_queryset(), name)(*args, **kwargs)
           ~~~~~~~~~~~~~~~~~~~~~~~~~~~~~~~~~~^^^^^^^^^^^^^^^^^
  File "D:\Fanshawe\capstone\recover_smart\venv\Lib\site-packages\django\db\models\query.py", line 649, in get
    raise self.model.DoesNotExist(
        "%s matching query does not exist." % self.model._meta.object_name
    )
patients.models.Patient.DoesNotExist: Patient matching query does not exist.
"GET /api/medical_record/my_records HTTP/1.1" 500 90295
D:\Fanshawe\capstone\recover_smart\medical_records\views.py changed, reloading.
Watching for file changes with StatReloader
Internal Server Error: /api/medical_record/my_records
Traceback (most recent call last):
  File "D:\Fanshawe\capstone\recover_smart\venv\Lib\site-packages\django\core\handlers\exception.py", line 55, in inner
    response = get_response(request)
  File "D:\Fanshawe\capstone\recover_smart\venv\Lib\site-packages\django\core\handlers\base.py", line 197, in _get_response
    response = wrapped_callback(request, *callback_args, **callback_kwargs)
  File "D:\Fanshawe\capstone\recover_smart\medical_records\views.py", line 26, in getMyRecords
    patients = Patient.objects.get(user=request.user.id)
  File "D:\Fanshawe\capstone\recover_smart\venv\Lib\site-packages\django\db\models\manager.py", line 87, in manager_method
    return getattr(self.get_queryset(), name)(*args, **kwargs)
           ~~~~~~~~~~~~~~~~~~~~~~~~~~~~~~~~~~^^^^^^^^^^^^^^^^^
  File "D:\Fanshawe\capstone\recover_smart\venv\Lib\site-packages\django\db\models\query.py", line 649, in get
    raise self.model.DoesNotExist(
        "%s matching query does not exist." % self.model._meta.object_name
    )
patients.models.Patient.DoesNotExist: Patient matching query does not exist.
"GET /api/medical_record/my_records HTTP/1.1" 500 90277
D:\Fanshawe\capstone\recover_smart\medical_records\views.py changed, reloading.
Watching for file changes with StatReloader
D:\Fanshawe\capstone\recover_smart\medical_records\views.py changed, reloading.
Watching for file changes with StatReloader
D:\Fanshawe\capstone\recover_smart\medical_records\views.py changed, reloading.
Watching for file changes with StatReloader
D:\Fanshawe\capstone\recover_smart\medical_records\views.py changed, reloading.
Watching for file changes with StatReloader
D:\Fanshawe\capstone\recover_smart\medical_records\views.py changed, reloading.
Watching for file changes with StatReloader
Internal Server Error: /api/medical_record/my_records
Traceback (most recent call last):
  File "D:\Fanshawe\capstone\recover_smart\venv\Lib\site-packages\django\core\handlers\exception.py", line 55, in inner
    response = get_response(request)
  File "D:\Fanshawe\capstone\recover_smart\venv\Lib\site-packages\django\core\handlers\base.py", line 197, in _get_response
    response = wrapped_callback(request, *callback_args, **callback_kwargs)
  File "D:\Fanshawe\capstone\recover_smart\medical_records\views.py", line 28, in getMyRecords
    medicalRecord = MedicalRecord.objects.filter(patient_id=patientSerializer.data.id)
                                                            ^^^^^^^^^^^^^^^^^^^^^^^^^
AttributeError: 'ReturnDict' object has no attribute 'id'
"GET /api/medical_record/my_records HTTP/1.1" 500 83555
D:\Fanshawe\capstone\recover_smart\medical_records\views.py changed, reloading.
Watching for file changes with StatReloader
Watching for file changes with StatReloader
Internal Server Error: /api/medical_record/my_records
Traceback (most recent call last):
  File "D:\Fanshawe\capstone\recover_smart\venv\Lib\site-packages\django\core\handlers\exception.py", line 55, in inner
    response = get_response(request)
  File "D:\Fanshawe\capstone\recover_smart\venv\Lib\site-packages\django\core\handlers\base.py", line 197, in _get_response
    response = wrapped_callback(request, *callback_args, **callback_kwargs)
  File "D:\Fanshawe\capstone\recover_smart\medical_records\views.py", line 26, in getMyRecords
    patients = Patient.objects.get(user_id=request.user.id)
  File "D:\Fanshawe\capstone\recover_smart\venv\Lib\site-packages\django\db\models\manager.py", line 87, in manager_method
    return getattr(self.get_queryset(), name)(*args, **kwargs)
           ~~~~~~~~~~~~~~~~~~~~~~~~~~~~~~~~~~^^^^^^^^^^^^^^^^^
  File "D:\Fanshawe\capstone\recover_smart\venv\Lib\site-packages\django\db\models\query.py", line 649, in get
    raise self.model.DoesNotExist(
        "%s matching query does not exist." % self.model._meta.object_name
    )
patients.models.Patient.DoesNotExist: Patient matching query does not exist.
"GET /api/medical_record/my_records HTTP/1.1" 500 90295
Internal Server Error: /api/medical_record/my_records
Traceback (most recent call last):
  File "D:\Fanshawe\capstone\recover_smart\venv\Lib\site-packages\django\core\handlers\exception.py", line 55, in inner
    response = get_response(request)
  File "D:\Fanshawe\capstone\recover_smart\venv\Lib\site-packages\django\core\handlers\base.py", line 197, in _get_response
    response = wrapped_callback(request, *callback_args, **callback_kwargs)
  File "D:\Fanshawe\capstone\recover_smart\medical_records\views.py", line 26, in getMyRecords
    patients = Patient.objects.get(user_id=request.user.id)
  File "D:\Fanshawe\capstone\recover_smart\venv\Lib\site-packages\django\db\models\manager.py", line 87, in manager_method
    return getattr(self.get_queryset(), name)(*args, **kwargs)
           ~~~~~~~~~~~~~~~~~~~~~~~~~~~~~~~~~~^^^^^^^^^^^^^^^^^
  File "D:\Fanshawe\capstone\recover_smart\venv\Lib\site-packages\django\db\models\query.py", line 649, in get
    raise self.model.DoesNotExist(
        "%s matching query does not exist." % self.model._meta.object_name
    )
patients.models.Patient.DoesNotExist: Patient matching query does not exist.
"GET /api/medical_record/my_records HTTP/1.1" 500 90295
"GET / HTTP/1.1" 200 13
D:\Fanshawe\capstone\recover_smart\medical_records\views.py changed, reloading.
Watching for file changes with StatReloader
D:\Fanshawe\capstone\recover_smart\medical_records\views.py changed, reloading.
Watching for file changes with StatReloader
"GET /api/medical_record/my_records HTTP/1.1" 200 457
D:\Fanshawe\capstone\recover_smart\medical_records\views.py changed, reloading.
Watching for file changes with StatReloader
D:\Fanshawe\capstone\recover_smart\medical_records\views.py changed, reloading.
Watching for file changes with StatReloader
D:\Fanshawe\capstone\recover_smart\medical_records\views.py changed, reloading.
Watching for file changes with StatReloader
"GET /api/medical_record/my_records HTTP/1.1" 200 457
"POST /api/auth/ HTTP/1.1" 200 483
Internal Server Error: /api/medical_record/my_records
Traceback (most recent call last):
  File "D:\Fanshawe\capstone\recover_smart\medical_records\views.py", line 29, in getMyRecords
    patient = Patient.objects.get(user_id=request.user.id)  # Find the patient for the current user
  File "D:\Fanshawe\capstone\recover_smart\venv\Lib\site-packages\django\db\models\manager.py", line 87, in manager_method
    return getattr(self.get_queryset(), name)(*args, **kwargs)
           ~~~~~~~~~~~~~~~~~~~~~~~~~~~~~~~~~~^^^^^^^^^^^^^^^^^
  File "D:\Fanshawe\capstone\recover_smart\venv\Lib\site-packages\django\db\models\query.py", line 649, in get
    raise self.model.DoesNotExist(
        "%s matching query does not exist." % self.model._meta.object_name
    )
patients.models.Patient.DoesNotExist: Patient matching query does not exist.

During handling of the above exception, another exception occurred:

Traceback (most recent call last):
  File "D:\Fanshawe\capstone\recover_smart\venv\Lib\site-packages\django\core\handlers\exception.py", line 55, in inner
    response = get_response(request)
  File "D:\Fanshawe\capstone\recover_smart\venv\Lib\site-packages\django\core\handlers\base.py", line 197, in _get_response
    response = wrapped_callback(request, *callback_args, **callback_kwargs)
  File "D:\Fanshawe\capstone\recover_smart\venv\Lib\site-packages\django\views\decorators\csrf.py", line 65, in _view_wrapper
    return view_func(request, *args, **kwargs)
  File "D:\Fanshawe\capstone\recover_smart\venv\Lib\site-packages\django\views\generic\base.py", line 104, in view
    return self.dispatch(request, *args, **kwargs)
           ~~~~~~~~~~~~~^^^^^^^^^^^^^^^^^^^^^^^^^^
  File "D:\Fanshawe\capstone\recover_smart\venv\Lib\site-packages\rest_framework\views.py", line 509, in dispatch
    response = self.handle_exception(exc)
  File "D:\Fanshawe\capstone\recover_smart\venv\Lib\site-packages\rest_framework\views.py", line 469, in handle_exception
    self.raise_uncaught_exception(exc)
    ~~~~~~~~~~~~~~~~~~~~~~~~~~~~~^^^^^
  File "D:\Fanshawe\capstone\recover_smart\venv\Lib\site-packages\rest_framework\views.py", line 480, in raise_uncaught_exception
    raise exc
  File "D:\Fanshawe\capstone\recover_smart\venv\Lib\site-packages\rest_framework\views.py", line 506, in dispatch
    response = handler(request, *args, **kwargs)
  File "D:\Fanshawe\capstone\recover_smart\venv\Lib\site-packages\rest_framework\decorators.py", line 50, in handler
    return func(*args, **kwargs)
  File "D:\Fanshawe\capstone\recover_smart\medical_records\views.py", line 31, in getMyRecords
    return Response({"error": "Patient matching query does not exist."}, status=HTTP_404_NOT_FOUND)
                                                                                ^^^^^^^^^^^^^^^^^^
NameError: name 'HTTP_404_NOT_FOUND' is not defined
"GET /api/medical_record/my_records HTTP/1.1" 500 126519
"POST /api/auth/ HTTP/1.1" 200 486
"GET /api/medical_record/my_records HTTP/1.1" 200 457
D:\Fanshawe\capstone\recover_smart\medical_records\views.py changed, reloading.
Watching for file changes with StatReloader
Internal Server Error: /api/checklists/item/
Traceback (most recent call last):
  File "D:\Fanshawe\capstone\recover_smart\venv\Lib\site-packages\django\core\handlers\exception.py", line 55, in inner
    response = get_response(request)
  File "D:\Fanshawe\capstone\recover_smart\venv\Lib\site-packages\django\core\handlers\base.py", line 197, in _get_response
    response = wrapped_callback(request, *callback_args, **callback_kwargs)
  File "D:\Fanshawe\capstone\recover_smart\venv\Lib\site-packages\django\views\decorators\csrf.py", line 65, in _view_wrapper
    return view_func(request, *args, **kwargs)
  File "D:\Fanshawe\capstone\recover_smart\venv\Lib\site-packages\django\views\generic\base.py", line 104, in view
    return self.dispatch(request, *args, **kwargs)
           ~~~~~~~~~~~~~^^^^^^^^^^^^^^^^^^^^^^^^^^
  File "D:\Fanshawe\capstone\recover_smart\venv\Lib\site-packages\rest_framework\views.py", line 509, in dispatch
    response = self.handle_exception(exc)
  File "D:\Fanshawe\capstone\recover_smart\venv\Lib\site-packages\rest_framework\views.py", line 469, in handle_exception
    self.raise_uncaught_exception(exc)
    ~~~~~~~~~~~~~~~~~~~~~~~~~~~~~^^^^^
  File "D:\Fanshawe\capstone\recover_smart\venv\Lib\site-packages\rest_framework\views.py", line 480, in raise_uncaught_exception
    raise exc
  File "D:\Fanshawe\capstone\recover_smart\venv\Lib\site-packages\rest_framework\views.py", line 506, in dispatch
    response = handler(request, *args, **kwargs)
TypeError: ChecklistsItem.get() missing 1 required positional argument: 'pk'
"GET /api/checklists/item/ HTTP/1.1" 500 104908
"GET / HTTP/1.1" 200 13
"POST /api/auth/ HTTP/1.1" 200 486
Forbidden: /api/medical_record/6
"GET /api/medical_record/6 HTTP/1.1" 403 66
"GET /api/medical_record/my_records HTTP/1.1" 200 457
Unauthorized: /api/auth/user/patient
"GET /api/auth/user/patient HTTP/1.1" 401 58
Internal Server Error: /api/checklists/item/
Traceback (most recent call last):
  File "D:\Fanshawe\capstone\recover_smart\venv\Lib\site-packages\django\core\handlers\exception.py", line 55, in inner
    response = get_response(request)
  File "D:\Fanshawe\capstone\recover_smart\venv\Lib\site-packages\django\core\handlers\base.py", line 197, in _get_response
    response = wrapped_callback(request, *callback_args, **callback_kwargs)
  File "D:\Fanshawe\capstone\recover_smart\venv\Lib\site-packages\django\views\decorators\csrf.py", line 65, in _view_wrapper
    return view_func(request, *args, **kwargs)
  File "D:\Fanshawe\capstone\recover_smart\venv\Lib\site-packages\django\views\generic\base.py", line 104, in view
    return self.dispatch(request, *args, **kwargs)
           ~~~~~~~~~~~~~^^^^^^^^^^^^^^^^^^^^^^^^^^
  File "D:\Fanshawe\capstone\recover_smart\venv\Lib\site-packages\rest_framework\views.py", line 509, in dispatch
    response = self.handle_exception(exc)
  File "D:\Fanshawe\capstone\recover_smart\venv\Lib\site-packages\rest_framework\views.py", line 469, in handle_exception
    self.raise_uncaught_exception(exc)
    ~~~~~~~~~~~~~~~~~~~~~~~~~~~~~^^^^^
  File "D:\Fanshawe\capstone\recover_smart\venv\Lib\site-packages\rest_framework\views.py", line 480, in raise_uncaught_exception
    raise exc
  File "D:\Fanshawe\capstone\recover_smart\venv\Lib\site-packages\rest_framework\views.py", line 506, in dispatch
    response = handler(request, *args, **kwargs)
TypeError: ChecklistsItem.get() missing 1 required positional argument: 'pk'
"GET /api/checklists/item/ HTTP/1.1" 500 104908
"GET /api/checklists/item/6 HTTP/1.1" 200 2
Bad Request: /api/checklists/item/
"POST /api/checklists/item/ HTTP/1.1" 400 235
Bad Request: /api/checklists/item/
"POST /api/checklists/item/ HTTP/1.1" 400 173
Bad Request: /api/checklists/item/
"POST /api/checklists/item/ HTTP/1.1" 400 66
Bad Request: /api/checklists/
"POST /api/checklists/ HTTP/1.1" 400 115
"POST /api/checklists/ HTTP/1.1" 201 93
"POST /api/checklists/item/ HTTP/1.1" 201 220
Bad Request: /api/checklists/item/
"POST /api/checklists/item/ HTTP/1.1" 400 59
"POST /api/checklists/item/ HTTP/1.1" 201 243
Bad Request: /api/checklists/item/
"POST /api/checklists/item/ HTTP/1.1" 400 59
"POST /api/checklists/item/ HTTP/1.1" 201 213
"POST /api/checklists/item/ HTTP/1.1" 201 232
"POST /api/checklists/item/ HTTP/1.1" 201 233
"GET /api/checklists/ HTTP/1.1" 200 1240
Internal Server Error: /api/checklists/1
Traceback (most recent call last):
  File "D:\Fanshawe\capstone\recover_smart\venv\Lib\site-packages\django\core\handlers\exception.py", line 55, in inner
    response = get_response(request)
  File "D:\Fanshawe\capstone\recover_smart\venv\Lib\site-packages\django\core\handlers\base.py", line 197, in _get_response
    response = wrapped_callback(request, *callback_args, **callback_kwargs)
  File "D:\Fanshawe\capstone\recover_smart\venv\Lib\site-packages\django\views\decorators\csrf.py", line 65, in _view_wrapper
    return view_func(request, *args, **kwargs)
  File "D:\Fanshawe\capstone\recover_smart\venv\Lib\site-packages\django\views\generic\base.py", line 104, in view
    return self.dispatch(request, *args, **kwargs)
           ~~~~~~~~~~~~~^^^^^^^^^^^^^^^^^^^^^^^^^^
  File "D:\Fanshawe\capstone\recover_smart\venv\Lib\site-packages\rest_framework\views.py", line 509, in dispatch
    response = self.handle_exception(exc)
  File "D:\Fanshawe\capstone\recover_smart\venv\Lib\site-packages\rest_framework\views.py", line 469, in handle_exception
    self.raise_uncaught_exception(exc)
    ~~~~~~~~~~~~~~~~~~~~~~~~~~~~~^^^^^
  File "D:\Fanshawe\capstone\recover_smart\venv\Lib\site-packages\rest_framework\views.py", line 480, in raise_uncaught_exception
    raise exc
  File "D:\Fanshawe\capstone\recover_smart\venv\Lib\site-packages\rest_framework\views.py", line 506, in dispatch
    response = handler(request, *args, **kwargs)
TypeError: Checklists.get() got an unexpected keyword argument 'pk'
"GET /api/checklists/1 HTTP/1.1" 500 104798
D:\Fanshawe\capstone\recover_smart\checklists\views.py changed, reloading.
Watching for file changes with StatReloader
D:\Fanshawe\capstone\recover_smart\checklists\views.py changed, reloading.
Watching for file changes with StatReloader
D:\Fanshawe\capstone\recover_smart\checklists\views.py changed, reloading.
Watching for file changes with StatReloader
D:\Fanshawe\capstone\recover_smart\checklists\views.py changed, reloading.
Watching for file changes with StatReloader
D:\Fanshawe\capstone\recover_smart\checklists\views.py changed, reloading.
Watching for file changes with StatReloader
D:\Fanshawe\capstone\recover_smart\checklists\urls.py changed, reloading.
Watching for file changes with StatReloader
D:\Fanshawe\capstone\recover_smart\checklists\urls.py changed, reloading.
Watching for file changes with StatReloader
D:\Fanshawe\capstone\recover_smart\checklists\urls.py changed, reloading.
Watching for file changes with StatReloader
Watching for file changes with StatReloader
"POST /api/auth/ HTTP/1.1" 200 486
D:\Fanshawe\capstone\recover_smart\recoversmart\settings.py changed, reloading.
Watching for file changes with StatReloader
D:\Fanshawe\capstone\recover_smart\recoversmart\settings.py changed, reloading.
Watching for file changes with StatReloader
"POST /api/auth/ HTTP/1.1" 200 486
Watching for file changes with StatReloader
"POST /api/auth/ HTTP/1.1" 200 486
D:\Fanshawe\capstone\recover_smart\recoversmart\settings.py changed, reloading.
Watching for file changes with StatReloader
D:\Fanshawe\capstone\recover_smart\recoversmart\settings.py changed, reloading.
Watching for file changes with StatReloader
D:\Fanshawe\capstone\recover_smart\recoversmart\settings.py changed, reloading.
Watching for file changes with StatReloader
D:\Fanshawe\capstone\recover_smart\recoversmart\settings.py changed, reloading.
Watching for file changes with StatReloader
"POST /api/auth/ HTTP/1.1" 200 486
Watching for file changes with StatReloader
"POST /api/auth/ HTTP/1.1" 200 486
D:\Fanshawe\capstone\recover_smart\recoversmart\settings.py changed, reloading.
Watching for file changes with StatReloader
D:\Fanshawe\capstone\recover_smart\recoversmart\settings.py changed, reloading.
Watching for file changes with StatReloader
D:\Fanshawe\capstone\recover_smart\recoversmart\settings.py changed, reloading.
Watching for file changes with StatReloader
"POST /api/auth/ HTTP/1.1" 200 486
"GET /api/medical_record/my_records HTTP/1.1" 200 457
D:\Fanshawe\capstone\recover_smart\medical_records\views.py changed, reloading.
Watching for file changes with StatReloader
D:\Fanshawe\capstone\recover_smart\medical_records\views.py changed, reloading.
Watching for file changes with StatReloader
D:\Fanshawe\capstone\recover_smart\medical_records\views.py changed, reloading.
Watching for file changes with StatReloader
"GET /api/medical_record/my_records HTTP/1.1" 200 457
D:\Fanshawe\capstone\recover_smart\medical_records\views.py changed, reloading.
Watching for file changes with StatReloader
D:\Fanshawe\capstone\recover_smart\medical_records\serializers.py changed, reloading.
Watching for file changes with StatReloader
D:\Fanshawe\capstone\recover_smart\medical_records\serializers.py changed, reloading.
Watching for file changes with StatReloader
D:\Fanshawe\capstone\recover_smart\medical_records\serializers.py changed, reloading.
Watching for file changes with StatReloader
D:\Fanshawe\capstone\recover_smart\medical_records\serializers.py changed, reloading.
Watching for file changes with StatReloader
D:\Fanshawe\capstone\recover_smart\medical_records\serializers.py changed, reloading.
Watching for file changes with StatReloader
D:\Fanshawe\capstone\recover_smart\medical_records\serializers.py changed, reloading.
Watching for file changes with StatReloader
D:\Fanshawe\capstone\recover_smart\medical_records\serializers.py changed, reloading.
Watching for file changes with StatReloader
D:\Fanshawe\capstone\recover_smart\medical_records\serializers.py changed, reloading.
Watching for file changes with StatReloader
D:\Fanshawe\capstone\recover_smart\medical_records\serializers.py changed, reloading.
Watching for file changes with StatReloader
"GET /api/medical_record/my_records HTTP/1.1" 200 1727
D:\Fanshawe\capstone\recover_smart\recoversmart\settings.py changed, reloading.
Watching for file changes with StatReloader
D:\Fanshawe\capstone\recover_smart\checklist_items\views.py changed, reloading.
Watching for file changes with StatReloader
D:\Fanshawe\capstone\recover_smart\checklist_items\views.py changed, reloading.
Watching for file changes with StatReloader
D:\Fanshawe\capstone\recover_smart\checklist_items\views.py changed, reloading.
Watching for file changes with StatReloader
D:\Fanshawe\capstone\recover_smart\checklist_items\views.py changed, reloading.
Watching for file changes with StatReloader
D:\Fanshawe\capstone\recover_smart\checklist_items\views.py changed, reloading.
Watching for file changes with StatReloader
D:\Fanshawe\capstone\recover_smart\checklist_items\views.py changed, reloading.
Watching for file changes with StatReloader
D:\Fanshawe\capstone\recover_smart\checklist_items\views.py changed, reloading.
Watching for file changes with StatReloader
D:\Fanshawe\capstone\recover_smart\checklist_items\views.py changed, reloading.
Watching for file changes with StatReloader
D:\Fanshawe\capstone\recover_smart\attachments\services.py changed, reloading.
Watching for file changes with StatReloader
D:\Fanshawe\capstone\recover_smart\attachments\services.py changed, reloading.
Watching for file changes with StatReloader
D:\Fanshawe\capstone\recover_smart\recoversmart\settings.py changed, reloading.
Watching for file changes with StatReloader
D:\Fanshawe\capstone\recover_smart\attachments\models.py changed, reloading.
Watching for file changes with StatReloader
D:\Fanshawe\capstone\recover_smart\attachments\models.py changed, reloading.
Watching for file changes with StatReloader
D:\Fanshawe\capstone\recover_smart\attachments\models.py changed, reloading.
Watching for file changes with StatReloader
Watching for file changes with StatReloader
Unauthorized: /api/checklists/item/
"POST /api/checklists/item/ HTTP/1.1" 401 183
"POST /api/auth/ HTTP/1.1" 200 486
Unsupported Media Type: /api/checklists/item/
"POST /api/checklists/item/ HTTP/1.1" 415 132
D:\Fanshawe\capstone\recover_smart\checklist_items\views.py changed, reloading.
Watching for file changes with StatReloader
Unsupported Media Type: /api/checklists/item/
"POST /api/checklists/item/ HTTP/1.1" 415 132
D:\Fanshawe\capstone\recover_smart\checklist_items\views.py changed, reloading.
Watching for file changes with StatReloader
Unsupported Media Type: /api/checklists/item/
"POST /api/checklists/item/ HTTP/1.1" 415 132
D:\Fanshawe\capstone\recover_smart\checklist_items\views.py changed, reloading.
Watching for file changes with StatReloader
D:\Fanshawe\capstone\recover_smart\checklist_items\views.py changed, reloading.
Watching for file changes with StatReloader
D:\Fanshawe\capstone\recover_smart\checklist_items\views.py changed, reloading.
Watching for file changes with StatReloader
D:\Fanshawe\capstone\recover_smart\checklist_items\views.py changed, reloading.
Watching for file changes with StatReloader
Unsupported Media Type: /api/checklists/item/
"POST /api/checklists/item/ HTTP/1.1" 415 132
Unsupported Media Type: /api/checklists/item/
Unsupported Media Type: /api/checklists/item/
"POST /api/checklists/item/ HTTP/1.1" 415 132
D:\Fanshawe\capstone\recover_smart\checklist_items\views.py changed, reloading.
Watching for file changes with StatReloader
D:\Fanshawe\capstone\recover_smart\checklist_items\views.py changed, reloading.
Watching for file changes with StatReloader
"POST /api/checklists/item/ HTTP/1.1" 201 233
Internal Server Error: /api/checklists/item/
Traceback (most recent call last):
  File "D:\Fanshawe\capstone\recover_smart\venv\Lib\site-packages\django\core\handlers\exception.py", line 55, in inner
    response = get_response(request)
  File "D:\Fanshawe\capstone\recover_smart\venv\Lib\site-packages\django\core\handlers\base.py", line 197, in _get_response
    response = wrapped_callback(request, *callback_args, **callback_kwargs)
  File "D:\Fanshawe\capstone\recover_smart\venv\Lib\site-packages\django\views\decorators\csrf.py", line 65, in _view_wrapper
    return view_func(request, *args, **kwargs)
  File "D:\Fanshawe\capstone\recover_smart\venv\Lib\site-packages\django\views\generic\base.py", line 104, in view
    return self.dispatch(request, *args, **kwargs)
           ~~~~~~~~~~~~~^^^^^^^^^^^^^^^^^^^^^^^^^^
  File "D:\Fanshawe\capstone\recover_smart\venv\Lib\site-packages\rest_framework\views.py", line 509, in dispatch
    response = self.handle_exception(exc)
  File "D:\Fanshawe\capstone\recover_smart\venv\Lib\site-packages\rest_framework\views.py", line 469, in handle_exception
    self.raise_uncaught_exception(exc)
    ~~~~~~~~~~~~~~~~~~~~~~~~~~~~~^^^^^
  File "D:\Fanshawe\capstone\recover_smart\venv\Lib\site-packages\rest_framework\views.py", line 480, in raise_uncaught_exception
    raise exc
  File "D:\Fanshawe\capstone\recover_smart\venv\Lib\site-packages\rest_framework\views.py", line 506, in dispatch
    response = handler(request, *args, **kwargs)
  File "D:\Fanshawe\capstone\recover_smart\checklist_items\views.py", line 34, in post
    uploadFile(file, serializer.data['id'], "checklist_items")
    ~~~~~~~~~~^^^^^^^^^^^^^^^^^^^^^^^^^^^^^^^^^^^^^^^^^^^^^^^^
TypeError: uploadFile() missing 1 required positional argument: 'entity'
"POST /api/checklists/item/ HTTP/1.1" 500 112272
D:\Fanshawe\capstone\recover_smart\checklist_items\views.py changed, reloading.
Watching for file changes with StatReloader
Internal Server Error: /api/checklists/item/
Traceback (most recent call last):
  File "D:\Fanshawe\capstone\recover_smart\venv\Lib\site-packages\django\core\handlers\exception.py", line 55, in inner
    response = get_response(request)
  File "D:\Fanshawe\capstone\recover_smart\venv\Lib\site-packages\django\core\handlers\base.py", line 197, in _get_response
    response = wrapped_callback(request, *callback_args, **callback_kwargs)
  File "D:\Fanshawe\capstone\recover_smart\venv\Lib\site-packages\django\views\decorators\csrf.py", line 65, in _view_wrapper
    return view_func(request, *args, **kwargs)
  File "D:\Fanshawe\capstone\recover_smart\venv\Lib\site-packages\django\views\generic\base.py", line 104, in view
    return self.dispatch(request, *args, **kwargs)
           ~~~~~~~~~~~~~^^^^^^^^^^^^^^^^^^^^^^^^^^
  File "D:\Fanshawe\capstone\recover_smart\venv\Lib\site-packages\rest_framework\views.py", line 509, in dispatch
    response = self.handle_exception(exc)
  File "D:\Fanshawe\capstone\recover_smart\venv\Lib\site-packages\rest_framework\views.py", line 469, in handle_exception
    self.raise_uncaught_exception(exc)
    ~~~~~~~~~~~~~~~~~~~~~~~~~~~~~^^^^^
  File "D:\Fanshawe\capstone\recover_smart\venv\Lib\site-packages\rest_framework\views.py", line 480, in raise_uncaught_exception
    raise exc
  File "D:\Fanshawe\capstone\recover_smart\venv\Lib\site-packages\rest_framework\views.py", line 506, in dispatch
    response = handler(request, *args, **kwargs)
  File "D:\Fanshawe\capstone\recover_smart\checklist_items\views.py", line 34, in post
    uploadFile(file, serializer.data['id'], "checklist_items")
    ~~~~~~~~~~^^^^^^^^^^^^^^^^^^^^^^^^^^^^^^^^^^^^^^^^^^^^^^^^
TypeError: uploadFile() missing 1 required positional argument: 'entity'
"POST /api/checklists/item/ HTTP/1.1" 500 112278
D:\Fanshawe\capstone\recover_smart\checklist_items\views.py changed, reloading.
Watching for file changes with StatReloader
D:\Fanshawe\capstone\recover_smart\checklist_items\views.py changed, reloading.
Watching for file changes with StatReloader
"POST /api/checklists/item/ HTTP/1.1" 201 233
D:\Fanshawe\capstone\recover_smart\attachments\services.py changed, reloading.
Watching for file changes with StatReloader
"POST /api/checklists/item/ HTTP/1.1" 201 233
D:\Fanshawe\capstone\recover_smart\attachments\services.py changed, reloading.
Watching for file changes with StatReloader
"POST /api/checklists/item/ HTTP/1.1" 201 233
D:\Fanshawe\capstone\recover_smart\attachments\services.py changed, reloading.
Watching for file changes with StatReloader
"POST /api/checklists/item/ HTTP/1.1" 201 233
D:\Fanshawe\capstone\recover_smart\attachments\services.py changed, reloading.
Watching for file changes with StatReloader
D:\Fanshawe\capstone\recover_smart\attachments\services.py changed, reloading.
Watching for file changes with StatReloader
D:\Fanshawe\capstone\recover_smart\attachments\services.py changed, reloading.
Watching for file changes with StatReloader
D:\Fanshawe\capstone\recover_smart\attachments\services.py changed, reloading.
Watching for file changes with StatReloader
D:\Fanshawe\capstone\recover_smart\checklist_items\views.py changed, reloading.
Watching for file changes with StatReloader
D:\Fanshawe\capstone\recover_smart\checklist_items\views.py changed, reloading.
Watching for file changes with StatReloader
Internal Server Error: /api/checklists/item/
Traceback (most recent call last):
  File "D:\Fanshawe\capstone\recover_smart\venv\Lib\site-packages\django\core\handlers\exception.py", line 55, in inner
    response = get_response(request)
  File "D:\Fanshawe\capstone\recover_smart\venv\Lib\site-packages\django\core\handlers\base.py", line 197, in _get_response
    response = wrapped_callback(request, *callback_args, **callback_kwargs)
  File "D:\Fanshawe\capstone\recover_smart\venv\Lib\site-packages\django\views\decorators\csrf.py", line 65, in _view_wrapper
    return view_func(request, *args, **kwargs)
  File "D:\Fanshawe\capstone\recover_smart\venv\Lib\site-packages\django\views\generic\base.py", line 104, in view
    return self.dispatch(request, *args, **kwargs)
           ~~~~~~~~~~~~~^^^^^^^^^^^^^^^^^^^^^^^^^^
  File "D:\Fanshawe\capstone\recover_smart\venv\Lib\site-packages\rest_framework\views.py", line 509, in dispatch
    response = self.handle_exception(exc)
  File "D:\Fanshawe\capstone\recover_smart\venv\Lib\site-packages\rest_framework\views.py", line 469, in handle_exception
    self.raise_uncaught_exception(exc)
    ~~~~~~~~~~~~~~~~~~~~~~~~~~~~~^^^^^
  File "D:\Fanshawe\capstone\recover_smart\venv\Lib\site-packages\rest_framework\views.py", line 480, in raise_uncaught_exception
    raise exc
  File "D:\Fanshawe\capstone\recover_smart\venv\Lib\site-packages\rest_framework\views.py", line 506, in dispatch
    response = handler(request, *args, **kwargs)
  File "D:\Fanshawe\capstone\recover_smart\checklist_items\views.py", line 34, in post
    FileUploadService.uploadFile(file, serializer.data['id'], "checklist_items")
    ~~~~~~~~~~~~~~~~~~~~~~~~~~~~^^^^^^^^^^^^^^^^^^^^^^^^^^^^^^^^^^^^^^^^^^^^^^^^
TypeError: FileUploadService.uploadFile() missing 1 required positional argument: 'entity'
"POST /api/checklists/item/ HTTP/1.1" 500 112452
D:\Fanshawe\capstone\recover_smart\checklist_items\views.py changed, reloading.
Watching for file changes with StatReloader
"POST /api/checklists/item/ HTTP/1.1" 201 233
D:\Fanshawe\capstone\recover_smart\checklist_items\views.py changed, reloading.
Watching for file changes with StatReloader
D:\Fanshawe\capstone\recover_smart\attachments\services.py changed, reloading.
Watching for file changes with StatReloader
D:\Fanshawe\capstone\recover_smart\checklist_items\views.py changed, reloading.
Watching for file changes with StatReloader
D:\Fanshawe\capstone\recover_smart\checklist_items\views.py changed, reloading.
Watching for file changes with StatReloader
"POST /api/checklists/item/ HTTP/1.1" 201 233
D:\Fanshawe\capstone\recover_smart\attachments\services.py changed, reloading.
Watching for file changes with StatReloader
D:\Fanshawe\capstone\recover_smart\attachments\services.py changed, reloading.
Watching for file changes with StatReloader
D:\Fanshawe\capstone\recover_smart\attachments\services.py changed, reloading.
Watching for file changes with StatReloader
D:\Fanshawe\capstone\recover_smart\attachments\services.py changed, reloading.
Watching for file changes with StatReloader
D:\Fanshawe\capstone\recover_smart\attachments\services.py changed, reloading.
Watching for file changes with StatReloader
D:\Fanshawe\capstone\recover_smart\attachments\services.py changed, reloading.
Watching for file changes with StatReloader
"POST /api/checklists/item/ HTTP/1.1" 201 233
"POST /api/checklists/item/ HTTP/1.1" 201 233
D:\Fanshawe\capstone\recover_smart\attachments\models.py changed, reloading.
Watching for file changes with StatReloader
Watching for file changes with StatReloader
D:\Fanshawe\capstone\recover_smart\attachments\models.py changed, reloading.
Watching for file changes with StatReloader
Watching for file changes with StatReloader
Watching for file changes with StatReloader
"GET /api/checklists/item/1 HTTP/1.1" 200 1455
Not Found: /api/api/attachments/
"POST /api/api/attachments/ HTTP/1.1" 404 7158
Not Found: /api/api/attachments
"POST /api/api/attachments HTTP/1.1" 404 7155
D:\Fanshawe\capstone\recover_smart\recoversmart\urls.py changed, reloading.
Watching for file changes with StatReloader
Not Found: /api/api/attachments
"POST /api/api/attachments HTTP/1.1" 404 7667
Internal Server Error: /api/attachments
Traceback (most recent call last):
  File "D:\Fanshawe\capstone\recover_smart\venv\Lib\site-packages\django\core\handlers\exception.py", line 55, in inner
    response = get_response(request)
  File "D:\Fanshawe\capstone\recover_smart\venv\Lib\site-packages\django\utils\deprecation.py", line 131, in __call__
    response = self.process_response(request, response)
  File "D:\Fanshawe\capstone\recover_smart\venv\Lib\site-packages\django\middleware\common.py", line 108, in process_response
    return self.response_redirect_class(self.get_full_path_with_slash(request))
                                        ~~~~~~~~~~~~~~~~~~~~~~~~~~~~~^^^^^^^^^
  File "D:\Fanshawe\capstone\recover_smart\venv\Lib\site-packages\django\middleware\common.py", line 87, in get_full_path_with_slash
    raise RuntimeError(
    ...<9 lines>...
    )
RuntimeError: You called this URL via POST, but the URL doesn't end in a slash and you have APPEND_SLASH set. Django can't redirect to the slash URL while maintaining POST data. Change your form to point to 127.0.0.1:8000/api/attachments/ (note the trailing slash), or set APPEND_SLASH=False in your Django settings.
"POST /api/attachments HTTP/1.1" 500 86949
D:\Fanshawe\capstone\recover_smart\attachments\urls.py changed, reloading.
Watching for file changes with StatReloader
Unauthorized: /api/attachments
"POST /api/attachments HTTP/1.1" 200 11
D:\Fanshawe\capstone\recover_smart\attachments\views.py changed, reloading.
Watching for file changes with StatReloader
D:\Fanshawe\capstone\recover_smart\attachments\views.py changed, reloading.
Watching for file changes with StatReloader
D:\Fanshawe\capstone\recover_smart\attachments\views.py changed, reloading.
Watching for file changes with StatReloader
D:\Fanshawe\capstone\recover_smart\attachments\views.py changed, reloading.
Watching for file changes with StatReloader
D:\Fanshawe\capstone\recover_smart\attachments\views.py changed, reloading.
Watching for file changes with StatReloader
D:\Fanshawe\capstone\recover_smart\attachments\views.py changed, reloading.
Watching for file changes with StatReloader
D:\Fanshawe\capstone\recover_smart\attachments\views.py changed, reloading.
Watching for file changes with StatReloader
Internal Server Error: /api/attachments
Traceback (most recent call last):
  File "D:\Fanshawe\capstone\recover_smart\venv\Lib\site-packages\django\core\handlers\exception.py", line 55, in inner
    response = get_response(request)
  File "D:\Fanshawe\capstone\recover_smart\venv\Lib\site-packages\django\core\handlers\base.py", line 197, in _get_response
    response = wrapped_callback(request, *callback_args, **callback_kwargs)
  File "D:\Fanshawe\capstone\recover_smart\venv\Lib\site-packages\django\views\decorators\csrf.py", line 65, in _view_wrapper
    return view_func(request, *args, **kwargs)
  File "D:\Fanshawe\capstone\recover_smart\venv\Lib\site-packages\django\views\generic\base.py", line 104, in view
    return self.dispatch(request, *args, **kwargs)
           ~~~~~~~~~~~~~^^^^^^^^^^^^^^^^^^^^^^^^^^
  File "D:\Fanshawe\capstone\recover_smart\venv\Lib\site-packages\rest_framework\views.py", line 511, in dispatch
    self.response = self.finalize_response(request, response, *args, **kwargs)
                    ~~~~~~~~~~~~~~~~~~~~~~^^^^^^^^^^^^^^^^^^^^^^^^^^^^^^^^^^^^
  File "D:\Fanshawe\capstone\recover_smart\venv\Lib\site-packages\rest_framework\views.py", line 423, in finalize_response
    assert isinstance(response, HttpResponseBase), (
           ~~~~~~~~~~^^^^^^^^^^^^^^^^^^^^^^^^^^^^
AssertionError: Expected a `Response`, `HttpResponse` or `StreamingHttpResponse` to be returned from the view, but received a `<class 'NoneType'>`
"POST /api/attachments HTTP/1.1" 500 96821
D:\Fanshawe\capstone\recover_smart\attachments\views.py changed, reloading.
Watching for file changes with StatReloader
D:\Fanshawe\capstone\recover_smart\attachments\views.py changed, reloading.
Watching for file changes with StatReloader
D:\Fanshawe\capstone\recover_smart\attachments\views.py changed, reloading.
Watching for file changes with StatReloader
D:\Fanshawe\capstone\recover_smart\attachments\views.py changed, reloading.
Watching for file changes with StatReloader
"POST /api/attachments HTTP/1.1" 201 40
"POST /api/attachments HTTP/1.1" 201 40
D:\Fanshawe\capstone\recover_smart\attachments\views.py changed, reloading.
Watching for file changes with StatReloader
"POST /api/attachments HTTP/1.1" 201 41
"POST /api/attachments HTTP/1.1" 201 41
"POST /api/attachments HTTP/1.1" 201 41
D:\Fanshawe\capstone\recover_smart\attachments\views.py changed, reloading.
Watching for file changes with StatReloader
D:\Fanshawe\capstone\recover_smart\attachments\views.py changed, reloading.
Watching for file changes with StatReloader
D:\Fanshawe\capstone\recover_smart\attachments\views.py changed, reloading.
Watching for file changes with StatReloader
D:\Fanshawe\capstone\recover_smart\attachments\views.py changed, reloading.
Watching for file changes with StatReloader
"POST /api/attachments HTTP/1.1" 201 41
D:\Fanshawe\capstone\recover_smart\attachments\views.py changed, reloading.
Watching for file changes with StatReloader
"POST /api/attachments HTTP/1.1" 201 41
"POST /api/attachments HTTP/1.1" 201 41
"POST /api/attachments HTTP/1.1" 201 41
D:\Fanshawe\capstone\recover_smart\attachments\views.py changed, reloading.
Watching for file changes with StatReloader
D:\Fanshawe\capstone\recover_smart\attachments\services.py changed, reloading.
Watching for file changes with StatReloader
D:\Fanshawe\capstone\recover_smart\attachments\services.py changed, reloading.
Watching for file changes with StatReloader
D:\Fanshawe\capstone\recover_smart\attachments\services.py changed, reloading.
Watching for file changes with StatReloader
D:\Fanshawe\capstone\recover_smart\attachments\services.py changed, reloading.
Watching for file changes with StatReloader
D:\Fanshawe\capstone\recover_smart\attachments\services.py changed, reloading.
Watching for file changes with StatReloader
D:\Fanshawe\capstone\recover_smart\attachments\services.py changed, reloading.
Watching for file changes with StatReloader
D:\Fanshawe\capstone\recover_smart\attachments\services.py changed, reloading.
Watching for file changes with StatReloader
D:\Fanshawe\capstone\recover_smart\attachments\services.py changed, reloading.
Watching for file changes with StatReloader
D:\Fanshawe\capstone\recover_smart\attachments\services.py changed, reloading.
Watching for file changes with StatReloader
D:\Fanshawe\capstone\recover_smart\attachments\services.py changed, reloading.
Watching for file changes with StatReloader
D:\Fanshawe\capstone\recover_smart\attachments\services.py changed, reloading.
Watching for file changes with StatReloader
D:\Fanshawe\capstone\recover_smart\attachments\services.py changed, reloading.
Watching for file changes with StatReloader
D:\Fanshawe\capstone\recover_smart\attachments\services.py changed, reloading.
Watching for file changes with StatReloader
Watching for file changes with StatReloader
D:\Fanshawe\capstone\recover_smart\attachments\views.py changed, reloading.
Watching for file changes with StatReloader
D:\Fanshawe\capstone\recover_smart\attachments\views.py changed, reloading.
Watching for file changes with StatReloader
Internal Server Error: /api/attachments/list
Traceback (most recent call last):
  File "D:\Fanshawe\capstone\recover_smart\venv\Lib\site-packages\django\core\handlers\exception.py", line 55, in inner
    response = get_response(request)
  File "D:\Fanshawe\capstone\recover_smart\venv\Lib\site-packages\django\core\handlers\base.py", line 197, in _get_response
    response = wrapped_callback(request, *callback_args, **callback_kwargs)
  File "D:\Fanshawe\capstone\recover_smart\venv\Lib\site-packages\django\views\decorators\csrf.py", line 65, in _view_wrapper
    return view_func(request, *args, **kwargs)
  File "D:\Fanshawe\capstone\recover_smart\venv\Lib\site-packages\django\views\generic\base.py", line 104, in view
    return self.dispatch(request, *args, **kwargs)
           ~~~~~~~~~~~~~^^^^^^^^^^^^^^^^^^^^^^^^^^
  File "D:\Fanshawe\capstone\recover_smart\venv\Lib\site-packages\rest_framework\views.py", line 509, in dispatch
    response = self.handle_exception(exc)
  File "D:\Fanshawe\capstone\recover_smart\venv\Lib\site-packages\rest_framework\views.py", line 469, in handle_exception
    self.raise_uncaught_exception(exc)
    ~~~~~~~~~~~~~~~~~~~~~~~~~~~~~^^^^^
  File "D:\Fanshawe\capstone\recover_smart\venv\Lib\site-packages\rest_framework\views.py", line 480, in raise_uncaught_exception
    raise exc
  File "D:\Fanshawe\capstone\recover_smart\venv\Lib\site-packages\rest_framework\views.py", line 506, in dispatch
    response = handler(request, *args, **kwargs)
  File "D:\Fanshawe\capstone\recover_smart\venv\Lib\site-packages\rest_framework\decorators.py", line 50, in handler
    return func(*args, **kwargs)
TypeError: AttachmentView.getFile() missing 1 required positional argument: 'request'
"GET /api/attachments/list HTTP/1.1" 500 109399
D:\Fanshawe\capstone\recover_smart\attachments\views.py changed, reloading.
Watching for file changes with StatReloader
D:\Fanshawe\capstone\recover_smart\attachments\views.py changed, reloading.
Watching for file changes with StatReloader
Internal Server Error: /api/attachments/list
Traceback (most recent call last):
  File "D:\Fanshawe\capstone\recover_smart\venv\Lib\site-packages\django\core\handlers\exception.py", line 55, in inner
    response = get_response(request)
  File "D:\Fanshawe\capstone\recover_smart\venv\Lib\site-packages\django\core\handlers\base.py", line 197, in _get_response
    response = wrapped_callback(request, *callback_args, **callback_kwargs)
  File "D:\Fanshawe\capstone\recover_smart\venv\Lib\site-packages\django\views\decorators\csrf.py", line 65, in _view_wrapper
    return view_func(request, *args, **kwargs)
  File "D:\Fanshawe\capstone\recover_smart\venv\Lib\site-packages\django\views\generic\base.py", line 104, in view
    return self.dispatch(request, *args, **kwargs)
           ~~~~~~~~~~~~~^^^^^^^^^^^^^^^^^^^^^^^^^^
  File "D:\Fanshawe\capstone\recover_smart\venv\Lib\site-packages\rest_framework\views.py", line 509, in dispatch
    response = self.handle_exception(exc)
  File "D:\Fanshawe\capstone\recover_smart\venv\Lib\site-packages\rest_framework\views.py", line 469, in handle_exception
    self.raise_uncaught_exception(exc)
    ~~~~~~~~~~~~~~~~~~~~~~~~~~~~~^^^^^
  File "D:\Fanshawe\capstone\recover_smart\venv\Lib\site-packages\rest_framework\views.py", line 480, in raise_uncaught_exception
    raise exc
  File "D:\Fanshawe\capstone\recover_smart\venv\Lib\site-packages\rest_framework\views.py", line 506, in dispatch
    response = handler(request, *args, **kwargs)
  File "D:\Fanshawe\capstone\recover_smart\venv\Lib\site-packages\rest_framework\decorators.py", line 50, in handler
    return func(*args, **kwargs)
TypeError: AttachmentView.getFile() missing 1 required positional argument: 'request'
"GET /api/attachments/list HTTP/1.1" 500 109399
Internal Server Error: /api/attachments/list
Traceback (most recent call last):
  File "D:\Fanshawe\capstone\recover_smart\venv\Lib\site-packages\django\core\handlers\exception.py", line 55, in inner
    response = get_response(request)
  File "D:\Fanshawe\capstone\recover_smart\venv\Lib\site-packages\django\core\handlers\base.py", line 197, in _get_response
    response = wrapped_callback(request, *callback_args, **callback_kwargs)
  File "D:\Fanshawe\capstone\recover_smart\venv\Lib\site-packages\django\views\decorators\csrf.py", line 65, in _view_wrapper
    return view_func(request, *args, **kwargs)
  File "D:\Fanshawe\capstone\recover_smart\venv\Lib\site-packages\django\views\generic\base.py", line 104, in view
    return self.dispatch(request, *args, **kwargs)
           ~~~~~~~~~~~~~^^^^^^^^^^^^^^^^^^^^^^^^^^
  File "D:\Fanshawe\capstone\recover_smart\venv\Lib\site-packages\rest_framework\views.py", line 509, in dispatch
    response = self.handle_exception(exc)
  File "D:\Fanshawe\capstone\recover_smart\venv\Lib\site-packages\rest_framework\views.py", line 469, in handle_exception
    self.raise_uncaught_exception(exc)
    ~~~~~~~~~~~~~~~~~~~~~~~~~~~~~^^^^^
  File "D:\Fanshawe\capstone\recover_smart\venv\Lib\site-packages\rest_framework\views.py", line 480, in raise_uncaught_exception
    raise exc
  File "D:\Fanshawe\capstone\recover_smart\venv\Lib\site-packages\rest_framework\views.py", line 506, in dispatch
    response = handler(request, *args, **kwargs)
  File "D:\Fanshawe\capstone\recover_smart\venv\Lib\site-packages\rest_framework\decorators.py", line 50, in handler
    return func(*args, **kwargs)
TypeError: AttachmentView.getFile() missing 1 required positional argument: 'request'
"GET /api/attachments/list HTTP/1.1" 500 109399
D:\Fanshawe\capstone\recover_smart\attachments\services.py changed, reloading.
Watching for file changes with StatReloader
Internal Server Error: /api/attachments/list
Traceback (most recent call last):
  File "D:\Fanshawe\capstone\recover_smart\venv\Lib\site-packages\django\core\handlers\exception.py", line 55, in inner
    response = get_response(request)
  File "D:\Fanshawe\capstone\recover_smart\venv\Lib\site-packages\django\core\handlers\base.py", line 197, in _get_response
    response = wrapped_callback(request, *callback_args, **callback_kwargs)
  File "D:\Fanshawe\capstone\recover_smart\venv\Lib\site-packages\django\views\decorators\csrf.py", line 65, in _view_wrapper
    return view_func(request, *args, **kwargs)
  File "D:\Fanshawe\capstone\recover_smart\venv\Lib\site-packages\django\views\generic\base.py", line 104, in view
    return self.dispatch(request, *args, **kwargs)
           ~~~~~~~~~~~~~^^^^^^^^^^^^^^^^^^^^^^^^^^
  File "D:\Fanshawe\capstone\recover_smart\venv\Lib\site-packages\rest_framework\views.py", line 509, in dispatch
    response = self.handle_exception(exc)
  File "D:\Fanshawe\capstone\recover_smart\venv\Lib\site-packages\rest_framework\views.py", line 469, in handle_exception
    self.raise_uncaught_exception(exc)
    ~~~~~~~~~~~~~~~~~~~~~~~~~~~~~^^^^^
  File "D:\Fanshawe\capstone\recover_smart\venv\Lib\site-packages\rest_framework\views.py", line 480, in raise_uncaught_exception
    raise exc
  File "D:\Fanshawe\capstone\recover_smart\venv\Lib\site-packages\rest_framework\views.py", line 506, in dispatch
    response = handler(request, *args, **kwargs)
  File "D:\Fanshawe\capstone\recover_smart\venv\Lib\site-packages\rest_framework\decorators.py", line 50, in handler
    return func(*args, **kwargs)
TypeError: AttachmentView.getFile() missing 1 required positional argument: 'request'
"GET /api/attachments/list HTTP/1.1" 500 109399
D:\Fanshawe\capstone\recover_smart\attachments\views.py changed, reloading.
Watching for file changes with StatReloader
Unsupported Media Type: /api/attachments/list
"GET /api/attachments/list HTTP/1.1" 415 132
D:\Fanshawe\capstone\recover_smart\attachments\views.py changed, reloading.
Watching for file changes with StatReloader
Internal Server Error: /api/attachments/list
Traceback (most recent call last):
  File "D:\Fanshawe\capstone\recover_smart\venv\Lib\site-packages\django\core\handlers\exception.py", line 55, in inner
    response = get_response(request)
  File "D:\Fanshawe\capstone\recover_smart\venv\Lib\site-packages\django\core\handlers\base.py", line 197, in _get_response
    response = wrapped_callback(request, *callback_args, **callback_kwargs)
  File "D:\Fanshawe\capstone\recover_smart\venv\Lib\site-packages\django\views\decorators\csrf.py", line 65, in _view_wrapper
    return view_func(request, *args, **kwargs)
  File "D:\Fanshawe\capstone\recover_smart\venv\Lib\site-packages\django\views\generic\base.py", line 104, in view
    return self.dispatch(request, *args, **kwargs)
           ~~~~~~~~~~~~~^^^^^^^^^^^^^^^^^^^^^^^^^^
  File "D:\Fanshawe\capstone\recover_smart\venv\Lib\site-packages\rest_framework\views.py", line 509, in dispatch
    response = self.handle_exception(exc)
  File "D:\Fanshawe\capstone\recover_smart\venv\Lib\site-packages\rest_framework\views.py", line 469, in handle_exception
    self.raise_uncaught_exception(exc)
    ~~~~~~~~~~~~~~~~~~~~~~~~~~~~~^^^^^
  File "D:\Fanshawe\capstone\recover_smart\venv\Lib\site-packages\rest_framework\views.py", line 480, in raise_uncaught_exception
    raise exc
  File "D:\Fanshawe\capstone\recover_smart\venv\Lib\site-packages\rest_framework\views.py", line 506, in dispatch
    response = handler(request, *args, **kwargs)
  File "D:\Fanshawe\capstone\recover_smart\venv\Lib\site-packages\rest_framework\decorators.py", line 50, in handler
    return func(*args, **kwargs)
  File "D:\Fanshawe\capstone\recover_smart\attachments\views.py", line 21, in getFile
    files = service.getFiles(request.data['id'],request.data['entity'])  # Get files
TypeError: FileUploadService.getFiles() takes 2 positional arguments but 3 were given
"GET /api/attachments/list HTTP/1.1" 500 113402
D:\Fanshawe\capstone\recover_smart\attachments\views.py changed, reloading.
Watching for file changes with StatReloader
D:\Fanshawe\capstone\recover_smart\attachments\services.py changed, reloading.
Watching for file changes with StatReloader
"GET /api/attachments/list HTTP/1.1" 200 2
"GET /api/attachments/list HTTP/1.1" 200 2
D:\Fanshawe\capstone\recover_smart\attachments\services.py changed, reloading.
Watching for file changes with StatReloader
D:\Fanshawe\capstone\recover_smart\attachments\services.py changed, reloading.
Watching for file changes with StatReloader
"GET /api/attachments/list HTTP/1.1" 200 367
D:\Fanshawe\capstone\recover_smart\attachments\services.py changed, reloading.
Watching for file changes with StatReloader
D:\Fanshawe\capstone\recover_smart\attachments\services.py changed, reloading.
Watching for file changes with StatReloader
D:\Fanshawe\capstone\recover_smart\attachments\services.py changed, reloading.
Watching for file changes with StatReloader
D:\Fanshawe\capstone\recover_smart\attachments\services.py changed, reloading.
Watching for file changes with StatReloader
D:\Fanshawe\capstone\recover_smart\attachments\services.py changed, reloading.
Watching for file changes with StatReloader
D:\Fanshawe\capstone\recover_smart\attachments\services.py changed, reloading.
Watching for file changes with StatReloader
D:\Fanshawe\capstone\recover_smart\attachments\services.py changed, reloading.
Watching for file changes with StatReloader
D:\Fanshawe\capstone\recover_smart\attachments\services.py changed, reloading.
Watching for file changes with StatReloader
D:\Fanshawe\capstone\recover_smart\attachments\services.py changed, reloading.
Watching for file changes with StatReloader
D:\Fanshawe\capstone\recover_smart\attachments\services.py changed, reloading.
Watching for file changes with StatReloader
D:\Fanshawe\capstone\recover_smart\attachments\services.py changed, reloading.
Watching for file changes with StatReloader
D:\Fanshawe\capstone\recover_smart\attachments\services.py changed, reloading.
Watching for file changes with StatReloader
D:\Fanshawe\capstone\recover_smart\attachments\services.py changed, reloading.
Watching for file changes with StatReloader
"GET /api/attachments/list HTTP/1.1" 200 367
D:\Fanshawe\capstone\recover_smart\attachments\urls.py changed, reloading.
Watching for file changes with StatReloader
D:\Fanshawe\capstone\recover_smart\attachments\views.py changed, reloading.
Watching for file changes with StatReloader
D:\Fanshawe\capstone\recover_smart\attachments\views.py changed, reloading.
Watching for file changes with StatReloader
Internal Server Error: /api/attachments/file
Traceback (most recent call last):
  File "D:\Fanshawe\capstone\recover_smart\venv\Lib\site-packages\django\core\handlers\exception.py", line 55, in inner
    response = get_response(request)
  File "D:\Fanshawe\capstone\recover_smart\venv\Lib\site-packages\django\core\handlers\base.py", line 197, in _get_response
    response = wrapped_callback(request, *callback_args, **callback_kwargs)
  File "D:\Fanshawe\capstone\recover_smart\attachments\views.py", line 34, in getSingleFile
    file = service.getSingleFile(request.data['file_id'])  # Get file
                                 ^^^^^^^^^^^^
AttributeError: 'WSGIRequest' object has no attribute 'data'
"GET /api/attachments/file HTTP/1.1" 500 81077
Internal Server Error: /api/attachments/file
Traceback (most recent call last):
  File "D:\Fanshawe\capstone\recover_smart\venv\Lib\site-packages\django\core\handlers\exception.py", line 55, in inner
    response = get_response(request)
  File "D:\Fanshawe\capstone\recover_smart\venv\Lib\site-packages\django\core\handlers\base.py", line 197, in _get_response
    response = wrapped_callback(request, *callback_args, **callback_kwargs)
  File "D:\Fanshawe\capstone\recover_smart\attachments\views.py", line 34, in getSingleFile
    file = service.getSingleFile(request.data['file_id'])  # Get file
                                 ^^^^^^^^^^^^
AttributeError: 'WSGIRequest' object has no attribute 'data'
"GET /api/attachments/file HTTP/1.1" 500 81077
D:\Fanshawe\capstone\recover_smart\attachments\views.py changed, reloading.
Watching for file changes with StatReloader
Unsupported Media Type: /api/attachments/file
"GET /api/attachments/file HTTP/1.1" 415 132
Internal Server Error: /api/attachments/file
Traceback (most recent call last):
  File "D:\Fanshawe\capstone\recover_smart\venv\Lib\site-packages\django\core\handlers\exception.py", line 55, in inner
    response = get_response(request)
  File "D:\Fanshawe\capstone\recover_smart\venv\Lib\site-packages\django\core\handlers\base.py", line 197, in _get_response
    response = wrapped_callback(request, *callback_args, **callback_kwargs)
  File "D:\Fanshawe\capstone\recover_smart\venv\Lib\site-packages\django\views\decorators\csrf.py", line 65, in _view_wrapper
    return view_func(request, *args, **kwargs)
  File "D:\Fanshawe\capstone\recover_smart\venv\Lib\site-packages\django\views\generic\base.py", line 104, in view
    return self.dispatch(request, *args, **kwargs)
           ~~~~~~~~~~~~~^^^^^^^^^^^^^^^^^^^^^^^^^^
  File "D:\Fanshawe\capstone\recover_smart\venv\Lib\site-packages\rest_framework\views.py", line 509, in dispatch
    response = self.handle_exception(exc)
  File "D:\Fanshawe\capstone\recover_smart\venv\Lib\site-packages\rest_framework\views.py", line 469, in handle_exception
    self.raise_uncaught_exception(exc)
    ~~~~~~~~~~~~~~~~~~~~~~~~~~~~~^^^^^
  File "D:\Fanshawe\capstone\recover_smart\venv\Lib\site-packages\rest_framework\views.py", line 480, in raise_uncaught_exception
    raise exc
  File "D:\Fanshawe\capstone\recover_smart\venv\Lib\site-packages\rest_framework\views.py", line 506, in dispatch
    response = handler(request, *args, **kwargs)
  File "D:\Fanshawe\capstone\recover_smart\venv\Lib\site-packages\rest_framework\decorators.py", line 50, in handler
    return func(*args, **kwargs)
  File "D:\Fanshawe\capstone\recover_smart\attachments\views.py", line 35, in getSingleFile
    file = service.getSingleFile(request.data['file_id'])  # Get file
                                 ~~~~~~~~~~~~^^^^^^^^^^^
KeyError: 'file_id'
"GET /api/attachments/file HTTP/1.1" 500 112271
"GET /api/attachments/file HTTP/1.1" 200 223
D:\Fanshawe\capstone\recover_smart\attachments\services.py changed, reloading.
Watching for file changes with StatReloader
Internal Server Error: /api/attachments/file
Traceback (most recent call last):
  File "D:\Fanshawe\capstone\recover_smart\venv\Lib\site-packages\django\core\handlers\exception.py", line 55, in inner
    response = get_response(request)
  File "D:\Fanshawe\capstone\recover_smart\venv\Lib\site-packages\django\core\handlers\base.py", line 220, in _get_response
    response = response.render()
  File "D:\Fanshawe\capstone\recover_smart\venv\Lib\site-packages\django\template\response.py", line 114, in render
    self.content = self.rendered_content
                   ^^^^^^^^^^^^^^^^^^^^^
  File "D:\Fanshawe\capstone\recover_smart\venv\Lib\site-packages\rest_framework\response.py", line 74, in rendered_content
    ret = renderer.render(self.data, accepted_media_type, context)
  File "D:\Fanshawe\capstone\recover_smart\venv\Lib\site-packages\rest_framework\renderers.py", line 100, in render
    ret = json.dumps(
        data, cls=self.encoder_class,
        indent=indent, ensure_ascii=self.ensure_ascii,
        allow_nan=not self.strict, separators=separators
    )
  File "D:\Fanshawe\capstone\recover_smart\venv\Lib\site-packages\rest_framework\utils\json.py", line 25, in dumps
    return json.dumps(*args, **kwargs)
           ~~~~~~~~~~^^^^^^^^^^^^^^^^^
  File "C:\Users\moham\AppData\Local\Programs\Python\Python313\Lib\json\__init__.py", line 238, in dumps
    **kw).encode(obj)
          ~~~~~~^^^^^
  File "C:\Users\moham\AppData\Local\Programs\Python\Python313\Lib\json\encoder.py", line 200, in encode
    chunks = self.iterencode(o, _one_shot=True)
  File "C:\Users\moham\AppData\Local\Programs\Python\Python313\Lib\json\encoder.py", line 261, in iterencode
    return _iterencode(o, 0)
  File "D:\Fanshawe\capstone\recover_smart\venv\Lib\site-packages\rest_framework\utils\encoders.py", line 52, in default
    return obj.decode()
           ~~~~~~~~~~^^
UnicodeDecodeError: 'utf-8' codec can't decode byte 0xff in position 0: invalid start byte
"GET /api/attachments/file HTTP/1.1" 500 151260
D:\Fanshawe\capstone\recover_smart\attachments\services.py changed, reloading.
Watching for file changes with StatReloader
D:\Fanshawe\capstone\recover_smart\attachments\services.py changed, reloading.
Watching for file changes with StatReloader
D:\Fanshawe\capstone\recover_smart\attachments\services.py changed, reloading.
Watching for file changes with StatReloader
Internal Server Error: /api/attachments/file
Traceback (most recent call last):
  File "D:\Fanshawe\capstone\recover_smart\venv\Lib\site-packages\django\core\handlers\exception.py", line 55, in inner
    response = get_response(request)
  File "D:\Fanshawe\capstone\recover_smart\venv\Lib\site-packages\django\core\handlers\base.py", line 197, in _get_response
    response = wrapped_callback(request, *callback_args, **callback_kwargs)
  File "D:\Fanshawe\capstone\recover_smart\venv\Lib\site-packages\django\views\decorators\csrf.py", line 65, in _view_wrapper
    return view_func(request, *args, **kwargs)
  File "D:\Fanshawe\capstone\recover_smart\venv\Lib\site-packages\django\views\generic\base.py", line 104, in view
    return self.dispatch(request, *args, **kwargs)
           ~~~~~~~~~~~~~^^^^^^^^^^^^^^^^^^^^^^^^^^
  File "D:\Fanshawe\capstone\recover_smart\venv\Lib\site-packages\rest_framework\views.py", line 509, in dispatch
    response = self.handle_exception(exc)
  File "D:\Fanshawe\capstone\recover_smart\venv\Lib\site-packages\rest_framework\views.py", line 469, in handle_exception
    self.raise_uncaught_exception(exc)
    ~~~~~~~~~~~~~~~~~~~~~~~~~~~~~^^^^^
  File "D:\Fanshawe\capstone\recover_smart\venv\Lib\site-packages\rest_framework\views.py", line 480, in raise_uncaught_exception
    raise exc
  File "D:\Fanshawe\capstone\recover_smart\venv\Lib\site-packages\rest_framework\views.py", line 506, in dispatch
    response = handler(request, *args, **kwargs)
  File "D:\Fanshawe\capstone\recover_smart\venv\Lib\site-packages\rest_framework\decorators.py", line 50, in handler
    return func(*args, **kwargs)
  File "D:\Fanshawe\capstone\recover_smart\attachments\views.py", line 35, in getSingleFile
    file = service.getSingleFile(request.data['file_id'])  # Get file
           ^^^^^^^^^^^^^^^^^^^^^
AttributeError: 'FileUploadService' object has no attribute 'getSingleFile'
"GET /api/attachments/file HTTP/1.1" 500 112675
D:\Fanshawe\capstone\recover_smart\attachments\services.py changed, reloading.
Watching for file changes with StatReloader
D:\Fanshawe\capstone\recover_smart\attachments\services.py changed, reloading.
Watching for file changes with StatReloader
Internal Server Error: /api/attachments/file
Traceback (most recent call last):
  File "D:\Fanshawe\capstone\recover_smart\venv\Lib\site-packages\django\core\handlers\exception.py", line 55, in inner
    response = get_response(request)
  File "D:\Fanshawe\capstone\recover_smart\venv\Lib\site-packages\django\core\handlers\base.py", line 197, in _get_response
    response = wrapped_callback(request, *callback_args, **callback_kwargs)
  File "D:\Fanshawe\capstone\recover_smart\venv\Lib\site-packages\django\views\decorators\csrf.py", line 65, in _view_wrapper
    return view_func(request, *args, **kwargs)
  File "D:\Fanshawe\capstone\recover_smart\venv\Lib\site-packages\django\views\generic\base.py", line 104, in view
    return self.dispatch(request, *args, **kwargs)
           ~~~~~~~~~~~~~^^^^^^^^^^^^^^^^^^^^^^^^^^
  File "D:\Fanshawe\capstone\recover_smart\venv\Lib\site-packages\rest_framework\views.py", line 509, in dispatch
    response = self.handle_exception(exc)
  File "D:\Fanshawe\capstone\recover_smart\venv\Lib\site-packages\rest_framework\views.py", line 469, in handle_exception
    self.raise_uncaught_exception(exc)
    ~~~~~~~~~~~~~~~~~~~~~~~~~~~~~^^^^^
  File "D:\Fanshawe\capstone\recover_smart\venv\Lib\site-packages\rest_framework\views.py", line 480, in raise_uncaught_exception
    raise exc
  File "D:\Fanshawe\capstone\recover_smart\venv\Lib\site-packages\rest_framework\views.py", line 506, in dispatch
    response = handler(request, *args, **kwargs)
  File "D:\Fanshawe\capstone\recover_smart\venv\Lib\site-packages\rest_framework\decorators.py", line 50, in handler
    return func(*args, **kwargs)
  File "D:\Fanshawe\capstone\recover_smart\attachments\views.py", line 35, in getSingleFile
    file = service.getSingleFile(request.data['file_id'])  # Get file
           ^^^^^^^^^^^^^^^^^^^^^
AttributeError: 'FileUploadService' object has no attribute 'getSingleFile'
"GET /api/attachments/file HTTP/1.1" 500 112675
D:\Fanshawe\capstone\recover_smart\attachments\services.py changed, reloading.
Watching for file changes with StatReloader
Internal Server Error: /api/attachments/file
Traceback (most recent call last):
  File "D:\Fanshawe\capstone\recover_smart\venv\Lib\site-packages\django\core\handlers\exception.py", line 55, in inner
    response = get_response(request)
  File "D:\Fanshawe\capstone\recover_smart\venv\Lib\site-packages\django\core\handlers\base.py", line 197, in _get_response
    response = wrapped_callback(request, *callback_args, **callback_kwargs)
  File "D:\Fanshawe\capstone\recover_smart\venv\Lib\site-packages\django\views\decorators\csrf.py", line 65, in _view_wrapper
    return view_func(request, *args, **kwargs)
  File "D:\Fanshawe\capstone\recover_smart\venv\Lib\site-packages\django\views\generic\base.py", line 104, in view
    return self.dispatch(request, *args, **kwargs)
           ~~~~~~~~~~~~~^^^^^^^^^^^^^^^^^^^^^^^^^^
  File "D:\Fanshawe\capstone\recover_smart\venv\Lib\site-packages\rest_framework\views.py", line 509, in dispatch
    response = self.handle_exception(exc)
  File "D:\Fanshawe\capstone\recover_smart\venv\Lib\site-packages\rest_framework\views.py", line 469, in handle_exception
    self.raise_uncaught_exception(exc)
    ~~~~~~~~~~~~~~~~~~~~~~~~~~~~~^^^^^
  File "D:\Fanshawe\capstone\recover_smart\venv\Lib\site-packages\rest_framework\views.py", line 480, in raise_uncaught_exception
    raise exc
  File "D:\Fanshawe\capstone\recover_smart\venv\Lib\site-packages\rest_framework\views.py", line 506, in dispatch
    response = handler(request, *args, **kwargs)
  File "D:\Fanshawe\capstone\recover_smart\venv\Lib\site-packages\rest_framework\decorators.py", line 50, in handler
    return func(*args, **kwargs)
  File "D:\Fanshawe\capstone\recover_smart\attachments\views.py", line 35, in getSingleFile
    file = service.getSingleFile(request.data['file_id'])  # Get file
TypeError: FileUploadService.getSingleFile() takes 1 positional argument but 2 were given
"GET /api/attachments/file HTTP/1.1" 500 112679
D:\Fanshawe\capstone\recover_smart\attachments\views.py changed, reloading.
Watching for file changes with StatReloader
Internal Server Error: /api/attachments/file
Traceback (most recent call last):
  File "D:\Fanshawe\capstone\recover_smart\venv\Lib\site-packages\django\core\handlers\exception.py", line 55, in inner
    response = get_response(request)
  File "D:\Fanshawe\capstone\recover_smart\venv\Lib\site-packages\django\core\handlers\base.py", line 197, in _get_response
    response = wrapped_callback(request, *callback_args, **callback_kwargs)
  File "D:\Fanshawe\capstone\recover_smart\venv\Lib\site-packages\django\views\decorators\csrf.py", line 65, in _view_wrapper
    return view_func(request, *args, **kwargs)
  File "D:\Fanshawe\capstone\recover_smart\venv\Lib\site-packages\django\views\generic\base.py", line 104, in view
    return self.dispatch(request, *args, **kwargs)
           ~~~~~~~~~~~~~^^^^^^^^^^^^^^^^^^^^^^^^^^
  File "D:\Fanshawe\capstone\recover_smart\venv\Lib\site-packages\rest_framework\views.py", line 509, in dispatch
    response = self.handle_exception(exc)
  File "D:\Fanshawe\capstone\recover_smart\venv\Lib\site-packages\rest_framework\views.py", line 469, in handle_exception
    self.raise_uncaught_exception(exc)
    ~~~~~~~~~~~~~~~~~~~~~~~~~~~~~^^^^^
  File "D:\Fanshawe\capstone\recover_smart\venv\Lib\site-packages\rest_framework\views.py", line 480, in raise_uncaught_exception
    raise exc
  File "D:\Fanshawe\capstone\recover_smart\venv\Lib\site-packages\rest_framework\views.py", line 506, in dispatch
    response = handler(request, *args, **kwargs)
  File "D:\Fanshawe\capstone\recover_smart\venv\Lib\site-packages\rest_framework\decorators.py", line 50, in handler
    return func(*args, **kwargs)
  File "D:\Fanshawe\capstone\recover_smart\attachments\views.py", line 35, in getSingleFile
    file = service.getSingleFile(1)  # Get file
TypeError: FileUploadService.getSingleFile() takes 1 positional argument but 2 were given
"GET /api/attachments/file HTTP/1.1" 500 112571
D:\Fanshawe\capstone\recover_smart\attachments\views.py changed, reloading.
Watching for file changes with StatReloader
D:\Fanshawe\capstone\recover_smart\attachments\views.py changed, reloading.
Watching for file changes with StatReloader
Internal Server Error: /api/attachments/file
Traceback (most recent call last):
  File "D:\Fanshawe\capstone\recover_smart\venv\Lib\site-packages\django\db\models\fields\__init__.py", line 2123, in get_prep_value
    return int(value)
TypeError: int() argument must be a string, a bytes-like object or a real number, not 'FileUploadService'

The above exception was the direct cause of the following exception:

Traceback (most recent call last):
  File "D:\Fanshawe\capstone\recover_smart\venv\Lib\site-packages\django\core\handlers\exception.py", line 55, in inner
    response = get_response(request)
  File "D:\Fanshawe\capstone\recover_smart\venv\Lib\site-packages\django\core\handlers\base.py", line 197, in _get_response
    response = wrapped_callback(request, *callback_args, **callback_kwargs)
  File "D:\Fanshawe\capstone\recover_smart\venv\Lib\site-packages\django\views\decorators\csrf.py", line 65, in _view_wrapper
    return view_func(request, *args, **kwargs)
  File "D:\Fanshawe\capstone\recover_smart\venv\Lib\site-packages\django\views\generic\base.py", line 104, in view
    return self.dispatch(request, *args, **kwargs)
           ~~~~~~~~~~~~~^^^^^^^^^^^^^^^^^^^^^^^^^^
  File "D:\Fanshawe\capstone\recover_smart\venv\Lib\site-packages\rest_framework\views.py", line 509, in dispatch
    response = self.handle_exception(exc)
  File "D:\Fanshawe\capstone\recover_smart\venv\Lib\site-packages\rest_framework\views.py", line 469, in handle_exception
    self.raise_uncaught_exception(exc)
    ~~~~~~~~~~~~~~~~~~~~~~~~~~~~~^^^^^
  File "D:\Fanshawe\capstone\recover_smart\venv\Lib\site-packages\rest_framework\views.py", line 480, in raise_uncaught_exception
    raise exc
  File "D:\Fanshawe\capstone\recover_smart\venv\Lib\site-packages\rest_framework\views.py", line 506, in dispatch
    response = handler(request, *args, **kwargs)
  File "D:\Fanshawe\capstone\recover_smart\venv\Lib\site-packages\rest_framework\decorators.py", line 50, in handler
    return func(*args, **kwargs)
  File "D:\Fanshawe\capstone\recover_smart\attachments\views.py", line 35, in getSingleFile
    file = service.getSingleFile()  # Get file
  File "D:\Fanshawe\capstone\recover_smart\attachments\services.py", line 54, in getSingleFile
    file = Attachment.objects.get(id=file_id)
  File "D:\Fanshawe\capstone\recover_smart\venv\Lib\site-packages\django\db\models\manager.py", line 87, in manager_method
    return getattr(self.get_queryset(), name)(*args, **kwargs)
           ~~~~~~~~~~~~~~~~~~~~~~~~~~~~~~~~~~^^^^^^^^^^^^^^^^^
  File "D:\Fanshawe\capstone\recover_smart\venv\Lib\site-packages\django\db\models\query.py", line 635, in get
    clone = self._chain() if self.query.combinator else self.filter(*args, **kwargs)
                                                        ~~~~~~~~~~~^^^^^^^^^^^^^^^^^
  File "D:\Fanshawe\capstone\recover_smart\venv\Lib\site-packages\django\db\models\query.py", line 1476, in filter
    return self._filter_or_exclude(False, args, kwargs)
           ~~~~~~~~~~~~~~~~~~~~~~~^^^^^^^^^^^^^^^^^^^^^
  File "D:\Fanshawe\capstone\recover_smart\venv\Lib\site-packages\django\db\models\query.py", line 1494, in _filter_or_exclude
    clone._filter_or_exclude_inplace(negate, args, kwargs)
    ~~~~~~~~~~~~~~~~~~~~~~~~~~~~~~~~^^^^^^^^^^^^^^^^^^^^^^
  File "D:\Fanshawe\capstone\recover_smart\venv\Lib\site-packages\django\db\models\query.py", line 1501, in _filter_or_exclude_inplace
    self._query.add_q(Q(*args, **kwargs))
    ~~~~~~~~~~~~~~~~~^^^^^^^^^^^^^^^^^^^^
  File "D:\Fanshawe\capstone\recover_smart\venv\Lib\site-packages\django\db\models\sql\query.py", line 1609, in add_q
    clause, _ = self._add_q(q_object, self.used_aliases)
                ~~~~~~~~~~~^^^^^^^^^^^^^^^^^^^^^^^^^^^^^
  File "D:\Fanshawe\capstone\recover_smart\venv\Lib\site-packages\django\db\models\sql\query.py", line 1641, in _add_q
    child_clause, needed_inner = self.build_filter(
                                 ~~~~~~~~~~~~~~~~~^
        child,
        ^^^^^^
    ...<7 lines>...
        update_join_types=update_join_types,
        ^^^^^^^^^^^^^^^^^^^^^^^^^^^^^^^^^^^^
    )
    ^
  File "D:\Fanshawe\capstone\recover_smart\venv\Lib\site-packages\django\db\models\sql\query.py", line 1555, in build_filter
    condition = self.build_lookup(lookups, col, value)
  File "D:\Fanshawe\capstone\recover_smart\venv\Lib\site-packages\django\db\models\sql\query.py", line 1385, in build_lookup
    lookup = lookup_class(lhs, rhs)
  File "D:\Fanshawe\capstone\recover_smart\venv\Lib\site-packages\django\db\models\lookups.py", line 30, in __init__
    self.rhs = self.get_prep_lookup()
               ~~~~~~~~~~~~~~~~~~~~^^
  File "D:\Fanshawe\capstone\recover_smart\venv\Lib\site-packages\django\db\models\lookups.py", line 369, in get_prep_lookup
    return super().get_prep_lookup()
           ~~~~~~~~~~~~~~~~~~~~~~~^^
  File "D:\Fanshawe\capstone\recover_smart\venv\Lib\site-packages\django\db\models\lookups.py", line 88, in get_prep_lookup
    return self.lhs.output_field.get_prep_value(self.rhs)
           ~~~~~~~~~~~~~~~~~~~~~~~~~~~~~~~~~~~~^^^^^^^^^^
  File "D:\Fanshawe\capstone\recover_smart\venv\Lib\site-packages\django\db\models\fields\__init__.py", line 2125, in get_prep_value
    raise e.__class__(
        "Field '%s' expected a number but got %r." % (self.name, value),
    ) from e
TypeError: Field 'id' expected a number but got <attachments.services.FileUploadService object at 0x000001181DE18C20>.
"GET /api/attachments/file HTTP/1.1" 500 184469
D:\Fanshawe\capstone\recover_smart\attachments\views.py changed, reloading.
Watching for file changes with StatReloader
Internal Server Error: /api/attachments/file
Traceback (most recent call last):
  File "D:\Fanshawe\capstone\recover_smart\venv\Lib\site-packages\django\core\handlers\exception.py", line 55, in inner
    response = get_response(request)
  File "D:\Fanshawe\capstone\recover_smart\venv\Lib\site-packages\django\core\handlers\base.py", line 197, in _get_response
    response = wrapped_callback(request, *callback_args, **callback_kwargs)
  File "D:\Fanshawe\capstone\recover_smart\venv\Lib\site-packages\django\views\decorators\csrf.py", line 65, in _view_wrapper
    return view_func(request, *args, **kwargs)
  File "D:\Fanshawe\capstone\recover_smart\venv\Lib\site-packages\django\views\generic\base.py", line 104, in view
    return self.dispatch(request, *args, **kwargs)
           ~~~~~~~~~~~~~^^^^^^^^^^^^^^^^^^^^^^^^^^
  File "D:\Fanshawe\capstone\recover_smart\venv\Lib\site-packages\rest_framework\views.py", line 509, in dispatch
    response = self.handle_exception(exc)
  File "D:\Fanshawe\capstone\recover_smart\venv\Lib\site-packages\rest_framework\views.py", line 469, in handle_exception
    self.raise_uncaught_exception(exc)
    ~~~~~~~~~~~~~~~~~~~~~~~~~~~~~^^^^^
  File "D:\Fanshawe\capstone\recover_smart\venv\Lib\site-packages\rest_framework\views.py", line 480, in raise_uncaught_exception
    raise exc
  File "D:\Fanshawe\capstone\recover_smart\venv\Lib\site-packages\rest_framework\views.py", line 506, in dispatch
    response = handler(request, *args, **kwargs)
  File "D:\Fanshawe\capstone\recover_smart\venv\Lib\site-packages\rest_framework\decorators.py", line 50, in handler
    return func(*args, **kwargs)
  File "D:\Fanshawe\capstone\recover_smart\attachments\views.py", line 35, in getSingleFile
    file = service.getSingleFile(request.data['file_id'])  # Get file
TypeError: FileUploadService.getSingleFile() takes 1 positional argument but 2 were given
"GET /api/attachments/file HTTP/1.1" 500 112679
D:\Fanshawe\capstone\recover_smart\attachments\views.py changed, reloading.
Watching for file changes with StatReloader
D:\Fanshawe\capstone\recover_smart\attachments\views.py changed, reloading.
Watching for file changes with StatReloader
D:\Fanshawe\capstone\recover_smart\attachments\views.py changed, reloading.
Watching for file changes with StatReloader
"GET /api/attachments/file HTTP/1.1" 200 6
D:\Fanshawe\capstone\recover_smart\attachments\views.py changed, reloading.
Watching for file changes with StatReloader
D:\Fanshawe\capstone\recover_smart\attachments\views.py changed, reloading.
Watching for file changes with StatReloader
D:\Fanshawe\capstone\recover_smart\attachments\services.py changed, reloading.
Watching for file changes with StatReloader
Internal Server Error: /api/attachments/file
Traceback (most recent call last):
  File "D:\Fanshawe\capstone\recover_smart\venv\Lib\site-packages\django\core\handlers\exception.py", line 55, in inner
    response = get_response(request)
  File "D:\Fanshawe\capstone\recover_smart\venv\Lib\site-packages\django\core\handlers\base.py", line 197, in _get_response
    response = wrapped_callback(request, *callback_args, **callback_kwargs)
  File "D:\Fanshawe\capstone\recover_smart\venv\Lib\site-packages\django\views\decorators\csrf.py", line 65, in _view_wrapper
    return view_func(request, *args, **kwargs)
  File "D:\Fanshawe\capstone\recover_smart\venv\Lib\site-packages\django\views\generic\base.py", line 104, in view
    return self.dispatch(request, *args, **kwargs)
           ~~~~~~~~~~~~~^^^^^^^^^^^^^^^^^^^^^^^^^^
  File "D:\Fanshawe\capstone\recover_smart\venv\Lib\site-packages\rest_framework\views.py", line 509, in dispatch
    response = self.handle_exception(exc)
  File "D:\Fanshawe\capstone\recover_smart\venv\Lib\site-packages\rest_framework\views.py", line 469, in handle_exception
    self.raise_uncaught_exception(exc)
    ~~~~~~~~~~~~~~~~~~~~~~~~~~~~~^^^^^
  File "D:\Fanshawe\capstone\recover_smart\venv\Lib\site-packages\rest_framework\views.py", line 480, in raise_uncaught_exception
    raise exc
  File "D:\Fanshawe\capstone\recover_smart\venv\Lib\site-packages\rest_framework\views.py", line 506, in dispatch
    response = handler(request, *args, **kwargs)
  File "D:\Fanshawe\capstone\recover_smart\venv\Lib\site-packages\rest_framework\decorators.py", line 50, in handler
    return func(*args, **kwargs)
  File "D:\Fanshawe\capstone\recover_smart\attachments\views.py", line 35, in getSingleFile
    file = service.getSingleFileData(request.data['file_id'])  # Get file
TypeError: FileUploadService.getSingleFileData() takes 1 positional argument but 2 were given
"GET /api/attachments/file HTTP/1.1" 500 112719
D:\Fanshawe\capstone\recover_smart\attachments\services.py changed, reloading.
Watching for file changes with StatReloader
D:\Fanshawe\capstone\recover_smart\attachments\views.py changed, reloading.
Watching for file changes with StatReloader
D:\Fanshawe\capstone\recover_smart\attachments\services.py changed, reloading.
Watching for file changes with StatReloader
Internal Server Error: /api/attachments/file
Traceback (most recent call last):
  File "D:\Fanshawe\capstone\recover_smart\venv\Lib\site-packages\django\core\handlers\exception.py", line 55, in inner
    response = get_response(request)
  File "D:\Fanshawe\capstone\recover_smart\venv\Lib\site-packages\django\core\handlers\base.py", line 220, in _get_response
    response = response.render()
  File "D:\Fanshawe\capstone\recover_smart\venv\Lib\site-packages\django\template\response.py", line 114, in render
    self.content = self.rendered_content
                   ^^^^^^^^^^^^^^^^^^^^^
  File "D:\Fanshawe\capstone\recover_smart\venv\Lib\site-packages\rest_framework\response.py", line 74, in rendered_content
    ret = renderer.render(self.data, accepted_media_type, context)
  File "D:\Fanshawe\capstone\recover_smart\venv\Lib\site-packages\rest_framework\renderers.py", line 100, in render
    ret = json.dumps(
        data, cls=self.encoder_class,
        indent=indent, ensure_ascii=self.ensure_ascii,
        allow_nan=not self.strict, separators=separators
    )
  File "D:\Fanshawe\capstone\recover_smart\venv\Lib\site-packages\rest_framework\utils\json.py", line 25, in dumps
    return json.dumps(*args, **kwargs)
           ~~~~~~~~~~^^^^^^^^^^^^^^^^^
  File "C:\Users\moham\AppData\Local\Programs\Python\Python313\Lib\json\__init__.py", line 238, in dumps
    **kw).encode(obj)
          ~~~~~~^^^^^
  File "C:\Users\moham\AppData\Local\Programs\Python\Python313\Lib\json\encoder.py", line 200, in encode
    chunks = self.iterencode(o, _one_shot=True)
  File "C:\Users\moham\AppData\Local\Programs\Python\Python313\Lib\json\encoder.py", line 261, in iterencode
    return _iterencode(o, 0)
  File "D:\Fanshawe\capstone\recover_smart\venv\Lib\site-packages\rest_framework\utils\encoders.py", line 67, in default
    return super().default(obj)
           ~~~~~~~~~~~~~~~^^^^^
  File "C:\Users\moham\AppData\Local\Programs\Python\Python313\Lib\json\encoder.py", line 180, in default
    raise TypeError(f'Object of type {o.__class__.__name__} '
                    f'is not JSON serializable')
TypeError: Object of type FileResponse is not JSON serializable
"GET /api/attachments/file HTTP/1.1" 500 118391
D:\Fanshawe\capstone\recover_smart\attachments\views.py changed, reloading.
Watching for file changes with StatReloader
"GET /api/attachments/file HTTP/1.1" 200 1062185
D:\Fanshawe\capstone\recover_smart\attachments\services.py changed, reloading.
Watching for file changes with StatReloader
D:\Fanshawe\capstone\recover_smart\attachments\services.py changed, reloading.
Watching for file changes with StatReloader
D:\Fanshawe\capstone\recover_smart\attachments\services.py changed, reloading.
Watching for file changes with StatReloader
Internal Server Error: /api/attachments/file
Traceback (most recent call last):
  File "D:\Fanshawe\capstone\recover_smart\venv\Lib\site-packages\django\core\handlers\exception.py", line 55, in inner
    response = get_response(request)
  File "D:\Fanshawe\capstone\recover_smart\venv\Lib\site-packages\django\core\handlers\base.py", line 197, in _get_response
    response = wrapped_callback(request, *callback_args, **callback_kwargs)
  File "D:\Fanshawe\capstone\recover_smart\venv\Lib\site-packages\django\views\decorators\csrf.py", line 65, in _view_wrapper
    return view_func(request, *args, **kwargs)
  File "D:\Fanshawe\capstone\recover_smart\venv\Lib\site-packages\django\views\generic\base.py", line 104, in view
    return self.dispatch(request, *args, **kwargs)
           ~~~~~~~~~~~~~^^^^^^^^^^^^^^^^^^^^^^^^^^
  File "D:\Fanshawe\capstone\recover_smart\venv\Lib\site-packages\rest_framework\views.py", line 511, in dispatch
    self.response = self.finalize_response(request, response, *args, **kwargs)
                    ~~~~~~~~~~~~~~~~~~~~~~^^^^^^^^^^^^^^^^^^^^^^^^^^^^^^^^^^^^
  File "D:\Fanshawe\capstone\recover_smart\venv\Lib\site-packages\rest_framework\views.py", line 423, in finalize_response
    assert isinstance(response, HttpResponseBase), (
           ~~~~~~~~~~^^^^^^^^^^^^^^^^^^^^^^^^^^^^
AssertionError: Expected a `Response`, `HttpResponse` or `StreamingHttpResponse` to be returned from the view, but received a `<class 'NoneType'>`
"GET /api/attachments/file HTTP/1.1" 500 96031
D:\Fanshawe\capstone\recover_smart\attachments\services.py changed, reloading.
Watching for file changes with StatReloader
D:\Fanshawe\capstone\recover_smart\attachments\services.py changed, reloading.
Watching for file changes with StatReloader
Not Found: /api/attachments/file
"GET /api/attachments/file HTTP/1.1" 404 14
"GET /api/attachments/file HTTP/1.1" 200 1062185
"GET /api/attachments/list HTTP/1.1" 200 367
